ERROR:app:Exception on /login [POST]
Traceback (most recent call last):
  File "/home/runner/DreamShare/.pythonlibs/lib/python3.11/site-packages/flask/app.py", line 1473, in wsgi_app
    response = self.full_dispatch_request()
               ^^^^^^^^^^^^^^^^^^^^^^^^^^^^
  File "/home/runner/DreamShare/.pythonlibs/lib/python3.11/site-packages/flask/app.py", line 882, in full_dispatch_request
    rv = self.handle_user_exception(e)
         ^^^^^^^^^^^^^^^^^^^^^^^^^^^^^
  File "/home/runner/DreamShare/.pythonlibs/lib/python3.11/site-packages/flask/app.py", line 880, in full_dispatch_request
    rv = self.dispatch_request()
         ^^^^^^^^^^^^^^^^^^^^^^^
  File "/home/runner/DreamShare/.pythonlibs/lib/python3.11/site-packages/flask/app.py", line 865, in dispatch_request
    return self.ensure_sync(self.view_functions[rule.endpoint])(**view_args)  # type: ignore[no-any-return]
           ^^^^^^^^^^^^^^^^^^^^^^^^^^^^^^^^^^^^^^^^^^^^^^^^^^^^^^^^^^^^^^^^^
  File "/home/runner/DreamShare/routes.py", line 33, in login
    user = User.query.filter_by(username=username).first()
           ^^^^^^^^^^
  File "/home/runner/DreamShare/.pythonlibs/lib/python3.11/site-packages/flask_sqlalchemy/model.py", line 22, in __get__
    return cls.query_class(
           ^^^^^^^^^^^^^^^^
  File "/home/runner/DreamShare/.pythonlibs/lib/python3.11/site-packages/sqlalchemy/orm/query.py", line 275, in __init__
    self._set_entities(entities)
  File "/home/runner/DreamShare/.pythonlibs/lib/python3.11/site-packages/sqlalchemy/orm/query.py", line 287, in _set_entities
    self._raw_columns = [
                        ^
  File "/home/runner/DreamShare/.pythonlibs/lib/python3.11/site-packages/sqlalchemy/orm/query.py", line 288, in <listcomp>
    coercions.expect(
  File "/home/runner/DreamShare/.pythonlibs/lib/python3.11/site-packages/sqlalchemy/sql/coercions.py", line 388, in expect
    insp._post_inspect
  File "/home/runner/DreamShare/.pythonlibs/lib/python3.11/site-packages/sqlalchemy/util/langhelpers.py", line 1253, in __get__
    obj.__dict__[self.__name__] = result = self.fget(obj)
                                           ^^^^^^^^^^^^^^
  File "/home/runner/DreamShare/.pythonlibs/lib/python3.11/site-packages/sqlalchemy/orm/mapper.py", line 2722, in _post_inspect
    self._check_configure()
  File "/home/runner/DreamShare/.pythonlibs/lib/python3.11/site-packages/sqlalchemy/orm/mapper.py", line 2399, in _check_configure
    _configure_registries({self.registry}, cascade=True)
  File "/home/runner/DreamShare/.pythonlibs/lib/python3.11/site-packages/sqlalchemy/orm/mapper.py", line 4215, in _configure_registries
    _do_configure_registries(registries, cascade)
  File "/home/runner/DreamShare/.pythonlibs/lib/python3.11/site-packages/sqlalchemy/orm/mapper.py", line 4256, in _do_configure_registries
    mapper._post_configure_properties()
  File "/home/runner/DreamShare/.pythonlibs/lib/python3.11/site-packages/sqlalchemy/orm/mapper.py", line 2416, in _post_configure_properties
    prop.init()
  File "/home/runner/DreamShare/.pythonlibs/lib/python3.11/site-packages/sqlalchemy/orm/interfaces.py", line 589, in init
    self.do_init()
  File "/home/runner/DreamShare/.pythonlibs/lib/python3.11/site-packages/sqlalchemy/orm/relationships.py", line 1647, in do_init
    self._generate_backref()
  File "/home/runner/DreamShare/.pythonlibs/lib/python3.11/site-packages/sqlalchemy/orm/relationships.py", line 2075, in _generate_backref
    raise sa_exc.ArgumentError(
sqlalchemy.exc.ArgumentError: Error creating backref 'author' on relationship 'User.comments': property of that name exists on mapper 'Mapper[Comment(comment)]'
INFO:werkzeug:172.31.196.19 - - [29/Oct/2024 23:59:03] "POST /login HTTP/1.1" 500 -
