2024-11-12 18:00:46,474 - - - 172.31.196.66 - GET http://b32b1022-79d3-4136-8932-6be41b2bb124-00-37otgv6q0gsca.picard.replit.dev/dream/1
Level: ERROR
Module: routes
Message: Error in dream_view route: Could not build url for endpoint 'reanalyze_dream' with values ['dream_id']. Did you mean 'group_dreams' instead?

2024-11-12 18:00:51,753 - - - 172.31.196.66 - GET http://b32b1022-79d3-4136-8932-6be41b2bb124-00-37otgv6q0gsca.picard.replit.dev/dream/1
Level: ERROR
Module: routes
Message: Error in dream_view route: Could not build url for endpoint 'reanalyze_dream' with values ['dream_id']. Did you mean 'group_dreams' instead?

2024-11-12 18:01:01,425 - - - 172.31.196.66 - GET http://b32b1022-79d3-4136-8932-6be41b2bb124-00-37otgv6q0gsca.picard.replit.dev/dream/1
Level: ERROR
Module: routes
Message: Error in dream_view route: Could not build url for endpoint 'reanalyze_dream' with values ['dream_id']. Did you mean 'group_dreams' instead?

2024-11-12 21:42:27,160 - - - 172.31.196.23 - GET http://b32b1022-79d3-4136-8932-6be41b2bb124-00-37otgv6q0gsca.picard.replit.dev/dream/1
Level: ERROR
Module: routes
Message: Error in dream_view route: Could not build url for endpoint 'reanalyze_dream' with values ['dream_id']. Did you mean 'group_dreams' instead?

2024-11-12 21:42:44,937 - - - 172.31.196.23 - GET http://b32b1022-79d3-4136-8932-6be41b2bb124-00-37otgv6q0gsca.picard.replit.dev/dream/1
Level: ERROR
Module: routes
Message: Error in dream_view route: Could not build url for endpoint 'reanalyze_dream' with values ['dream_id']. Did you mean 'group_dreams' instead?

2024-11-12 21:43:21,102 - - - 172.31.196.23 - GET http://b32b1022-79d3-4136-8932-6be41b2bb124-00-37otgv6q0gsca.picard.replit.dev/dream/1
Level: ERROR
Module: routes
Message: Error in dream_view route: Could not build url for endpoint 'reanalyze_dream' with values ['dream_id']. Did you mean 'group_dreams' instead?

2024-11-12 22:23:20,385 - - - 172.31.196.17 - GET http://b32b1022-79d3-4136-8932-6be41b2bb124-00-37otgv6q0gsca.picard.replit.dev/dream/1
Level: ERROR
Module: routes
Message: Error in dream_view route: No filter named 'markdown' found.

2024-11-12 22:37:06,954 - - - 172.31.196.17 - GET http://b32b1022-79d3-4136-8932-6be41b2bb124-00-37otgv6q0gsca.picard.replit.dev/dream/1
Level: ERROR
Module: routes
Message: Error in dream_view route: expected token 'end of statement block', got '='

2024-11-12 22:37:12,745 - - - 172.31.196.17 - GET http://b32b1022-79d3-4136-8932-6be41b2bb124-00-37otgv6q0gsca.picard.replit.dev/dream/1
Level: ERROR
Module: routes
Message: Error in dream_view route: expected token 'end of statement block', got '='

2024-11-13 17:37:09,840 - - - 172.31.196.22 - GET http://b32b1022-79d3-4136-8932-6be41b2bb124-00-37otgv6q0gsca.picard.replit.dev/
Level: ERROR
Module: routes
Message: Error in index route: Could not build url for endpoint 'community_dreams'. Did you mean 'dream_groups' instead?

2024-11-13 17:42:38,969 - - - 172.31.196.22 - POST http://b32b1022-79d3-4136-8932-6be41b2bb124-00-37otgv6q0gsca.picard.replit.dev/login
Level: ERROR
Module: activity_tracker
Message: Error tracking activity: __init__() got an unexpected keyword argument 'created_at'

2024-11-13 17:42:39,244 - - - 172.31.196.22 - GET http://b32b1022-79d3-4136-8932-6be41b2bb124-00-37otgv6q0gsca.picard.replit.dev/
Level: ERROR
Module: activity_tracker
Message: Error tracking activity: __init__() got an unexpected keyword argument 'created_at'

2024-11-13 17:42:47,531 - - - 172.31.196.22 - GET http://b32b1022-79d3-4136-8932-6be41b2bb124-00-37otgv6q0gsca.picard.replit.dev/dream/1
Level: ERROR
Module: activity_tracker
Message: Error tracking activity: __init__() got an unexpected keyword argument 'created_at'

2024-11-13 17:42:47,562 - - - 172.31.196.22 - GET http://b32b1022-79d3-4136-8932-6be41b2bb124-00-37otgv6q0gsca.picard.replit.dev/dream/1
Level: ERROR
Module: routes
Message: Error viewing dream: expected token 'end of statement block', got '='

2024-11-13 17:42:47,980 - - - 172.31.196.22 - GET http://b32b1022-79d3-4136-8932-6be41b2bb124-00-37otgv6q0gsca.picard.replit.dev/
Level: ERROR
Module: activity_tracker
Message: Error tracking activity: __init__() got an unexpected keyword argument 'created_at'

2024-11-13 17:42:52,840 - - - 172.31.196.22 - GET http://b32b1022-79d3-4136-8932-6be41b2bb124-00-37otgv6q0gsca.picard.replit.dev/dream/1
Level: ERROR
Module: activity_tracker
Message: Error tracking activity: __init__() got an unexpected keyword argument 'created_at'

2024-11-13 17:42:52,864 - - - 172.31.196.22 - GET http://b32b1022-79d3-4136-8932-6be41b2bb124-00-37otgv6q0gsca.picard.replit.dev/dream/1
Level: ERROR
Module: routes
Message: Error viewing dream: expected token 'end of statement block', got '='

2024-11-13 17:42:53,226 - - - 172.31.196.22 - GET http://b32b1022-79d3-4136-8932-6be41b2bb124-00-37otgv6q0gsca.picard.replit.dev/
Level: ERROR
Module: activity_tracker
Message: Error tracking activity: __init__() got an unexpected keyword argument 'created_at'

2024-11-13 17:45:31,853 - - - 127.0.0.1 - POST http://localhost/login
Level: ERROR
Module: activity_tracker
Message: Error tracking activity: __init__() got an unexpected keyword argument 'created_at'

2024-11-13 17:45:31,853 - - - 127.0.0.1 - POST http://localhost/login
Level: ERROR
Module: activity_tracker
Message: Error tracking activity: __init__() got an unexpected keyword argument 'created_at'

2024-11-13 17:45:31,853 - - - 127.0.0.1 - POST http://localhost/login
Level: ERROR
Module: activity_tracker
Message: Error tracking activity: __init__() got an unexpected keyword argument 'created_at'

2024-11-13 17:45:31,853 - - - 127.0.0.1 - POST http://localhost/login
Level: ERROR
Module: activity_tracker
Message: Error tracking activity: __init__() got an unexpected keyword argument 'created_at'

2024-11-13 17:45:31,853 - - - 127.0.0.1 - POST http://localhost/login
Level: ERROR
Module: activity_tracker
Message: Error tracking activity: __init__() got an unexpected keyword argument 'created_at'

2024-11-13 17:45:31,853 - - - 127.0.0.1 - POST http://localhost/login
Level: ERROR
Module: activity_tracker
Message: Error tracking activity: __init__() got an unexpected keyword argument 'created_at'

2024-11-13 17:45:31,853 - - - 127.0.0.1 - POST http://localhost/login
Level: ERROR
Module: activity_tracker
Message: Error tracking activity: __init__() got an unexpected keyword argument 'created_at'

2024-11-13 17:45:31,961 - - - 127.0.0.1 - GET http://localhost/
Level: ERROR
Module: activity_tracker
Message: Error tracking activity: __init__() got an unexpected keyword argument 'created_at'

2024-11-13 17:45:31,961 - - - 127.0.0.1 - GET http://localhost/
Level: ERROR
Module: activity_tracker
Message: Error tracking activity: __init__() got an unexpected keyword argument 'created_at'

2024-11-13 17:45:31,961 - - - 127.0.0.1 - GET http://localhost/
Level: ERROR
Module: activity_tracker
Message: Error tracking activity: __init__() got an unexpected keyword argument 'created_at'

2024-11-13 17:45:31,961 - - - 127.0.0.1 - GET http://localhost/
Level: ERROR
Module: activity_tracker
Message: Error tracking activity: __init__() got an unexpected keyword argument 'created_at'

2024-11-13 17:45:31,961 - - - 127.0.0.1 - GET http://localhost/
Level: ERROR
Module: activity_tracker
Message: Error tracking activity: __init__() got an unexpected keyword argument 'created_at'

2024-11-13 17:45:31,961 - - - 127.0.0.1 - GET http://localhost/
Level: ERROR
Module: activity_tracker
Message: Error tracking activity: __init__() got an unexpected keyword argument 'created_at'

2024-11-13 17:45:31,961 - - - 127.0.0.1 - GET http://localhost/
Level: ERROR
Module: activity_tracker
Message: Error tracking activity: __init__() got an unexpected keyword argument 'created_at'

2024-11-13 17:45:32,140 - - - 127.0.0.1 - GET http://localhost/
Level: ERROR
Module: activity_tracker
Message: Error tracking activity: __init__() got an unexpected keyword argument 'created_at'

2024-11-13 17:45:32,140 - - - 127.0.0.1 - GET http://localhost/
Level: ERROR
Module: activity_tracker
Message: Error tracking activity: __init__() got an unexpected keyword argument 'created_at'

2024-11-13 17:45:32,140 - - - 127.0.0.1 - GET http://localhost/
Level: ERROR
Module: activity_tracker
Message: Error tracking activity: __init__() got an unexpected keyword argument 'created_at'

2024-11-13 17:45:32,140 - - - 127.0.0.1 - GET http://localhost/
Level: ERROR
Module: activity_tracker
Message: Error tracking activity: __init__() got an unexpected keyword argument 'created_at'

2024-11-13 17:45:32,140 - - - 127.0.0.1 - GET http://localhost/
Level: ERROR
Module: activity_tracker
Message: Error tracking activity: __init__() got an unexpected keyword argument 'created_at'

2024-11-13 17:45:32,140 - - - 127.0.0.1 - GET http://localhost/
Level: ERROR
Module: activity_tracker
Message: Error tracking activity: __init__() got an unexpected keyword argument 'created_at'

2024-11-13 17:45:32,140 - - - 127.0.0.1 - GET http://localhost/
Level: ERROR
Module: activity_tracker
Message: Error tracking activity: __init__() got an unexpected keyword argument 'created_at'

2024-11-13 17:45:34,145 - - - 127.0.0.1 - POST http://localhost/register
Level: ERROR
Module: activity_tracker
Message: Error tracking activity: __init__() got an unexpected keyword argument 'created_at'

2024-11-13 17:45:34,145 - - - 127.0.0.1 - POST http://localhost/register
Level: ERROR
Module: activity_tracker
Message: Error tracking activity: __init__() got an unexpected keyword argument 'created_at'

2024-11-13 17:45:34,145 - - - 127.0.0.1 - POST http://localhost/register
Level: ERROR
Module: activity_tracker
Message: Error tracking activity: __init__() got an unexpected keyword argument 'created_at'

2024-11-13 17:45:34,145 - - - 127.0.0.1 - POST http://localhost/register
Level: ERROR
Module: activity_tracker
Message: Error tracking activity: __init__() got an unexpected keyword argument 'created_at'

2024-11-13 17:45:34,145 - - - 127.0.0.1 - POST http://localhost/register
Level: ERROR
Module: activity_tracker
Message: Error tracking activity: __init__() got an unexpected keyword argument 'created_at'

2024-11-13 17:45:34,145 - - - 127.0.0.1 - POST http://localhost/register
Level: ERROR
Module: activity_tracker
Message: Error tracking activity: __init__() got an unexpected keyword argument 'created_at'

2024-11-13 17:45:34,145 - - - 127.0.0.1 - POST http://localhost/register
Level: ERROR
Module: activity_tracker
Message: Error tracking activity: __init__() got an unexpected keyword argument 'created_at'

2024-11-13 17:45:34,145 - - - 127.0.0.1 - POST http://localhost/register
Level: ERROR
Module: activity_tracker
Message: Error tracking activity: __init__() got an unexpected keyword argument 'created_at'

2024-11-13 17:45:34,250 - - - 127.0.0.1 - GET http://localhost/
Level: ERROR
Module: activity_tracker
Message: Error tracking activity: __init__() got an unexpected keyword argument 'created_at'

2024-11-13 17:45:34,250 - - - 127.0.0.1 - GET http://localhost/
Level: ERROR
Module: activity_tracker
Message: Error tracking activity: __init__() got an unexpected keyword argument 'created_at'

2024-11-13 17:45:34,250 - - - 127.0.0.1 - GET http://localhost/
Level: ERROR
Module: activity_tracker
Message: Error tracking activity: __init__() got an unexpected keyword argument 'created_at'

2024-11-13 17:45:34,250 - - - 127.0.0.1 - GET http://localhost/
Level: ERROR
Module: activity_tracker
Message: Error tracking activity: __init__() got an unexpected keyword argument 'created_at'

2024-11-13 17:45:34,250 - - - 127.0.0.1 - GET http://localhost/
Level: ERROR
Module: activity_tracker
Message: Error tracking activity: __init__() got an unexpected keyword argument 'created_at'

2024-11-13 17:45:34,250 - - - 127.0.0.1 - GET http://localhost/
Level: ERROR
Module: activity_tracker
Message: Error tracking activity: __init__() got an unexpected keyword argument 'created_at'

2024-11-13 17:45:34,250 - - - 127.0.0.1 - GET http://localhost/
Level: ERROR
Module: activity_tracker
Message: Error tracking activity: __init__() got an unexpected keyword argument 'created_at'

2024-11-13 17:45:34,250 - - - 127.0.0.1 - GET http://localhost/
Level: ERROR
Module: activity_tracker
Message: Error tracking activity: __init__() got an unexpected keyword argument 'created_at'

2024-11-13 17:45:34,433 - - - 127.0.0.1 - GET http://localhost/
Level: ERROR
Module: activity_tracker
Message: Error tracking activity: __init__() got an unexpected keyword argument 'created_at'

2024-11-13 17:45:34,433 - - - 127.0.0.1 - GET http://localhost/
Level: ERROR
Module: activity_tracker
Message: Error tracking activity: __init__() got an unexpected keyword argument 'created_at'

2024-11-13 17:45:34,433 - - - 127.0.0.1 - GET http://localhost/
Level: ERROR
Module: activity_tracker
Message: Error tracking activity: __init__() got an unexpected keyword argument 'created_at'

2024-11-13 17:45:34,433 - - - 127.0.0.1 - GET http://localhost/
Level: ERROR
Module: activity_tracker
Message: Error tracking activity: __init__() got an unexpected keyword argument 'created_at'

2024-11-13 17:45:34,433 - - - 127.0.0.1 - GET http://localhost/
Level: ERROR
Module: activity_tracker
Message: Error tracking activity: __init__() got an unexpected keyword argument 'created_at'

2024-11-13 17:45:34,433 - - - 127.0.0.1 - GET http://localhost/
Level: ERROR
Module: activity_tracker
Message: Error tracking activity: __init__() got an unexpected keyword argument 'created_at'

2024-11-13 17:45:34,433 - - - 127.0.0.1 - GET http://localhost/
Level: ERROR
Module: activity_tracker
Message: Error tracking activity: __init__() got an unexpected keyword argument 'created_at'

2024-11-13 17:45:34,433 - - - 127.0.0.1 - GET http://localhost/
Level: ERROR
Module: activity_tracker
Message: Error tracking activity: __init__() got an unexpected keyword argument 'created_at'

2024-11-13 17:45:36,558 - - - 127.0.0.1 - POST http://localhost/login
Level: ERROR
Module: activity_tracker
Message: Error tracking activity: __init__() got an unexpected keyword argument 'created_at'

2024-11-13 17:45:36,558 - - - 127.0.0.1 - POST http://localhost/login
Level: ERROR
Module: activity_tracker
Message: Error tracking activity: __init__() got an unexpected keyword argument 'created_at'

2024-11-13 17:45:36,558 - - - 127.0.0.1 - POST http://localhost/login
Level: ERROR
Module: activity_tracker
Message: Error tracking activity: __init__() got an unexpected keyword argument 'created_at'

2024-11-13 17:45:36,558 - - - 127.0.0.1 - POST http://localhost/login
Level: ERROR
Module: activity_tracker
Message: Error tracking activity: __init__() got an unexpected keyword argument 'created_at'

2024-11-13 17:45:36,558 - - - 127.0.0.1 - POST http://localhost/login
Level: ERROR
Module: activity_tracker
Message: Error tracking activity: __init__() got an unexpected keyword argument 'created_at'

2024-11-13 17:45:36,558 - - - 127.0.0.1 - POST http://localhost/login
Level: ERROR
Module: activity_tracker
Message: Error tracking activity: __init__() got an unexpected keyword argument 'created_at'

2024-11-13 17:45:36,558 - - - 127.0.0.1 - POST http://localhost/login
Level: ERROR
Module: activity_tracker
Message: Error tracking activity: __init__() got an unexpected keyword argument 'created_at'

2024-11-13 17:45:36,558 - - - 127.0.0.1 - POST http://localhost/login
Level: ERROR
Module: activity_tracker
Message: Error tracking activity: __init__() got an unexpected keyword argument 'created_at'

2024-11-13 17:45:36,558 - - - 127.0.0.1 - POST http://localhost/login
Level: ERROR
Module: activity_tracker
Message: Error tracking activity: __init__() got an unexpected keyword argument 'created_at'

2024-11-13 17:45:36,661 - - - 127.0.0.1 - POST http://localhost/dream/new
Level: ERROR
Module: routes
Message: Error creating dream: __init__() got an unexpected keyword argument 'is_public'

2024-11-13 17:45:36,661 - - - 127.0.0.1 - POST http://localhost/dream/new
Level: ERROR
Module: routes
Message: Error creating dream: __init__() got an unexpected keyword argument 'is_public'

2024-11-13 17:45:36,661 - - - 127.0.0.1 - POST http://localhost/dream/new
Level: ERROR
Module: routes
Message: Error creating dream: __init__() got an unexpected keyword argument 'is_public'

2024-11-13 17:45:36,661 - - - 127.0.0.1 - POST http://localhost/dream/new
Level: ERROR
Module: routes
Message: Error creating dream: __init__() got an unexpected keyword argument 'is_public'

2024-11-13 17:45:36,661 - - - 127.0.0.1 - POST http://localhost/dream/new
Level: ERROR
Module: routes
Message: Error creating dream: __init__() got an unexpected keyword argument 'is_public'

2024-11-13 17:45:36,661 - - - 127.0.0.1 - POST http://localhost/dream/new
Level: ERROR
Module: routes
Message: Error creating dream: __init__() got an unexpected keyword argument 'is_public'

2024-11-13 17:45:36,661 - - - 127.0.0.1 - POST http://localhost/dream/new
Level: ERROR
Module: routes
Message: Error creating dream: __init__() got an unexpected keyword argument 'is_public'

2024-11-13 17:45:36,661 - - - 127.0.0.1 - POST http://localhost/dream/new
Level: ERROR
Module: routes
Message: Error creating dream: __init__() got an unexpected keyword argument 'is_public'

2024-11-13 17:45:36,661 - - - 127.0.0.1 - POST http://localhost/dream/new
Level: ERROR
Module: routes
Message: Error creating dream: __init__() got an unexpected keyword argument 'is_public'

2024-11-13 17:45:42,591 - - - None - GET http://localhost/
Level: ERROR
Module: logging_config
Message: Application Error: {'timestamp': '2024-11-13T17:45:42.590811', 'error_type': 'ValueError', 'error_message': 'Test error', 'traceback': 'NoneType: None\n', 'context': {'test': 'context'}, 'url': 'http://localhost/', 'method': 'GET', 'headers': {'Host': 'localhost'}, 'remote_addr': None}

2024-11-13 17:45:42,591 - - - None - GET http://localhost/
Level: ERROR
Module: logging_config
Message: Application Error: {'timestamp': '2024-11-13T17:45:42.590811', 'error_type': 'ValueError', 'error_message': 'Test error', 'traceback': 'NoneType: None\n', 'context': {'test': 'context'}, 'url': 'http://localhost/', 'method': 'GET', 'headers': {'Host': 'localhost'}, 'remote_addr': None}

2024-11-13 17:45:42,591 - - - None - GET http://localhost/
Level: ERROR
Module: logging_config
Message: Application Error: {'timestamp': '2024-11-13T17:45:42.590811', 'error_type': 'ValueError', 'error_message': 'Test error', 'traceback': 'NoneType: None\n', 'context': {'test': 'context'}, 'url': 'http://localhost/', 'method': 'GET', 'headers': {'Host': 'localhost'}, 'remote_addr': None}

2024-11-13 17:45:42,591 - - - None - GET http://localhost/
Level: ERROR
Module: logging_config
Message: Application Error: {'timestamp': '2024-11-13T17:45:42.590811', 'error_type': 'ValueError', 'error_message': 'Test error', 'traceback': 'NoneType: None\n', 'context': {'test': 'context'}, 'url': 'http://localhost/', 'method': 'GET', 'headers': {'Host': 'localhost'}, 'remote_addr': None}

2024-11-13 17:45:42,591 - - - None - GET http://localhost/
Level: ERROR
Module: logging_config
Message: Application Error: {'timestamp': '2024-11-13T17:45:42.590811', 'error_type': 'ValueError', 'error_message': 'Test error', 'traceback': 'NoneType: None\n', 'context': {'test': 'context'}, 'url': 'http://localhost/', 'method': 'GET', 'headers': {'Host': 'localhost'}, 'remote_addr': None}

2024-11-13 17:45:42,591 - - - None - GET http://localhost/
Level: ERROR
Module: logging_config
Message: Application Error: {'timestamp': '2024-11-13T17:45:42.590811', 'error_type': 'ValueError', 'error_message': 'Test error', 'traceback': 'NoneType: None\n', 'context': {'test': 'context'}, 'url': 'http://localhost/', 'method': 'GET', 'headers': {'Host': 'localhost'}, 'remote_addr': None}

2024-11-13 17:45:42,591 - - - None - GET http://localhost/
Level: ERROR
Module: logging_config
Message: Application Error: {'timestamp': '2024-11-13T17:45:42.590811', 'error_type': 'ValueError', 'error_message': 'Test error', 'traceback': 'NoneType: None\n', 'context': {'test': 'context'}, 'url': 'http://localhost/', 'method': 'GET', 'headers': {'Host': 'localhost'}, 'remote_addr': None}

2024-11-13 17:45:42,591 - - - None - GET http://localhost/
Level: ERROR
Module: logging_config
Message: Application Error: {'timestamp': '2024-11-13T17:45:42.590811', 'error_type': 'ValueError', 'error_message': 'Test error', 'traceback': 'NoneType: None\n', 'context': {'test': 'context'}, 'url': 'http://localhost/', 'method': 'GET', 'headers': {'Host': 'localhost'}, 'remote_addr': None}

2024-11-13 17:45:42,591 - - - None - GET http://localhost/
Level: ERROR
Module: logging_config
Message: Application Error: {'timestamp': '2024-11-13T17:45:42.590811', 'error_type': 'ValueError', 'error_message': 'Test error', 'traceback': 'NoneType: None\n', 'context': {'test': 'context'}, 'url': 'http://localhost/', 'method': 'GET', 'headers': {'Host': 'localhost'}, 'remote_addr': None}

2024-11-13 17:45:42,591 - - - None - GET http://localhost/
Level: ERROR
Module: logging_config
Message: Application Error: {'timestamp': '2024-11-13T17:45:42.590811', 'error_type': 'ValueError', 'error_message': 'Test error', 'traceback': 'NoneType: None\n', 'context': {'test': 'context'}, 'url': 'http://localhost/', 'method': 'GET', 'headers': {'Host': 'localhost'}, 'remote_addr': None}

2024-11-13 17:45:42,591 - - - None - GET http://localhost/
Level: ERROR
Module: logging_config
Message: Application Error: {'timestamp': '2024-11-13T17:45:42.590811', 'error_type': 'ValueError', 'error_message': 'Test error', 'traceback': 'NoneType: None\n', 'context': {'test': 'context'}, 'url': 'http://localhost/', 'method': 'GET', 'headers': {'Host': 'localhost'}, 'remote_addr': None}

2024-11-13 17:45:42,591 - - - None - GET http://localhost/
Level: ERROR
Module: logging_config
Message: Application Error: {'timestamp': '2024-11-13T17:45:42.590811', 'error_type': 'ValueError', 'error_message': 'Test error', 'traceback': 'NoneType: None\n', 'context': {'test': 'context'}, 'url': 'http://localhost/', 'method': 'GET', 'headers': {'Host': 'localhost'}, 'remote_addr': None}

2024-11-13 17:46:01,311 - None - None - None None
Level: ERROR
Module: logging_config
Message: Application Error: {'timestamp': '2024-11-13T17:46:01.297065', 'error_type': 'IntegrityError', 'error_message': '(psycopg2.errors.UniqueViolation) duplicate key value violates unique constraint "pg_class_relname_nsp_index"\nDETAIL:  Key (relname, relnamespace)=(user_id_seq, 360560) already exists.\n\n[SQL: \nCREATE TABLE "user" (\n\tid SERIAL NOT NULL, \n\tusername VARCHAR(64) NOT NULL, \n\temail VARCHAR(120) NOT NULL, \n\tpassword_hash VARCHAR(256), \n\tsubscription_type VARCHAR(20), \n\tsubscription_end_date TIMESTAMP WITHOUT TIME ZONE, \n\tmonthly_ai_analysis_count INTEGER, \n\tlast_analysis_reset TIMESTAMP WITHOUT TIME ZONE, \n\tPRIMARY KEY (id), \n\tUNIQUE (username), \n\tUNIQUE (email)\n)\n\n]\n(Background on this error at: https://sqlalche.me/e/20/gkpj)', 'traceback': 'Traceback (most recent call last):\n  File "/home/runner/DreamShare/.pythonlibs/lib/python3.11/site-packages/sqlalchemy/engine/base.py", line 1967, in _exec_single_context\n    self.dialect.do_execute(\n  File "/home/runner/DreamShare/.pythonlibs/lib/python3.11/site-packages/sqlalchemy/engine/default.py", line 941, in do_execute\n    cursor.execute(statement, parameters)\npsycopg2.errors.UniqueViolation: duplicate key value violates unique constraint "pg_class_relname_nsp_index"\nDETAIL:  Key (relname, relnamespace)=(user_id_seq, 360560) already exists.\n\n\nThe above exception was the direct cause of the following exception:\n\nTraceback (most recent call last):\n  File "/home/runner/DreamShare/app.py", line 78, in create_app\n    db.create_all()\n  File "/home/runner/DreamShare/.pythonlibs/lib/python3.11/site-packages/flask_sqlalchemy/extension.py", line 900, in create_all\n    self._call_for_binds(bind_key, "create_all")\n  File "/home/runner/DreamShare/.pythonlibs/lib/python3.11/site-packages/flask_sqlalchemy/extension.py", line 881, in _call_for_binds\n    getattr(metadata, op_name)(bind=engine)\n  File "/home/runner/DreamShare/.pythonlibs/lib/python3.11/site-packages/sqlalchemy/sql/schema.py", line 5868, in create_all\n    bind._run_ddl_visitor(\n  File "/home/runner/DreamShare/.pythonlibs/lib/python3.11/site-packages/sqlalchemy/engine/base.py", line 3253, in _run_ddl_visitor\n    conn._run_ddl_visitor(visitorcallable, element, **kwargs)\n  File "/home/runner/DreamShare/.pythonlibs/lib/python3.11/site-packages/sqlalchemy/engine/base.py", line 2459, in _run_ddl_visitor\n    visitorcallable(self.dialect, self, **kwargs).traverse_single(element)\n  File "/home/runner/DreamShare/.pythonlibs/lib/python3.11/site-packages/sqlalchemy/sql/visitors.py", line 664, in traverse_single\n    return meth(obj, **kw)\n           ^^^^^^^^^^^^^^^\n  File "/home/runner/DreamShare/.pythonlibs/lib/python3.11/site-packages/sqlalchemy/sql/ddl.py", line 918, in visit_metadata\n    self.traverse_single(\n  File "/home/runner/DreamShare/.pythonlibs/lib/python3.11/site-packages/sqlalchemy/sql/visitors.py", line 664, in traverse_single\n    return meth(obj, **kw)\n           ^^^^^^^^^^^^^^^\n  File "/home/runner/DreamShare/.pythonlibs/lib/python3.11/site-packages/sqlalchemy/sql/ddl.py", line 956, in visit_table\n    )._invoke_with(self.connection)\n      ^^^^^^^^^^^^^^^^^^^^^^^^^^^^^\n  File "/home/runner/DreamShare/.pythonlibs/lib/python3.11/site-packages/sqlalchemy/sql/ddl.py", line 314, in _invoke_with\n    return bind.execute(self)\n           ^^^^^^^^^^^^^^^^^^\n  File "/home/runner/DreamShare/.pythonlibs/lib/python3.11/site-packages/sqlalchemy/engine/base.py", line 1418, in execute\n    return meth(\n           ^^^^^\n  File "/home/runner/DreamShare/.pythonlibs/lib/python3.11/site-packages/sqlalchemy/sql/ddl.py", line 180, in _execute_on_connection\n    return connection._execute_ddl(\n           ^^^^^^^^^^^^^^^^^^^^^^^^\n  File "/home/runner/DreamShare/.pythonlibs/lib/python3.11/site-packages/sqlalchemy/engine/base.py", line 1529, in _execute_ddl\n    ret = self._execute_context(\n          ^^^^^^^^^^^^^^^^^^^^^^\n  File "/home/runner/DreamShare/.pythonlibs/lib/python3.11/site-packages/sqlalchemy/engine/base.py", line 1846, in _execute_context\n    return self._exec_single_context(\n           ^^^^^^^^^^^^^^^^^^^^^^^^^^\n  File "/home/runner/DreamShare/.pythonlibs/lib/python3.11/site-packages/sqlalchemy/engine/base.py", line 1986, in _exec_single_context\n    self._handle_dbapi_exception(\n  File "/home/runner/DreamShare/.pythonlibs/lib/python3.11/site-packages/sqlalchemy/engine/base.py", line 2355, in _handle_dbapi_exception\n    raise sqlalchemy_exception.with_traceback(exc_info[2]) from e\n  File "/home/runner/DreamShare/.pythonlibs/lib/python3.11/site-packages/sqlalchemy/engine/base.py", line 1967, in _exec_single_context\n    self.dialect.do_execute(\n  File "/home/runner/DreamShare/.pythonlibs/lib/python3.11/site-packages/sqlalchemy/engine/default.py", line 941, in do_execute\n    cursor.execute(statement, parameters)\nsqlalchemy.exc.IntegrityError: (psycopg2.errors.UniqueViolation) duplicate key value violates unique constraint "pg_class_relname_nsp_index"\nDETAIL:  Key (relname, relnamespace)=(user_id_seq, 360560) already exists.\n\n[SQL: \nCREATE TABLE "user" (\n\tid SERIAL NOT NULL, \n\tusername VARCHAR(64) NOT NULL, \n\temail VARCHAR(120) NOT NULL, \n\tpassword_hash VARCHAR(256), \n\tsubscription_type VARCHAR(20), \n\tsubscription_end_date TIMESTAMP WITHOUT TIME ZONE, \n\tmonthly_ai_analysis_count INTEGER, \n\tlast_analysis_reset TIMESTAMP WITHOUT TIME ZONE, \n\tPRIMARY KEY (id), \n\tUNIQUE (username), \n\tUNIQUE (email)\n)\n\n]\n(Background on this error at: https://sqlalche.me/e/20/gkpj)\n', 'context': {}}

2024-11-13 17:46:01,311 - None - None - None None
Level: ERROR
Module: logging_config
Message: Application Error: {'timestamp': '2024-11-13T17:46:01.297065', 'error_type': 'IntegrityError', 'error_message': '(psycopg2.errors.UniqueViolation) duplicate key value violates unique constraint "pg_class_relname_nsp_index"\nDETAIL:  Key (relname, relnamespace)=(user_id_seq, 360560) already exists.\n\n[SQL: \nCREATE TABLE "user" (\n\tid SERIAL NOT NULL, \n\tusername VARCHAR(64) NOT NULL, \n\temail VARCHAR(120) NOT NULL, \n\tpassword_hash VARCHAR(256), \n\tsubscription_type VARCHAR(20), \n\tsubscription_end_date TIMESTAMP WITHOUT TIME ZONE, \n\tmonthly_ai_analysis_count INTEGER, \n\tlast_analysis_reset TIMESTAMP WITHOUT TIME ZONE, \n\tPRIMARY KEY (id), \n\tUNIQUE (username), \n\tUNIQUE (email)\n)\n\n]\n(Background on this error at: https://sqlalche.me/e/20/gkpj)', 'traceback': 'Traceback (most recent call last):\n  File "/home/runner/DreamShare/.pythonlibs/lib/python3.11/site-packages/sqlalchemy/engine/base.py", line 1967, in _exec_single_context\n    self.dialect.do_execute(\n  File "/home/runner/DreamShare/.pythonlibs/lib/python3.11/site-packages/sqlalchemy/engine/default.py", line 941, in do_execute\n    cursor.execute(statement, parameters)\npsycopg2.errors.UniqueViolation: duplicate key value violates unique constraint "pg_class_relname_nsp_index"\nDETAIL:  Key (relname, relnamespace)=(user_id_seq, 360560) already exists.\n\n\nThe above exception was the direct cause of the following exception:\n\nTraceback (most recent call last):\n  File "/home/runner/DreamShare/app.py", line 78, in create_app\n    db.create_all()\n  File "/home/runner/DreamShare/.pythonlibs/lib/python3.11/site-packages/flask_sqlalchemy/extension.py", line 900, in create_all\n    self._call_for_binds(bind_key, "create_all")\n  File "/home/runner/DreamShare/.pythonlibs/lib/python3.11/site-packages/flask_sqlalchemy/extension.py", line 881, in _call_for_binds\n    getattr(metadata, op_name)(bind=engine)\n  File "/home/runner/DreamShare/.pythonlibs/lib/python3.11/site-packages/sqlalchemy/sql/schema.py", line 5868, in create_all\n    bind._run_ddl_visitor(\n  File "/home/runner/DreamShare/.pythonlibs/lib/python3.11/site-packages/sqlalchemy/engine/base.py", line 3253, in _run_ddl_visitor\n    conn._run_ddl_visitor(visitorcallable, element, **kwargs)\n  File "/home/runner/DreamShare/.pythonlibs/lib/python3.11/site-packages/sqlalchemy/engine/base.py", line 2459, in _run_ddl_visitor\n    visitorcallable(self.dialect, self, **kwargs).traverse_single(element)\n  File "/home/runner/DreamShare/.pythonlibs/lib/python3.11/site-packages/sqlalchemy/sql/visitors.py", line 664, in traverse_single\n    return meth(obj, **kw)\n           ^^^^^^^^^^^^^^^\n  File "/home/runner/DreamShare/.pythonlibs/lib/python3.11/site-packages/sqlalchemy/sql/ddl.py", line 918, in visit_metadata\n    self.traverse_single(\n  File "/home/runner/DreamShare/.pythonlibs/lib/python3.11/site-packages/sqlalchemy/sql/visitors.py", line 664, in traverse_single\n    return meth(obj, **kw)\n           ^^^^^^^^^^^^^^^\n  File "/home/runner/DreamShare/.pythonlibs/lib/python3.11/site-packages/sqlalchemy/sql/ddl.py", line 956, in visit_table\n    )._invoke_with(self.connection)\n      ^^^^^^^^^^^^^^^^^^^^^^^^^^^^^\n  File "/home/runner/DreamShare/.pythonlibs/lib/python3.11/site-packages/sqlalchemy/sql/ddl.py", line 314, in _invoke_with\n    return bind.execute(self)\n           ^^^^^^^^^^^^^^^^^^\n  File "/home/runner/DreamShare/.pythonlibs/lib/python3.11/site-packages/sqlalchemy/engine/base.py", line 1418, in execute\n    return meth(\n           ^^^^^\n  File "/home/runner/DreamShare/.pythonlibs/lib/python3.11/site-packages/sqlalchemy/sql/ddl.py", line 180, in _execute_on_connection\n    return connection._execute_ddl(\n           ^^^^^^^^^^^^^^^^^^^^^^^^\n  File "/home/runner/DreamShare/.pythonlibs/lib/python3.11/site-packages/sqlalchemy/engine/base.py", line 1529, in _execute_ddl\n    ret = self._execute_context(\n          ^^^^^^^^^^^^^^^^^^^^^^\n  File "/home/runner/DreamShare/.pythonlibs/lib/python3.11/site-packages/sqlalchemy/engine/base.py", line 1846, in _execute_context\n    return self._exec_single_context(\n           ^^^^^^^^^^^^^^^^^^^^^^^^^^\n  File "/home/runner/DreamShare/.pythonlibs/lib/python3.11/site-packages/sqlalchemy/engine/base.py", line 1986, in _exec_single_context\n    self._handle_dbapi_exception(\n  File "/home/runner/DreamShare/.pythonlibs/lib/python3.11/site-packages/sqlalchemy/engine/base.py", line 2355, in _handle_dbapi_exception\n    raise sqlalchemy_exception.with_traceback(exc_info[2]) from e\n  File "/home/runner/DreamShare/.pythonlibs/lib/python3.11/site-packages/sqlalchemy/engine/base.py", line 1967, in _exec_single_context\n    self.dialect.do_execute(\n  File "/home/runner/DreamShare/.pythonlibs/lib/python3.11/site-packages/sqlalchemy/engine/default.py", line 941, in do_execute\n    cursor.execute(statement, parameters)\nsqlalchemy.exc.IntegrityError: (psycopg2.errors.UniqueViolation) duplicate key value violates unique constraint "pg_class_relname_nsp_index"\nDETAIL:  Key (relname, relnamespace)=(user_id_seq, 360560) already exists.\n\n[SQL: \nCREATE TABLE "user" (\n\tid SERIAL NOT NULL, \n\tusername VARCHAR(64) NOT NULL, \n\temail VARCHAR(120) NOT NULL, \n\tpassword_hash VARCHAR(256), \n\tsubscription_type VARCHAR(20), \n\tsubscription_end_date TIMESTAMP WITHOUT TIME ZONE, \n\tmonthly_ai_analysis_count INTEGER, \n\tlast_analysis_reset TIMESTAMP WITHOUT TIME ZONE, \n\tPRIMARY KEY (id), \n\tUNIQUE (username), \n\tUNIQUE (email)\n)\n\n]\n(Background on this error at: https://sqlalche.me/e/20/gkpj)\n', 'context': {}}

2024-11-13 17:46:01,311 - None - None - None None
Level: ERROR
Module: logging_config
Message: Application Error: {'timestamp': '2024-11-13T17:46:01.297065', 'error_type': 'IntegrityError', 'error_message': '(psycopg2.errors.UniqueViolation) duplicate key value violates unique constraint "pg_class_relname_nsp_index"\nDETAIL:  Key (relname, relnamespace)=(user_id_seq, 360560) already exists.\n\n[SQL: \nCREATE TABLE "user" (\n\tid SERIAL NOT NULL, \n\tusername VARCHAR(64) NOT NULL, \n\temail VARCHAR(120) NOT NULL, \n\tpassword_hash VARCHAR(256), \n\tsubscription_type VARCHAR(20), \n\tsubscription_end_date TIMESTAMP WITHOUT TIME ZONE, \n\tmonthly_ai_analysis_count INTEGER, \n\tlast_analysis_reset TIMESTAMP WITHOUT TIME ZONE, \n\tPRIMARY KEY (id), \n\tUNIQUE (username), \n\tUNIQUE (email)\n)\n\n]\n(Background on this error at: https://sqlalche.me/e/20/gkpj)', 'traceback': 'Traceback (most recent call last):\n  File "/home/runner/DreamShare/.pythonlibs/lib/python3.11/site-packages/sqlalchemy/engine/base.py", line 1967, in _exec_single_context\n    self.dialect.do_execute(\n  File "/home/runner/DreamShare/.pythonlibs/lib/python3.11/site-packages/sqlalchemy/engine/default.py", line 941, in do_execute\n    cursor.execute(statement, parameters)\npsycopg2.errors.UniqueViolation: duplicate key value violates unique constraint "pg_class_relname_nsp_index"\nDETAIL:  Key (relname, relnamespace)=(user_id_seq, 360560) already exists.\n\n\nThe above exception was the direct cause of the following exception:\n\nTraceback (most recent call last):\n  File "/home/runner/DreamShare/app.py", line 78, in create_app\n    db.create_all()\n  File "/home/runner/DreamShare/.pythonlibs/lib/python3.11/site-packages/flask_sqlalchemy/extension.py", line 900, in create_all\n    self._call_for_binds(bind_key, "create_all")\n  File "/home/runner/DreamShare/.pythonlibs/lib/python3.11/site-packages/flask_sqlalchemy/extension.py", line 881, in _call_for_binds\n    getattr(metadata, op_name)(bind=engine)\n  File "/home/runner/DreamShare/.pythonlibs/lib/python3.11/site-packages/sqlalchemy/sql/schema.py", line 5868, in create_all\n    bind._run_ddl_visitor(\n  File "/home/runner/DreamShare/.pythonlibs/lib/python3.11/site-packages/sqlalchemy/engine/base.py", line 3253, in _run_ddl_visitor\n    conn._run_ddl_visitor(visitorcallable, element, **kwargs)\n  File "/home/runner/DreamShare/.pythonlibs/lib/python3.11/site-packages/sqlalchemy/engine/base.py", line 2459, in _run_ddl_visitor\n    visitorcallable(self.dialect, self, **kwargs).traverse_single(element)\n  File "/home/runner/DreamShare/.pythonlibs/lib/python3.11/site-packages/sqlalchemy/sql/visitors.py", line 664, in traverse_single\n    return meth(obj, **kw)\n           ^^^^^^^^^^^^^^^\n  File "/home/runner/DreamShare/.pythonlibs/lib/python3.11/site-packages/sqlalchemy/sql/ddl.py", line 918, in visit_metadata\n    self.traverse_single(\n  File "/home/runner/DreamShare/.pythonlibs/lib/python3.11/site-packages/sqlalchemy/sql/visitors.py", line 664, in traverse_single\n    return meth(obj, **kw)\n           ^^^^^^^^^^^^^^^\n  File "/home/runner/DreamShare/.pythonlibs/lib/python3.11/site-packages/sqlalchemy/sql/ddl.py", line 956, in visit_table\n    )._invoke_with(self.connection)\n      ^^^^^^^^^^^^^^^^^^^^^^^^^^^^^\n  File "/home/runner/DreamShare/.pythonlibs/lib/python3.11/site-packages/sqlalchemy/sql/ddl.py", line 314, in _invoke_with\n    return bind.execute(self)\n           ^^^^^^^^^^^^^^^^^^\n  File "/home/runner/DreamShare/.pythonlibs/lib/python3.11/site-packages/sqlalchemy/engine/base.py", line 1418, in execute\n    return meth(\n           ^^^^^\n  File "/home/runner/DreamShare/.pythonlibs/lib/python3.11/site-packages/sqlalchemy/sql/ddl.py", line 180, in _execute_on_connection\n    return connection._execute_ddl(\n           ^^^^^^^^^^^^^^^^^^^^^^^^\n  File "/home/runner/DreamShare/.pythonlibs/lib/python3.11/site-packages/sqlalchemy/engine/base.py", line 1529, in _execute_ddl\n    ret = self._execute_context(\n          ^^^^^^^^^^^^^^^^^^^^^^\n  File "/home/runner/DreamShare/.pythonlibs/lib/python3.11/site-packages/sqlalchemy/engine/base.py", line 1846, in _execute_context\n    return self._exec_single_context(\n           ^^^^^^^^^^^^^^^^^^^^^^^^^^\n  File "/home/runner/DreamShare/.pythonlibs/lib/python3.11/site-packages/sqlalchemy/engine/base.py", line 1986, in _exec_single_context\n    self._handle_dbapi_exception(\n  File "/home/runner/DreamShare/.pythonlibs/lib/python3.11/site-packages/sqlalchemy/engine/base.py", line 2355, in _handle_dbapi_exception\n    raise sqlalchemy_exception.with_traceback(exc_info[2]) from e\n  File "/home/runner/DreamShare/.pythonlibs/lib/python3.11/site-packages/sqlalchemy/engine/base.py", line 1967, in _exec_single_context\n    self.dialect.do_execute(\n  File "/home/runner/DreamShare/.pythonlibs/lib/python3.11/site-packages/sqlalchemy/engine/default.py", line 941, in do_execute\n    cursor.execute(statement, parameters)\nsqlalchemy.exc.IntegrityError: (psycopg2.errors.UniqueViolation) duplicate key value violates unique constraint "pg_class_relname_nsp_index"\nDETAIL:  Key (relname, relnamespace)=(user_id_seq, 360560) already exists.\n\n[SQL: \nCREATE TABLE "user" (\n\tid SERIAL NOT NULL, \n\tusername VARCHAR(64) NOT NULL, \n\temail VARCHAR(120) NOT NULL, \n\tpassword_hash VARCHAR(256), \n\tsubscription_type VARCHAR(20), \n\tsubscription_end_date TIMESTAMP WITHOUT TIME ZONE, \n\tmonthly_ai_analysis_count INTEGER, \n\tlast_analysis_reset TIMESTAMP WITHOUT TIME ZONE, \n\tPRIMARY KEY (id), \n\tUNIQUE (username), \n\tUNIQUE (email)\n)\n\n]\n(Background on this error at: https://sqlalche.me/e/20/gkpj)\n', 'context': {}}

2024-11-13 17:46:02,994 - None - None - None None
Level: ERROR
Module: logging_config
Message: Application Error: {'timestamp': '2024-11-13T17:46:02.990026', 'error_type': 'IntegrityError', 'error_message': '(psycopg2.errors.UniqueViolation) duplicate key value violates unique constraint "pg_class_relname_nsp_index"\nDETAIL:  Key (relname, relnamespace)=(user_id_seq, 360560) already exists.\n\n[SQL: \nCREATE TABLE "user" (\n\tid SERIAL NOT NULL, \n\tusername VARCHAR(64) NOT NULL, \n\temail VARCHAR(120) NOT NULL, \n\tpassword_hash VARCHAR(256), \n\tsubscription_type VARCHAR(20), \n\tsubscription_end_date TIMESTAMP WITHOUT TIME ZONE, \n\tmonthly_ai_analysis_count INTEGER, \n\tlast_analysis_reset TIMESTAMP WITHOUT TIME ZONE, \n\tPRIMARY KEY (id), \n\tUNIQUE (username), \n\tUNIQUE (email)\n)\n\n]\n(Background on this error at: https://sqlalche.me/e/20/gkpj)', 'traceback': 'Traceback (most recent call last):\n  File "/home/runner/DreamShare/.pythonlibs/lib/python3.11/site-packages/sqlalchemy/engine/base.py", line 1967, in _exec_single_context\n    self.dialect.do_execute(\n  File "/home/runner/DreamShare/.pythonlibs/lib/python3.11/site-packages/sqlalchemy/engine/default.py", line 941, in do_execute\n    cursor.execute(statement, parameters)\npsycopg2.errors.UniqueViolation: duplicate key value violates unique constraint "pg_class_relname_nsp_index"\nDETAIL:  Key (relname, relnamespace)=(user_id_seq, 360560) already exists.\n\n\nThe above exception was the direct cause of the following exception:\n\nTraceback (most recent call last):\n  File "/home/runner/DreamShare/app.py", line 78, in create_app\n    db.create_all()\n  File "/home/runner/DreamShare/.pythonlibs/lib/python3.11/site-packages/flask_sqlalchemy/extension.py", line 900, in create_all\n    self._call_for_binds(bind_key, "create_all")\n  File "/home/runner/DreamShare/.pythonlibs/lib/python3.11/site-packages/flask_sqlalchemy/extension.py", line 881, in _call_for_binds\n    getattr(metadata, op_name)(bind=engine)\n  File "/home/runner/DreamShare/.pythonlibs/lib/python3.11/site-packages/sqlalchemy/sql/schema.py", line 5868, in create_all\n    bind._run_ddl_visitor(\n  File "/home/runner/DreamShare/.pythonlibs/lib/python3.11/site-packages/sqlalchemy/engine/base.py", line 3253, in _run_ddl_visitor\n    conn._run_ddl_visitor(visitorcallable, element, **kwargs)\n  File "/home/runner/DreamShare/.pythonlibs/lib/python3.11/site-packages/sqlalchemy/engine/base.py", line 2459, in _run_ddl_visitor\n    visitorcallable(self.dialect, self, **kwargs).traverse_single(element)\n  File "/home/runner/DreamShare/.pythonlibs/lib/python3.11/site-packages/sqlalchemy/sql/visitors.py", line 664, in traverse_single\n    return meth(obj, **kw)\n           ^^^^^^^^^^^^^^^\n  File "/home/runner/DreamShare/.pythonlibs/lib/python3.11/site-packages/sqlalchemy/sql/ddl.py", line 918, in visit_metadata\n    self.traverse_single(\n  File "/home/runner/DreamShare/.pythonlibs/lib/python3.11/site-packages/sqlalchemy/sql/visitors.py", line 664, in traverse_single\n    return meth(obj, **kw)\n           ^^^^^^^^^^^^^^^\n  File "/home/runner/DreamShare/.pythonlibs/lib/python3.11/site-packages/sqlalchemy/sql/ddl.py", line 956, in visit_table\n    )._invoke_with(self.connection)\n      ^^^^^^^^^^^^^^^^^^^^^^^^^^^^^\n  File "/home/runner/DreamShare/.pythonlibs/lib/python3.11/site-packages/sqlalchemy/sql/ddl.py", line 314, in _invoke_with\n    return bind.execute(self)\n           ^^^^^^^^^^^^^^^^^^\n  File "/home/runner/DreamShare/.pythonlibs/lib/python3.11/site-packages/sqlalchemy/engine/base.py", line 1418, in execute\n    return meth(\n           ^^^^^\n  File "/home/runner/DreamShare/.pythonlibs/lib/python3.11/site-packages/sqlalchemy/sql/ddl.py", line 180, in _execute_on_connection\n    return connection._execute_ddl(\n           ^^^^^^^^^^^^^^^^^^^^^^^^\n  File "/home/runner/DreamShare/.pythonlibs/lib/python3.11/site-packages/sqlalchemy/engine/base.py", line 1529, in _execute_ddl\n    ret = self._execute_context(\n          ^^^^^^^^^^^^^^^^^^^^^^\n  File "/home/runner/DreamShare/.pythonlibs/lib/python3.11/site-packages/sqlalchemy/engine/base.py", line 1846, in _execute_context\n    return self._exec_single_context(\n           ^^^^^^^^^^^^^^^^^^^^^^^^^^\n  File "/home/runner/DreamShare/.pythonlibs/lib/python3.11/site-packages/sqlalchemy/engine/base.py", line 1986, in _exec_single_context\n    self._handle_dbapi_exception(\n  File "/home/runner/DreamShare/.pythonlibs/lib/python3.11/site-packages/sqlalchemy/engine/base.py", line 2355, in _handle_dbapi_exception\n    raise sqlalchemy_exception.with_traceback(exc_info[2]) from e\n  File "/home/runner/DreamShare/.pythonlibs/lib/python3.11/site-packages/sqlalchemy/engine/base.py", line 1967, in _exec_single_context\n    self.dialect.do_execute(\n  File "/home/runner/DreamShare/.pythonlibs/lib/python3.11/site-packages/sqlalchemy/engine/default.py", line 941, in do_execute\n    cursor.execute(statement, parameters)\nsqlalchemy.exc.IntegrityError: (psycopg2.errors.UniqueViolation) duplicate key value violates unique constraint "pg_class_relname_nsp_index"\nDETAIL:  Key (relname, relnamespace)=(user_id_seq, 360560) already exists.\n\n[SQL: \nCREATE TABLE "user" (\n\tid SERIAL NOT NULL, \n\tusername VARCHAR(64) NOT NULL, \n\temail VARCHAR(120) NOT NULL, \n\tpassword_hash VARCHAR(256), \n\tsubscription_type VARCHAR(20), \n\tsubscription_end_date TIMESTAMP WITHOUT TIME ZONE, \n\tmonthly_ai_analysis_count INTEGER, \n\tlast_analysis_reset TIMESTAMP WITHOUT TIME ZONE, \n\tPRIMARY KEY (id), \n\tUNIQUE (username), \n\tUNIQUE (email)\n)\n\n]\n(Background on this error at: https://sqlalche.me/e/20/gkpj)\n', 'context': {}}

2024-11-13 17:46:02,994 - None - None - None None
Level: ERROR
Module: logging_config
Message: Application Error: {'timestamp': '2024-11-13T17:46:02.990026', 'error_type': 'IntegrityError', 'error_message': '(psycopg2.errors.UniqueViolation) duplicate key value violates unique constraint "pg_class_relname_nsp_index"\nDETAIL:  Key (relname, relnamespace)=(user_id_seq, 360560) already exists.\n\n[SQL: \nCREATE TABLE "user" (\n\tid SERIAL NOT NULL, \n\tusername VARCHAR(64) NOT NULL, \n\temail VARCHAR(120) NOT NULL, \n\tpassword_hash VARCHAR(256), \n\tsubscription_type VARCHAR(20), \n\tsubscription_end_date TIMESTAMP WITHOUT TIME ZONE, \n\tmonthly_ai_analysis_count INTEGER, \n\tlast_analysis_reset TIMESTAMP WITHOUT TIME ZONE, \n\tPRIMARY KEY (id), \n\tUNIQUE (username), \n\tUNIQUE (email)\n)\n\n]\n(Background on this error at: https://sqlalche.me/e/20/gkpj)', 'traceback': 'Traceback (most recent call last):\n  File "/home/runner/DreamShare/.pythonlibs/lib/python3.11/site-packages/sqlalchemy/engine/base.py", line 1967, in _exec_single_context\n    self.dialect.do_execute(\n  File "/home/runner/DreamShare/.pythonlibs/lib/python3.11/site-packages/sqlalchemy/engine/default.py", line 941, in do_execute\n    cursor.execute(statement, parameters)\npsycopg2.errors.UniqueViolation: duplicate key value violates unique constraint "pg_class_relname_nsp_index"\nDETAIL:  Key (relname, relnamespace)=(user_id_seq, 360560) already exists.\n\n\nThe above exception was the direct cause of the following exception:\n\nTraceback (most recent call last):\n  File "/home/runner/DreamShare/app.py", line 78, in create_app\n    db.create_all()\n  File "/home/runner/DreamShare/.pythonlibs/lib/python3.11/site-packages/flask_sqlalchemy/extension.py", line 900, in create_all\n    self._call_for_binds(bind_key, "create_all")\n  File "/home/runner/DreamShare/.pythonlibs/lib/python3.11/site-packages/flask_sqlalchemy/extension.py", line 881, in _call_for_binds\n    getattr(metadata, op_name)(bind=engine)\n  File "/home/runner/DreamShare/.pythonlibs/lib/python3.11/site-packages/sqlalchemy/sql/schema.py", line 5868, in create_all\n    bind._run_ddl_visitor(\n  File "/home/runner/DreamShare/.pythonlibs/lib/python3.11/site-packages/sqlalchemy/engine/base.py", line 3253, in _run_ddl_visitor\n    conn._run_ddl_visitor(visitorcallable, element, **kwargs)\n  File "/home/runner/DreamShare/.pythonlibs/lib/python3.11/site-packages/sqlalchemy/engine/base.py", line 2459, in _run_ddl_visitor\n    visitorcallable(self.dialect, self, **kwargs).traverse_single(element)\n  File "/home/runner/DreamShare/.pythonlibs/lib/python3.11/site-packages/sqlalchemy/sql/visitors.py", line 664, in traverse_single\n    return meth(obj, **kw)\n           ^^^^^^^^^^^^^^^\n  File "/home/runner/DreamShare/.pythonlibs/lib/python3.11/site-packages/sqlalchemy/sql/ddl.py", line 918, in visit_metadata\n    self.traverse_single(\n  File "/home/runner/DreamShare/.pythonlibs/lib/python3.11/site-packages/sqlalchemy/sql/visitors.py", line 664, in traverse_single\n    return meth(obj, **kw)\n           ^^^^^^^^^^^^^^^\n  File "/home/runner/DreamShare/.pythonlibs/lib/python3.11/site-packages/sqlalchemy/sql/ddl.py", line 956, in visit_table\n    )._invoke_with(self.connection)\n      ^^^^^^^^^^^^^^^^^^^^^^^^^^^^^\n  File "/home/runner/DreamShare/.pythonlibs/lib/python3.11/site-packages/sqlalchemy/sql/ddl.py", line 314, in _invoke_with\n    return bind.execute(self)\n           ^^^^^^^^^^^^^^^^^^\n  File "/home/runner/DreamShare/.pythonlibs/lib/python3.11/site-packages/sqlalchemy/engine/base.py", line 1418, in execute\n    return meth(\n           ^^^^^\n  File "/home/runner/DreamShare/.pythonlibs/lib/python3.11/site-packages/sqlalchemy/sql/ddl.py", line 180, in _execute_on_connection\n    return connection._execute_ddl(\n           ^^^^^^^^^^^^^^^^^^^^^^^^\n  File "/home/runner/DreamShare/.pythonlibs/lib/python3.11/site-packages/sqlalchemy/engine/base.py", line 1529, in _execute_ddl\n    ret = self._execute_context(\n          ^^^^^^^^^^^^^^^^^^^^^^\n  File "/home/runner/DreamShare/.pythonlibs/lib/python3.11/site-packages/sqlalchemy/engine/base.py", line 1846, in _execute_context\n    return self._exec_single_context(\n           ^^^^^^^^^^^^^^^^^^^^^^^^^^\n  File "/home/runner/DreamShare/.pythonlibs/lib/python3.11/site-packages/sqlalchemy/engine/base.py", line 1986, in _exec_single_context\n    self._handle_dbapi_exception(\n  File "/home/runner/DreamShare/.pythonlibs/lib/python3.11/site-packages/sqlalchemy/engine/base.py", line 2355, in _handle_dbapi_exception\n    raise sqlalchemy_exception.with_traceback(exc_info[2]) from e\n  File "/home/runner/DreamShare/.pythonlibs/lib/python3.11/site-packages/sqlalchemy/engine/base.py", line 1967, in _exec_single_context\n    self.dialect.do_execute(\n  File "/home/runner/DreamShare/.pythonlibs/lib/python3.11/site-packages/sqlalchemy/engine/default.py", line 941, in do_execute\n    cursor.execute(statement, parameters)\nsqlalchemy.exc.IntegrityError: (psycopg2.errors.UniqueViolation) duplicate key value violates unique constraint "pg_class_relname_nsp_index"\nDETAIL:  Key (relname, relnamespace)=(user_id_seq, 360560) already exists.\n\n[SQL: \nCREATE TABLE "user" (\n\tid SERIAL NOT NULL, \n\tusername VARCHAR(64) NOT NULL, \n\temail VARCHAR(120) NOT NULL, \n\tpassword_hash VARCHAR(256), \n\tsubscription_type VARCHAR(20), \n\tsubscription_end_date TIMESTAMP WITHOUT TIME ZONE, \n\tmonthly_ai_analysis_count INTEGER, \n\tlast_analysis_reset TIMESTAMP WITHOUT TIME ZONE, \n\tPRIMARY KEY (id), \n\tUNIQUE (username), \n\tUNIQUE (email)\n)\n\n]\n(Background on this error at: https://sqlalche.me/e/20/gkpj)\n', 'context': {}}

2024-11-13 17:46:02,994 - None - None - None None
Level: ERROR
Module: logging_config
Message: Application Error: {'timestamp': '2024-11-13T17:46:02.990026', 'error_type': 'IntegrityError', 'error_message': '(psycopg2.errors.UniqueViolation) duplicate key value violates unique constraint "pg_class_relname_nsp_index"\nDETAIL:  Key (relname, relnamespace)=(user_id_seq, 360560) already exists.\n\n[SQL: \nCREATE TABLE "user" (\n\tid SERIAL NOT NULL, \n\tusername VARCHAR(64) NOT NULL, \n\temail VARCHAR(120) NOT NULL, \n\tpassword_hash VARCHAR(256), \n\tsubscription_type VARCHAR(20), \n\tsubscription_end_date TIMESTAMP WITHOUT TIME ZONE, \n\tmonthly_ai_analysis_count INTEGER, \n\tlast_analysis_reset TIMESTAMP WITHOUT TIME ZONE, \n\tPRIMARY KEY (id), \n\tUNIQUE (username), \n\tUNIQUE (email)\n)\n\n]\n(Background on this error at: https://sqlalche.me/e/20/gkpj)', 'traceback': 'Traceback (most recent call last):\n  File "/home/runner/DreamShare/.pythonlibs/lib/python3.11/site-packages/sqlalchemy/engine/base.py", line 1967, in _exec_single_context\n    self.dialect.do_execute(\n  File "/home/runner/DreamShare/.pythonlibs/lib/python3.11/site-packages/sqlalchemy/engine/default.py", line 941, in do_execute\n    cursor.execute(statement, parameters)\npsycopg2.errors.UniqueViolation: duplicate key value violates unique constraint "pg_class_relname_nsp_index"\nDETAIL:  Key (relname, relnamespace)=(user_id_seq, 360560) already exists.\n\n\nThe above exception was the direct cause of the following exception:\n\nTraceback (most recent call last):\n  File "/home/runner/DreamShare/app.py", line 78, in create_app\n    db.create_all()\n  File "/home/runner/DreamShare/.pythonlibs/lib/python3.11/site-packages/flask_sqlalchemy/extension.py", line 900, in create_all\n    self._call_for_binds(bind_key, "create_all")\n  File "/home/runner/DreamShare/.pythonlibs/lib/python3.11/site-packages/flask_sqlalchemy/extension.py", line 881, in _call_for_binds\n    getattr(metadata, op_name)(bind=engine)\n  File "/home/runner/DreamShare/.pythonlibs/lib/python3.11/site-packages/sqlalchemy/sql/schema.py", line 5868, in create_all\n    bind._run_ddl_visitor(\n  File "/home/runner/DreamShare/.pythonlibs/lib/python3.11/site-packages/sqlalchemy/engine/base.py", line 3253, in _run_ddl_visitor\n    conn._run_ddl_visitor(visitorcallable, element, **kwargs)\n  File "/home/runner/DreamShare/.pythonlibs/lib/python3.11/site-packages/sqlalchemy/engine/base.py", line 2459, in _run_ddl_visitor\n    visitorcallable(self.dialect, self, **kwargs).traverse_single(element)\n  File "/home/runner/DreamShare/.pythonlibs/lib/python3.11/site-packages/sqlalchemy/sql/visitors.py", line 664, in traverse_single\n    return meth(obj, **kw)\n           ^^^^^^^^^^^^^^^\n  File "/home/runner/DreamShare/.pythonlibs/lib/python3.11/site-packages/sqlalchemy/sql/ddl.py", line 918, in visit_metadata\n    self.traverse_single(\n  File "/home/runner/DreamShare/.pythonlibs/lib/python3.11/site-packages/sqlalchemy/sql/visitors.py", line 664, in traverse_single\n    return meth(obj, **kw)\n           ^^^^^^^^^^^^^^^\n  File "/home/runner/DreamShare/.pythonlibs/lib/python3.11/site-packages/sqlalchemy/sql/ddl.py", line 956, in visit_table\n    )._invoke_with(self.connection)\n      ^^^^^^^^^^^^^^^^^^^^^^^^^^^^^\n  File "/home/runner/DreamShare/.pythonlibs/lib/python3.11/site-packages/sqlalchemy/sql/ddl.py", line 314, in _invoke_with\n    return bind.execute(self)\n           ^^^^^^^^^^^^^^^^^^\n  File "/home/runner/DreamShare/.pythonlibs/lib/python3.11/site-packages/sqlalchemy/engine/base.py", line 1418, in execute\n    return meth(\n           ^^^^^\n  File "/home/runner/DreamShare/.pythonlibs/lib/python3.11/site-packages/sqlalchemy/sql/ddl.py", line 180, in _execute_on_connection\n    return connection._execute_ddl(\n           ^^^^^^^^^^^^^^^^^^^^^^^^\n  File "/home/runner/DreamShare/.pythonlibs/lib/python3.11/site-packages/sqlalchemy/engine/base.py", line 1529, in _execute_ddl\n    ret = self._execute_context(\n          ^^^^^^^^^^^^^^^^^^^^^^\n  File "/home/runner/DreamShare/.pythonlibs/lib/python3.11/site-packages/sqlalchemy/engine/base.py", line 1846, in _execute_context\n    return self._exec_single_context(\n           ^^^^^^^^^^^^^^^^^^^^^^^^^^\n  File "/home/runner/DreamShare/.pythonlibs/lib/python3.11/site-packages/sqlalchemy/engine/base.py", line 1986, in _exec_single_context\n    self._handle_dbapi_exception(\n  File "/home/runner/DreamShare/.pythonlibs/lib/python3.11/site-packages/sqlalchemy/engine/base.py", line 2355, in _handle_dbapi_exception\n    raise sqlalchemy_exception.with_traceback(exc_info[2]) from e\n  File "/home/runner/DreamShare/.pythonlibs/lib/python3.11/site-packages/sqlalchemy/engine/base.py", line 1967, in _exec_single_context\n    self.dialect.do_execute(\n  File "/home/runner/DreamShare/.pythonlibs/lib/python3.11/site-packages/sqlalchemy/engine/default.py", line 941, in do_execute\n    cursor.execute(statement, parameters)\nsqlalchemy.exc.IntegrityError: (psycopg2.errors.UniqueViolation) duplicate key value violates unique constraint "pg_class_relname_nsp_index"\nDETAIL:  Key (relname, relnamespace)=(user_id_seq, 360560) already exists.\n\n[SQL: \nCREATE TABLE "user" (\n\tid SERIAL NOT NULL, \n\tusername VARCHAR(64) NOT NULL, \n\temail VARCHAR(120) NOT NULL, \n\tpassword_hash VARCHAR(256), \n\tsubscription_type VARCHAR(20), \n\tsubscription_end_date TIMESTAMP WITHOUT TIME ZONE, \n\tmonthly_ai_analysis_count INTEGER, \n\tlast_analysis_reset TIMESTAMP WITHOUT TIME ZONE, \n\tPRIMARY KEY (id), \n\tUNIQUE (username), \n\tUNIQUE (email)\n)\n\n]\n(Background on this error at: https://sqlalche.me/e/20/gkpj)\n', 'context': {}}

2024-11-13 17:46:04,683 - None - None - None None
Level: ERROR
Module: logging_config
Message: Application Error: {'timestamp': '2024-11-13T17:46:04.682217', 'error_type': 'IntegrityError', 'error_message': '(psycopg2.errors.UniqueViolation) duplicate key value violates unique constraint "pg_class_relname_nsp_index"\nDETAIL:  Key (relname, relnamespace)=(user_id_seq, 360560) already exists.\n\n[SQL: \nCREATE TABLE "user" (\n\tid SERIAL NOT NULL, \n\tusername VARCHAR(64) NOT NULL, \n\temail VARCHAR(120) NOT NULL, \n\tpassword_hash VARCHAR(256), \n\tsubscription_type VARCHAR(20), \n\tsubscription_end_date TIMESTAMP WITHOUT TIME ZONE, \n\tmonthly_ai_analysis_count INTEGER, \n\tlast_analysis_reset TIMESTAMP WITHOUT TIME ZONE, \n\tPRIMARY KEY (id), \n\tUNIQUE (username), \n\tUNIQUE (email)\n)\n\n]\n(Background on this error at: https://sqlalche.me/e/20/gkpj)', 'traceback': 'Traceback (most recent call last):\n  File "/home/runner/DreamShare/.pythonlibs/lib/python3.11/site-packages/sqlalchemy/engine/base.py", line 1967, in _exec_single_context\n    self.dialect.do_execute(\n  File "/home/runner/DreamShare/.pythonlibs/lib/python3.11/site-packages/sqlalchemy/engine/default.py", line 941, in do_execute\n    cursor.execute(statement, parameters)\npsycopg2.errors.UniqueViolation: duplicate key value violates unique constraint "pg_class_relname_nsp_index"\nDETAIL:  Key (relname, relnamespace)=(user_id_seq, 360560) already exists.\n\n\nThe above exception was the direct cause of the following exception:\n\nTraceback (most recent call last):\n  File "/home/runner/DreamShare/app.py", line 78, in create_app\n    db.create_all()\n  File "/home/runner/DreamShare/.pythonlibs/lib/python3.11/site-packages/flask_sqlalchemy/extension.py", line 900, in create_all\n    self._call_for_binds(bind_key, "create_all")\n  File "/home/runner/DreamShare/.pythonlibs/lib/python3.11/site-packages/flask_sqlalchemy/extension.py", line 881, in _call_for_binds\n    getattr(metadata, op_name)(bind=engine)\n  File "/home/runner/DreamShare/.pythonlibs/lib/python3.11/site-packages/sqlalchemy/sql/schema.py", line 5868, in create_all\n    bind._run_ddl_visitor(\n  File "/home/runner/DreamShare/.pythonlibs/lib/python3.11/site-packages/sqlalchemy/engine/base.py", line 3253, in _run_ddl_visitor\n    conn._run_ddl_visitor(visitorcallable, element, **kwargs)\n  File "/home/runner/DreamShare/.pythonlibs/lib/python3.11/site-packages/sqlalchemy/engine/base.py", line 2459, in _run_ddl_visitor\n    visitorcallable(self.dialect, self, **kwargs).traverse_single(element)\n  File "/home/runner/DreamShare/.pythonlibs/lib/python3.11/site-packages/sqlalchemy/sql/visitors.py", line 664, in traverse_single\n    return meth(obj, **kw)\n           ^^^^^^^^^^^^^^^\n  File "/home/runner/DreamShare/.pythonlibs/lib/python3.11/site-packages/sqlalchemy/sql/ddl.py", line 918, in visit_metadata\n    self.traverse_single(\n  File "/home/runner/DreamShare/.pythonlibs/lib/python3.11/site-packages/sqlalchemy/sql/visitors.py", line 664, in traverse_single\n    return meth(obj, **kw)\n           ^^^^^^^^^^^^^^^\n  File "/home/runner/DreamShare/.pythonlibs/lib/python3.11/site-packages/sqlalchemy/sql/ddl.py", line 956, in visit_table\n    )._invoke_with(self.connection)\n      ^^^^^^^^^^^^^^^^^^^^^^^^^^^^^\n  File "/home/runner/DreamShare/.pythonlibs/lib/python3.11/site-packages/sqlalchemy/sql/ddl.py", line 314, in _invoke_with\n    return bind.execute(self)\n           ^^^^^^^^^^^^^^^^^^\n  File "/home/runner/DreamShare/.pythonlibs/lib/python3.11/site-packages/sqlalchemy/engine/base.py", line 1418, in execute\n    return meth(\n           ^^^^^\n  File "/home/runner/DreamShare/.pythonlibs/lib/python3.11/site-packages/sqlalchemy/sql/ddl.py", line 180, in _execute_on_connection\n    return connection._execute_ddl(\n           ^^^^^^^^^^^^^^^^^^^^^^^^\n  File "/home/runner/DreamShare/.pythonlibs/lib/python3.11/site-packages/sqlalchemy/engine/base.py", line 1529, in _execute_ddl\n    ret = self._execute_context(\n          ^^^^^^^^^^^^^^^^^^^^^^\n  File "/home/runner/DreamShare/.pythonlibs/lib/python3.11/site-packages/sqlalchemy/engine/base.py", line 1846, in _execute_context\n    return self._exec_single_context(\n           ^^^^^^^^^^^^^^^^^^^^^^^^^^\n  File "/home/runner/DreamShare/.pythonlibs/lib/python3.11/site-packages/sqlalchemy/engine/base.py", line 1986, in _exec_single_context\n    self._handle_dbapi_exception(\n  File "/home/runner/DreamShare/.pythonlibs/lib/python3.11/site-packages/sqlalchemy/engine/base.py", line 2355, in _handle_dbapi_exception\n    raise sqlalchemy_exception.with_traceback(exc_info[2]) from e\n  File "/home/runner/DreamShare/.pythonlibs/lib/python3.11/site-packages/sqlalchemy/engine/base.py", line 1967, in _exec_single_context\n    self.dialect.do_execute(\n  File "/home/runner/DreamShare/.pythonlibs/lib/python3.11/site-packages/sqlalchemy/engine/default.py", line 941, in do_execute\n    cursor.execute(statement, parameters)\nsqlalchemy.exc.IntegrityError: (psycopg2.errors.UniqueViolation) duplicate key value violates unique constraint "pg_class_relname_nsp_index"\nDETAIL:  Key (relname, relnamespace)=(user_id_seq, 360560) already exists.\n\n[SQL: \nCREATE TABLE "user" (\n\tid SERIAL NOT NULL, \n\tusername VARCHAR(64) NOT NULL, \n\temail VARCHAR(120) NOT NULL, \n\tpassword_hash VARCHAR(256), \n\tsubscription_type VARCHAR(20), \n\tsubscription_end_date TIMESTAMP WITHOUT TIME ZONE, \n\tmonthly_ai_analysis_count INTEGER, \n\tlast_analysis_reset TIMESTAMP WITHOUT TIME ZONE, \n\tPRIMARY KEY (id), \n\tUNIQUE (username), \n\tUNIQUE (email)\n)\n\n]\n(Background on this error at: https://sqlalche.me/e/20/gkpj)\n', 'context': {}}

2024-11-13 17:46:04,683 - None - None - None None
Level: ERROR
Module: logging_config
Message: Application Error: {'timestamp': '2024-11-13T17:46:04.682217', 'error_type': 'IntegrityError', 'error_message': '(psycopg2.errors.UniqueViolation) duplicate key value violates unique constraint "pg_class_relname_nsp_index"\nDETAIL:  Key (relname, relnamespace)=(user_id_seq, 360560) already exists.\n\n[SQL: \nCREATE TABLE "user" (\n\tid SERIAL NOT NULL, \n\tusername VARCHAR(64) NOT NULL, \n\temail VARCHAR(120) NOT NULL, \n\tpassword_hash VARCHAR(256), \n\tsubscription_type VARCHAR(20), \n\tsubscription_end_date TIMESTAMP WITHOUT TIME ZONE, \n\tmonthly_ai_analysis_count INTEGER, \n\tlast_analysis_reset TIMESTAMP WITHOUT TIME ZONE, \n\tPRIMARY KEY (id), \n\tUNIQUE (username), \n\tUNIQUE (email)\n)\n\n]\n(Background on this error at: https://sqlalche.me/e/20/gkpj)', 'traceback': 'Traceback (most recent call last):\n  File "/home/runner/DreamShare/.pythonlibs/lib/python3.11/site-packages/sqlalchemy/engine/base.py", line 1967, in _exec_single_context\n    self.dialect.do_execute(\n  File "/home/runner/DreamShare/.pythonlibs/lib/python3.11/site-packages/sqlalchemy/engine/default.py", line 941, in do_execute\n    cursor.execute(statement, parameters)\npsycopg2.errors.UniqueViolation: duplicate key value violates unique constraint "pg_class_relname_nsp_index"\nDETAIL:  Key (relname, relnamespace)=(user_id_seq, 360560) already exists.\n\n\nThe above exception was the direct cause of the following exception:\n\nTraceback (most recent call last):\n  File "/home/runner/DreamShare/app.py", line 78, in create_app\n    db.create_all()\n  File "/home/runner/DreamShare/.pythonlibs/lib/python3.11/site-packages/flask_sqlalchemy/extension.py", line 900, in create_all\n    self._call_for_binds(bind_key, "create_all")\n  File "/home/runner/DreamShare/.pythonlibs/lib/python3.11/site-packages/flask_sqlalchemy/extension.py", line 881, in _call_for_binds\n    getattr(metadata, op_name)(bind=engine)\n  File "/home/runner/DreamShare/.pythonlibs/lib/python3.11/site-packages/sqlalchemy/sql/schema.py", line 5868, in create_all\n    bind._run_ddl_visitor(\n  File "/home/runner/DreamShare/.pythonlibs/lib/python3.11/site-packages/sqlalchemy/engine/base.py", line 3253, in _run_ddl_visitor\n    conn._run_ddl_visitor(visitorcallable, element, **kwargs)\n  File "/home/runner/DreamShare/.pythonlibs/lib/python3.11/site-packages/sqlalchemy/engine/base.py", line 2459, in _run_ddl_visitor\n    visitorcallable(self.dialect, self, **kwargs).traverse_single(element)\n  File "/home/runner/DreamShare/.pythonlibs/lib/python3.11/site-packages/sqlalchemy/sql/visitors.py", line 664, in traverse_single\n    return meth(obj, **kw)\n           ^^^^^^^^^^^^^^^\n  File "/home/runner/DreamShare/.pythonlibs/lib/python3.11/site-packages/sqlalchemy/sql/ddl.py", line 918, in visit_metadata\n    self.traverse_single(\n  File "/home/runner/DreamShare/.pythonlibs/lib/python3.11/site-packages/sqlalchemy/sql/visitors.py", line 664, in traverse_single\n    return meth(obj, **kw)\n           ^^^^^^^^^^^^^^^\n  File "/home/runner/DreamShare/.pythonlibs/lib/python3.11/site-packages/sqlalchemy/sql/ddl.py", line 956, in visit_table\n    )._invoke_with(self.connection)\n      ^^^^^^^^^^^^^^^^^^^^^^^^^^^^^\n  File "/home/runner/DreamShare/.pythonlibs/lib/python3.11/site-packages/sqlalchemy/sql/ddl.py", line 314, in _invoke_with\n    return bind.execute(self)\n           ^^^^^^^^^^^^^^^^^^\n  File "/home/runner/DreamShare/.pythonlibs/lib/python3.11/site-packages/sqlalchemy/engine/base.py", line 1418, in execute\n    return meth(\n           ^^^^^\n  File "/home/runner/DreamShare/.pythonlibs/lib/python3.11/site-packages/sqlalchemy/sql/ddl.py", line 180, in _execute_on_connection\n    return connection._execute_ddl(\n           ^^^^^^^^^^^^^^^^^^^^^^^^\n  File "/home/runner/DreamShare/.pythonlibs/lib/python3.11/site-packages/sqlalchemy/engine/base.py", line 1529, in _execute_ddl\n    ret = self._execute_context(\n          ^^^^^^^^^^^^^^^^^^^^^^\n  File "/home/runner/DreamShare/.pythonlibs/lib/python3.11/site-packages/sqlalchemy/engine/base.py", line 1846, in _execute_context\n    return self._exec_single_context(\n           ^^^^^^^^^^^^^^^^^^^^^^^^^^\n  File "/home/runner/DreamShare/.pythonlibs/lib/python3.11/site-packages/sqlalchemy/engine/base.py", line 1986, in _exec_single_context\n    self._handle_dbapi_exception(\n  File "/home/runner/DreamShare/.pythonlibs/lib/python3.11/site-packages/sqlalchemy/engine/base.py", line 2355, in _handle_dbapi_exception\n    raise sqlalchemy_exception.with_traceback(exc_info[2]) from e\n  File "/home/runner/DreamShare/.pythonlibs/lib/python3.11/site-packages/sqlalchemy/engine/base.py", line 1967, in _exec_single_context\n    self.dialect.do_execute(\n  File "/home/runner/DreamShare/.pythonlibs/lib/python3.11/site-packages/sqlalchemy/engine/default.py", line 941, in do_execute\n    cursor.execute(statement, parameters)\nsqlalchemy.exc.IntegrityError: (psycopg2.errors.UniqueViolation) duplicate key value violates unique constraint "pg_class_relname_nsp_index"\nDETAIL:  Key (relname, relnamespace)=(user_id_seq, 360560) already exists.\n\n[SQL: \nCREATE TABLE "user" (\n\tid SERIAL NOT NULL, \n\tusername VARCHAR(64) NOT NULL, \n\temail VARCHAR(120) NOT NULL, \n\tpassword_hash VARCHAR(256), \n\tsubscription_type VARCHAR(20), \n\tsubscription_end_date TIMESTAMP WITHOUT TIME ZONE, \n\tmonthly_ai_analysis_count INTEGER, \n\tlast_analysis_reset TIMESTAMP WITHOUT TIME ZONE, \n\tPRIMARY KEY (id), \n\tUNIQUE (username), \n\tUNIQUE (email)\n)\n\n]\n(Background on this error at: https://sqlalche.me/e/20/gkpj)\n', 'context': {}}

2024-11-13 17:46:04,683 - None - None - None None
Level: ERROR
Module: logging_config
Message: Application Error: {'timestamp': '2024-11-13T17:46:04.682217', 'error_type': 'IntegrityError', 'error_message': '(psycopg2.errors.UniqueViolation) duplicate key value violates unique constraint "pg_class_relname_nsp_index"\nDETAIL:  Key (relname, relnamespace)=(user_id_seq, 360560) already exists.\n\n[SQL: \nCREATE TABLE "user" (\n\tid SERIAL NOT NULL, \n\tusername VARCHAR(64) NOT NULL, \n\temail VARCHAR(120) NOT NULL, \n\tpassword_hash VARCHAR(256), \n\tsubscription_type VARCHAR(20), \n\tsubscription_end_date TIMESTAMP WITHOUT TIME ZONE, \n\tmonthly_ai_analysis_count INTEGER, \n\tlast_analysis_reset TIMESTAMP WITHOUT TIME ZONE, \n\tPRIMARY KEY (id), \n\tUNIQUE (username), \n\tUNIQUE (email)\n)\n\n]\n(Background on this error at: https://sqlalche.me/e/20/gkpj)', 'traceback': 'Traceback (most recent call last):\n  File "/home/runner/DreamShare/.pythonlibs/lib/python3.11/site-packages/sqlalchemy/engine/base.py", line 1967, in _exec_single_context\n    self.dialect.do_execute(\n  File "/home/runner/DreamShare/.pythonlibs/lib/python3.11/site-packages/sqlalchemy/engine/default.py", line 941, in do_execute\n    cursor.execute(statement, parameters)\npsycopg2.errors.UniqueViolation: duplicate key value violates unique constraint "pg_class_relname_nsp_index"\nDETAIL:  Key (relname, relnamespace)=(user_id_seq, 360560) already exists.\n\n\nThe above exception was the direct cause of the following exception:\n\nTraceback (most recent call last):\n  File "/home/runner/DreamShare/app.py", line 78, in create_app\n    db.create_all()\n  File "/home/runner/DreamShare/.pythonlibs/lib/python3.11/site-packages/flask_sqlalchemy/extension.py", line 900, in create_all\n    self._call_for_binds(bind_key, "create_all")\n  File "/home/runner/DreamShare/.pythonlibs/lib/python3.11/site-packages/flask_sqlalchemy/extension.py", line 881, in _call_for_binds\n    getattr(metadata, op_name)(bind=engine)\n  File "/home/runner/DreamShare/.pythonlibs/lib/python3.11/site-packages/sqlalchemy/sql/schema.py", line 5868, in create_all\n    bind._run_ddl_visitor(\n  File "/home/runner/DreamShare/.pythonlibs/lib/python3.11/site-packages/sqlalchemy/engine/base.py", line 3253, in _run_ddl_visitor\n    conn._run_ddl_visitor(visitorcallable, element, **kwargs)\n  File "/home/runner/DreamShare/.pythonlibs/lib/python3.11/site-packages/sqlalchemy/engine/base.py", line 2459, in _run_ddl_visitor\n    visitorcallable(self.dialect, self, **kwargs).traverse_single(element)\n  File "/home/runner/DreamShare/.pythonlibs/lib/python3.11/site-packages/sqlalchemy/sql/visitors.py", line 664, in traverse_single\n    return meth(obj, **kw)\n           ^^^^^^^^^^^^^^^\n  File "/home/runner/DreamShare/.pythonlibs/lib/python3.11/site-packages/sqlalchemy/sql/ddl.py", line 918, in visit_metadata\n    self.traverse_single(\n  File "/home/runner/DreamShare/.pythonlibs/lib/python3.11/site-packages/sqlalchemy/sql/visitors.py", line 664, in traverse_single\n    return meth(obj, **kw)\n           ^^^^^^^^^^^^^^^\n  File "/home/runner/DreamShare/.pythonlibs/lib/python3.11/site-packages/sqlalchemy/sql/ddl.py", line 956, in visit_table\n    )._invoke_with(self.connection)\n      ^^^^^^^^^^^^^^^^^^^^^^^^^^^^^\n  File "/home/runner/DreamShare/.pythonlibs/lib/python3.11/site-packages/sqlalchemy/sql/ddl.py", line 314, in _invoke_with\n    return bind.execute(self)\n           ^^^^^^^^^^^^^^^^^^\n  File "/home/runner/DreamShare/.pythonlibs/lib/python3.11/site-packages/sqlalchemy/engine/base.py", line 1418, in execute\n    return meth(\n           ^^^^^\n  File "/home/runner/DreamShare/.pythonlibs/lib/python3.11/site-packages/sqlalchemy/sql/ddl.py", line 180, in _execute_on_connection\n    return connection._execute_ddl(\n           ^^^^^^^^^^^^^^^^^^^^^^^^\n  File "/home/runner/DreamShare/.pythonlibs/lib/python3.11/site-packages/sqlalchemy/engine/base.py", line 1529, in _execute_ddl\n    ret = self._execute_context(\n          ^^^^^^^^^^^^^^^^^^^^^^\n  File "/home/runner/DreamShare/.pythonlibs/lib/python3.11/site-packages/sqlalchemy/engine/base.py", line 1846, in _execute_context\n    return self._exec_single_context(\n           ^^^^^^^^^^^^^^^^^^^^^^^^^^\n  File "/home/runner/DreamShare/.pythonlibs/lib/python3.11/site-packages/sqlalchemy/engine/base.py", line 1986, in _exec_single_context\n    self._handle_dbapi_exception(\n  File "/home/runner/DreamShare/.pythonlibs/lib/python3.11/site-packages/sqlalchemy/engine/base.py", line 2355, in _handle_dbapi_exception\n    raise sqlalchemy_exception.with_traceback(exc_info[2]) from e\n  File "/home/runner/DreamShare/.pythonlibs/lib/python3.11/site-packages/sqlalchemy/engine/base.py", line 1967, in _exec_single_context\n    self.dialect.do_execute(\n  File "/home/runner/DreamShare/.pythonlibs/lib/python3.11/site-packages/sqlalchemy/engine/default.py", line 941, in do_execute\n    cursor.execute(statement, parameters)\nsqlalchemy.exc.IntegrityError: (psycopg2.errors.UniqueViolation) duplicate key value violates unique constraint "pg_class_relname_nsp_index"\nDETAIL:  Key (relname, relnamespace)=(user_id_seq, 360560) already exists.\n\n[SQL: \nCREATE TABLE "user" (\n\tid SERIAL NOT NULL, \n\tusername VARCHAR(64) NOT NULL, \n\temail VARCHAR(120) NOT NULL, \n\tpassword_hash VARCHAR(256), \n\tsubscription_type VARCHAR(20), \n\tsubscription_end_date TIMESTAMP WITHOUT TIME ZONE, \n\tmonthly_ai_analysis_count INTEGER, \n\tlast_analysis_reset TIMESTAMP WITHOUT TIME ZONE, \n\tPRIMARY KEY (id), \n\tUNIQUE (username), \n\tUNIQUE (email)\n)\n\n]\n(Background on this error at: https://sqlalche.me/e/20/gkpj)\n', 'context': {}}

2024-11-13 17:46:04,683 - None - None - None None
Level: ERROR
Module: logging_config
Message: Application Error: {'timestamp': '2024-11-13T17:46:04.682217', 'error_type': 'IntegrityError', 'error_message': '(psycopg2.errors.UniqueViolation) duplicate key value violates unique constraint "pg_class_relname_nsp_index"\nDETAIL:  Key (relname, relnamespace)=(user_id_seq, 360560) already exists.\n\n[SQL: \nCREATE TABLE "user" (\n\tid SERIAL NOT NULL, \n\tusername VARCHAR(64) NOT NULL, \n\temail VARCHAR(120) NOT NULL, \n\tpassword_hash VARCHAR(256), \n\tsubscription_type VARCHAR(20), \n\tsubscription_end_date TIMESTAMP WITHOUT TIME ZONE, \n\tmonthly_ai_analysis_count INTEGER, \n\tlast_analysis_reset TIMESTAMP WITHOUT TIME ZONE, \n\tPRIMARY KEY (id), \n\tUNIQUE (username), \n\tUNIQUE (email)\n)\n\n]\n(Background on this error at: https://sqlalche.me/e/20/gkpj)', 'traceback': 'Traceback (most recent call last):\n  File "/home/runner/DreamShare/.pythonlibs/lib/python3.11/site-packages/sqlalchemy/engine/base.py", line 1967, in _exec_single_context\n    self.dialect.do_execute(\n  File "/home/runner/DreamShare/.pythonlibs/lib/python3.11/site-packages/sqlalchemy/engine/default.py", line 941, in do_execute\n    cursor.execute(statement, parameters)\npsycopg2.errors.UniqueViolation: duplicate key value violates unique constraint "pg_class_relname_nsp_index"\nDETAIL:  Key (relname, relnamespace)=(user_id_seq, 360560) already exists.\n\n\nThe above exception was the direct cause of the following exception:\n\nTraceback (most recent call last):\n  File "/home/runner/DreamShare/app.py", line 78, in create_app\n    db.create_all()\n  File "/home/runner/DreamShare/.pythonlibs/lib/python3.11/site-packages/flask_sqlalchemy/extension.py", line 900, in create_all\n    self._call_for_binds(bind_key, "create_all")\n  File "/home/runner/DreamShare/.pythonlibs/lib/python3.11/site-packages/flask_sqlalchemy/extension.py", line 881, in _call_for_binds\n    getattr(metadata, op_name)(bind=engine)\n  File "/home/runner/DreamShare/.pythonlibs/lib/python3.11/site-packages/sqlalchemy/sql/schema.py", line 5868, in create_all\n    bind._run_ddl_visitor(\n  File "/home/runner/DreamShare/.pythonlibs/lib/python3.11/site-packages/sqlalchemy/engine/base.py", line 3253, in _run_ddl_visitor\n    conn._run_ddl_visitor(visitorcallable, element, **kwargs)\n  File "/home/runner/DreamShare/.pythonlibs/lib/python3.11/site-packages/sqlalchemy/engine/base.py", line 2459, in _run_ddl_visitor\n    visitorcallable(self.dialect, self, **kwargs).traverse_single(element)\n  File "/home/runner/DreamShare/.pythonlibs/lib/python3.11/site-packages/sqlalchemy/sql/visitors.py", line 664, in traverse_single\n    return meth(obj, **kw)\n           ^^^^^^^^^^^^^^^\n  File "/home/runner/DreamShare/.pythonlibs/lib/python3.11/site-packages/sqlalchemy/sql/ddl.py", line 918, in visit_metadata\n    self.traverse_single(\n  File "/home/runner/DreamShare/.pythonlibs/lib/python3.11/site-packages/sqlalchemy/sql/visitors.py", line 664, in traverse_single\n    return meth(obj, **kw)\n           ^^^^^^^^^^^^^^^\n  File "/home/runner/DreamShare/.pythonlibs/lib/python3.11/site-packages/sqlalchemy/sql/ddl.py", line 956, in visit_table\n    )._invoke_with(self.connection)\n      ^^^^^^^^^^^^^^^^^^^^^^^^^^^^^\n  File "/home/runner/DreamShare/.pythonlibs/lib/python3.11/site-packages/sqlalchemy/sql/ddl.py", line 314, in _invoke_with\n    return bind.execute(self)\n           ^^^^^^^^^^^^^^^^^^\n  File "/home/runner/DreamShare/.pythonlibs/lib/python3.11/site-packages/sqlalchemy/engine/base.py", line 1418, in execute\n    return meth(\n           ^^^^^\n  File "/home/runner/DreamShare/.pythonlibs/lib/python3.11/site-packages/sqlalchemy/sql/ddl.py", line 180, in _execute_on_connection\n    return connection._execute_ddl(\n           ^^^^^^^^^^^^^^^^^^^^^^^^\n  File "/home/runner/DreamShare/.pythonlibs/lib/python3.11/site-packages/sqlalchemy/engine/base.py", line 1529, in _execute_ddl\n    ret = self._execute_context(\n          ^^^^^^^^^^^^^^^^^^^^^^\n  File "/home/runner/DreamShare/.pythonlibs/lib/python3.11/site-packages/sqlalchemy/engine/base.py", line 1846, in _execute_context\n    return self._exec_single_context(\n           ^^^^^^^^^^^^^^^^^^^^^^^^^^\n  File "/home/runner/DreamShare/.pythonlibs/lib/python3.11/site-packages/sqlalchemy/engine/base.py", line 1986, in _exec_single_context\n    self._handle_dbapi_exception(\n  File "/home/runner/DreamShare/.pythonlibs/lib/python3.11/site-packages/sqlalchemy/engine/base.py", line 2355, in _handle_dbapi_exception\n    raise sqlalchemy_exception.with_traceback(exc_info[2]) from e\n  File "/home/runner/DreamShare/.pythonlibs/lib/python3.11/site-packages/sqlalchemy/engine/base.py", line 1967, in _exec_single_context\n    self.dialect.do_execute(\n  File "/home/runner/DreamShare/.pythonlibs/lib/python3.11/site-packages/sqlalchemy/engine/default.py", line 941, in do_execute\n    cursor.execute(statement, parameters)\nsqlalchemy.exc.IntegrityError: (psycopg2.errors.UniqueViolation) duplicate key value violates unique constraint "pg_class_relname_nsp_index"\nDETAIL:  Key (relname, relnamespace)=(user_id_seq, 360560) already exists.\n\n[SQL: \nCREATE TABLE "user" (\n\tid SERIAL NOT NULL, \n\tusername VARCHAR(64) NOT NULL, \n\temail VARCHAR(120) NOT NULL, \n\tpassword_hash VARCHAR(256), \n\tsubscription_type VARCHAR(20), \n\tsubscription_end_date TIMESTAMP WITHOUT TIME ZONE, \n\tmonthly_ai_analysis_count INTEGER, \n\tlast_analysis_reset TIMESTAMP WITHOUT TIME ZONE, \n\tPRIMARY KEY (id), \n\tUNIQUE (username), \n\tUNIQUE (email)\n)\n\n]\n(Background on this error at: https://sqlalche.me/e/20/gkpj)\n', 'context': {}}

2024-11-13 17:46:04,683 - None - None - None None
Level: ERROR
Module: logging_config
Message: Application Error: {'timestamp': '2024-11-13T17:46:04.682217', 'error_type': 'IntegrityError', 'error_message': '(psycopg2.errors.UniqueViolation) duplicate key value violates unique constraint "pg_class_relname_nsp_index"\nDETAIL:  Key (relname, relnamespace)=(user_id_seq, 360560) already exists.\n\n[SQL: \nCREATE TABLE "user" (\n\tid SERIAL NOT NULL, \n\tusername VARCHAR(64) NOT NULL, \n\temail VARCHAR(120) NOT NULL, \n\tpassword_hash VARCHAR(256), \n\tsubscription_type VARCHAR(20), \n\tsubscription_end_date TIMESTAMP WITHOUT TIME ZONE, \n\tmonthly_ai_analysis_count INTEGER, \n\tlast_analysis_reset TIMESTAMP WITHOUT TIME ZONE, \n\tPRIMARY KEY (id), \n\tUNIQUE (username), \n\tUNIQUE (email)\n)\n\n]\n(Background on this error at: https://sqlalche.me/e/20/gkpj)', 'traceback': 'Traceback (most recent call last):\n  File "/home/runner/DreamShare/.pythonlibs/lib/python3.11/site-packages/sqlalchemy/engine/base.py", line 1967, in _exec_single_context\n    self.dialect.do_execute(\n  File "/home/runner/DreamShare/.pythonlibs/lib/python3.11/site-packages/sqlalchemy/engine/default.py", line 941, in do_execute\n    cursor.execute(statement, parameters)\npsycopg2.errors.UniqueViolation: duplicate key value violates unique constraint "pg_class_relname_nsp_index"\nDETAIL:  Key (relname, relnamespace)=(user_id_seq, 360560) already exists.\n\n\nThe above exception was the direct cause of the following exception:\n\nTraceback (most recent call last):\n  File "/home/runner/DreamShare/app.py", line 78, in create_app\n    db.create_all()\n  File "/home/runner/DreamShare/.pythonlibs/lib/python3.11/site-packages/flask_sqlalchemy/extension.py", line 900, in create_all\n    self._call_for_binds(bind_key, "create_all")\n  File "/home/runner/DreamShare/.pythonlibs/lib/python3.11/site-packages/flask_sqlalchemy/extension.py", line 881, in _call_for_binds\n    getattr(metadata, op_name)(bind=engine)\n  File "/home/runner/DreamShare/.pythonlibs/lib/python3.11/site-packages/sqlalchemy/sql/schema.py", line 5868, in create_all\n    bind._run_ddl_visitor(\n  File "/home/runner/DreamShare/.pythonlibs/lib/python3.11/site-packages/sqlalchemy/engine/base.py", line 3253, in _run_ddl_visitor\n    conn._run_ddl_visitor(visitorcallable, element, **kwargs)\n  File "/home/runner/DreamShare/.pythonlibs/lib/python3.11/site-packages/sqlalchemy/engine/base.py", line 2459, in _run_ddl_visitor\n    visitorcallable(self.dialect, self, **kwargs).traverse_single(element)\n  File "/home/runner/DreamShare/.pythonlibs/lib/python3.11/site-packages/sqlalchemy/sql/visitors.py", line 664, in traverse_single\n    return meth(obj, **kw)\n           ^^^^^^^^^^^^^^^\n  File "/home/runner/DreamShare/.pythonlibs/lib/python3.11/site-packages/sqlalchemy/sql/ddl.py", line 918, in visit_metadata\n    self.traverse_single(\n  File "/home/runner/DreamShare/.pythonlibs/lib/python3.11/site-packages/sqlalchemy/sql/visitors.py", line 664, in traverse_single\n    return meth(obj, **kw)\n           ^^^^^^^^^^^^^^^\n  File "/home/runner/DreamShare/.pythonlibs/lib/python3.11/site-packages/sqlalchemy/sql/ddl.py", line 956, in visit_table\n    )._invoke_with(self.connection)\n      ^^^^^^^^^^^^^^^^^^^^^^^^^^^^^\n  File "/home/runner/DreamShare/.pythonlibs/lib/python3.11/site-packages/sqlalchemy/sql/ddl.py", line 314, in _invoke_with\n    return bind.execute(self)\n           ^^^^^^^^^^^^^^^^^^\n  File "/home/runner/DreamShare/.pythonlibs/lib/python3.11/site-packages/sqlalchemy/engine/base.py", line 1418, in execute\n    return meth(\n           ^^^^^\n  File "/home/runner/DreamShare/.pythonlibs/lib/python3.11/site-packages/sqlalchemy/sql/ddl.py", line 180, in _execute_on_connection\n    return connection._execute_ddl(\n           ^^^^^^^^^^^^^^^^^^^^^^^^\n  File "/home/runner/DreamShare/.pythonlibs/lib/python3.11/site-packages/sqlalchemy/engine/base.py", line 1529, in _execute_ddl\n    ret = self._execute_context(\n          ^^^^^^^^^^^^^^^^^^^^^^\n  File "/home/runner/DreamShare/.pythonlibs/lib/python3.11/site-packages/sqlalchemy/engine/base.py", line 1846, in _execute_context\n    return self._exec_single_context(\n           ^^^^^^^^^^^^^^^^^^^^^^^^^^\n  File "/home/runner/DreamShare/.pythonlibs/lib/python3.11/site-packages/sqlalchemy/engine/base.py", line 1986, in _exec_single_context\n    self._handle_dbapi_exception(\n  File "/home/runner/DreamShare/.pythonlibs/lib/python3.11/site-packages/sqlalchemy/engine/base.py", line 2355, in _handle_dbapi_exception\n    raise sqlalchemy_exception.with_traceback(exc_info[2]) from e\n  File "/home/runner/DreamShare/.pythonlibs/lib/python3.11/site-packages/sqlalchemy/engine/base.py", line 1967, in _exec_single_context\n    self.dialect.do_execute(\n  File "/home/runner/DreamShare/.pythonlibs/lib/python3.11/site-packages/sqlalchemy/engine/default.py", line 941, in do_execute\n    cursor.execute(statement, parameters)\nsqlalchemy.exc.IntegrityError: (psycopg2.errors.UniqueViolation) duplicate key value violates unique constraint "pg_class_relname_nsp_index"\nDETAIL:  Key (relname, relnamespace)=(user_id_seq, 360560) already exists.\n\n[SQL: \nCREATE TABLE "user" (\n\tid SERIAL NOT NULL, \n\tusername VARCHAR(64) NOT NULL, \n\temail VARCHAR(120) NOT NULL, \n\tpassword_hash VARCHAR(256), \n\tsubscription_type VARCHAR(20), \n\tsubscription_end_date TIMESTAMP WITHOUT TIME ZONE, \n\tmonthly_ai_analysis_count INTEGER, \n\tlast_analysis_reset TIMESTAMP WITHOUT TIME ZONE, \n\tPRIMARY KEY (id), \n\tUNIQUE (username), \n\tUNIQUE (email)\n)\n\n]\n(Background on this error at: https://sqlalche.me/e/20/gkpj)\n', 'context': {}}

2024-11-13 17:46:06,552 - None - None - None None
Level: ERROR
Module: logging_config
Message: Application Error: {'timestamp': '2024-11-13T17:46:06.550861', 'error_type': 'ProgrammingError', 'error_message': '(psycopg2.errors.DuplicateTable) relation "user" already exists\n\n[SQL: \nCREATE TABLE "user" (\n\tid SERIAL NOT NULL, \n\tusername VARCHAR(64) NOT NULL, \n\temail VARCHAR(120) NOT NULL, \n\tpassword_hash VARCHAR(256), \n\tsubscription_type VARCHAR(20), \n\tsubscription_end_date TIMESTAMP WITHOUT TIME ZONE, \n\tmonthly_ai_analysis_count INTEGER, \n\tlast_analysis_reset TIMESTAMP WITHOUT TIME ZONE, \n\tPRIMARY KEY (id), \n\tUNIQUE (username), \n\tUNIQUE (email)\n)\n\n]\n(Background on this error at: https://sqlalche.me/e/20/f405)', 'traceback': 'Traceback (most recent call last):\n  File "/home/runner/DreamShare/.pythonlibs/lib/python3.11/site-packages/sqlalchemy/engine/base.py", line 1967, in _exec_single_context\n    self.dialect.do_execute(\n  File "/home/runner/DreamShare/.pythonlibs/lib/python3.11/site-packages/sqlalchemy/engine/default.py", line 941, in do_execute\n    cursor.execute(statement, parameters)\npsycopg2.errors.DuplicateTable: relation "user" already exists\n\n\nThe above exception was the direct cause of the following exception:\n\nTraceback (most recent call last):\n  File "/home/runner/DreamShare/app.py", line 78, in create_app\n    db.create_all()\n  File "/home/runner/DreamShare/.pythonlibs/lib/python3.11/site-packages/flask_sqlalchemy/extension.py", line 900, in create_all\n    self._call_for_binds(bind_key, "create_all")\n  File "/home/runner/DreamShare/.pythonlibs/lib/python3.11/site-packages/flask_sqlalchemy/extension.py", line 881, in _call_for_binds\n    getattr(metadata, op_name)(bind=engine)\n  File "/home/runner/DreamShare/.pythonlibs/lib/python3.11/site-packages/sqlalchemy/sql/schema.py", line 5868, in create_all\n    bind._run_ddl_visitor(\n  File "/home/runner/DreamShare/.pythonlibs/lib/python3.11/site-packages/sqlalchemy/engine/base.py", line 3253, in _run_ddl_visitor\n    conn._run_ddl_visitor(visitorcallable, element, **kwargs)\n  File "/home/runner/DreamShare/.pythonlibs/lib/python3.11/site-packages/sqlalchemy/engine/base.py", line 2459, in _run_ddl_visitor\n    visitorcallable(self.dialect, self, **kwargs).traverse_single(element)\n  File "/home/runner/DreamShare/.pythonlibs/lib/python3.11/site-packages/sqlalchemy/sql/visitors.py", line 664, in traverse_single\n    return meth(obj, **kw)\n           ^^^^^^^^^^^^^^^\n  File "/home/runner/DreamShare/.pythonlibs/lib/python3.11/site-packages/sqlalchemy/sql/ddl.py", line 918, in visit_metadata\n    self.traverse_single(\n  File "/home/runner/DreamShare/.pythonlibs/lib/python3.11/site-packages/sqlalchemy/sql/visitors.py", line 664, in traverse_single\n    return meth(obj, **kw)\n           ^^^^^^^^^^^^^^^\n  File "/home/runner/DreamShare/.pythonlibs/lib/python3.11/site-packages/sqlalchemy/sql/ddl.py", line 956, in visit_table\n    )._invoke_with(self.connection)\n      ^^^^^^^^^^^^^^^^^^^^^^^^^^^^^\n  File "/home/runner/DreamShare/.pythonlibs/lib/python3.11/site-packages/sqlalchemy/sql/ddl.py", line 314, in _invoke_with\n    return bind.execute(self)\n           ^^^^^^^^^^^^^^^^^^\n  File "/home/runner/DreamShare/.pythonlibs/lib/python3.11/site-packages/sqlalchemy/engine/base.py", line 1418, in execute\n    return meth(\n           ^^^^^\n  File "/home/runner/DreamShare/.pythonlibs/lib/python3.11/site-packages/sqlalchemy/sql/ddl.py", line 180, in _execute_on_connection\n    return connection._execute_ddl(\n           ^^^^^^^^^^^^^^^^^^^^^^^^\n  File "/home/runner/DreamShare/.pythonlibs/lib/python3.11/site-packages/sqlalchemy/engine/base.py", line 1529, in _execute_ddl\n    ret = self._execute_context(\n          ^^^^^^^^^^^^^^^^^^^^^^\n  File "/home/runner/DreamShare/.pythonlibs/lib/python3.11/site-packages/sqlalchemy/engine/base.py", line 1846, in _execute_context\n    return self._exec_single_context(\n           ^^^^^^^^^^^^^^^^^^^^^^^^^^\n  File "/home/runner/DreamShare/.pythonlibs/lib/python3.11/site-packages/sqlalchemy/engine/base.py", line 1986, in _exec_single_context\n    self._handle_dbapi_exception(\n  File "/home/runner/DreamShare/.pythonlibs/lib/python3.11/site-packages/sqlalchemy/engine/base.py", line 2355, in _handle_dbapi_exception\n    raise sqlalchemy_exception.with_traceback(exc_info[2]) from e\n  File "/home/runner/DreamShare/.pythonlibs/lib/python3.11/site-packages/sqlalchemy/engine/base.py", line 1967, in _exec_single_context\n    self.dialect.do_execute(\n  File "/home/runner/DreamShare/.pythonlibs/lib/python3.11/site-packages/sqlalchemy/engine/default.py", line 941, in do_execute\n    cursor.execute(statement, parameters)\nsqlalchemy.exc.ProgrammingError: (psycopg2.errors.DuplicateTable) relation "user" already exists\n\n[SQL: \nCREATE TABLE "user" (\n\tid SERIAL NOT NULL, \n\tusername VARCHAR(64) NOT NULL, \n\temail VARCHAR(120) NOT NULL, \n\tpassword_hash VARCHAR(256), \n\tsubscription_type VARCHAR(20), \n\tsubscription_end_date TIMESTAMP WITHOUT TIME ZONE, \n\tmonthly_ai_analysis_count INTEGER, \n\tlast_analysis_reset TIMESTAMP WITHOUT TIME ZONE, \n\tPRIMARY KEY (id), \n\tUNIQUE (username), \n\tUNIQUE (email)\n)\n\n]\n(Background on this error at: https://sqlalche.me/e/20/f405)\n', 'context': {}}

2024-11-13 17:46:06,552 - None - None - None None
Level: ERROR
Module: logging_config
Message: Application Error: {'timestamp': '2024-11-13T17:46:06.550861', 'error_type': 'ProgrammingError', 'error_message': '(psycopg2.errors.DuplicateTable) relation "user" already exists\n\n[SQL: \nCREATE TABLE "user" (\n\tid SERIAL NOT NULL, \n\tusername VARCHAR(64) NOT NULL, \n\temail VARCHAR(120) NOT NULL, \n\tpassword_hash VARCHAR(256), \n\tsubscription_type VARCHAR(20), \n\tsubscription_end_date TIMESTAMP WITHOUT TIME ZONE, \n\tmonthly_ai_analysis_count INTEGER, \n\tlast_analysis_reset TIMESTAMP WITHOUT TIME ZONE, \n\tPRIMARY KEY (id), \n\tUNIQUE (username), \n\tUNIQUE (email)\n)\n\n]\n(Background on this error at: https://sqlalche.me/e/20/f405)', 'traceback': 'Traceback (most recent call last):\n  File "/home/runner/DreamShare/.pythonlibs/lib/python3.11/site-packages/sqlalchemy/engine/base.py", line 1967, in _exec_single_context\n    self.dialect.do_execute(\n  File "/home/runner/DreamShare/.pythonlibs/lib/python3.11/site-packages/sqlalchemy/engine/default.py", line 941, in do_execute\n    cursor.execute(statement, parameters)\npsycopg2.errors.DuplicateTable: relation "user" already exists\n\n\nThe above exception was the direct cause of the following exception:\n\nTraceback (most recent call last):\n  File "/home/runner/DreamShare/app.py", line 78, in create_app\n    db.create_all()\n  File "/home/runner/DreamShare/.pythonlibs/lib/python3.11/site-packages/flask_sqlalchemy/extension.py", line 900, in create_all\n    self._call_for_binds(bind_key, "create_all")\n  File "/home/runner/DreamShare/.pythonlibs/lib/python3.11/site-packages/flask_sqlalchemy/extension.py", line 881, in _call_for_binds\n    getattr(metadata, op_name)(bind=engine)\n  File "/home/runner/DreamShare/.pythonlibs/lib/python3.11/site-packages/sqlalchemy/sql/schema.py", line 5868, in create_all\n    bind._run_ddl_visitor(\n  File "/home/runner/DreamShare/.pythonlibs/lib/python3.11/site-packages/sqlalchemy/engine/base.py", line 3253, in _run_ddl_visitor\n    conn._run_ddl_visitor(visitorcallable, element, **kwargs)\n  File "/home/runner/DreamShare/.pythonlibs/lib/python3.11/site-packages/sqlalchemy/engine/base.py", line 2459, in _run_ddl_visitor\n    visitorcallable(self.dialect, self, **kwargs).traverse_single(element)\n  File "/home/runner/DreamShare/.pythonlibs/lib/python3.11/site-packages/sqlalchemy/sql/visitors.py", line 664, in traverse_single\n    return meth(obj, **kw)\n           ^^^^^^^^^^^^^^^\n  File "/home/runner/DreamShare/.pythonlibs/lib/python3.11/site-packages/sqlalchemy/sql/ddl.py", line 918, in visit_metadata\n    self.traverse_single(\n  File "/home/runner/DreamShare/.pythonlibs/lib/python3.11/site-packages/sqlalchemy/sql/visitors.py", line 664, in traverse_single\n    return meth(obj, **kw)\n           ^^^^^^^^^^^^^^^\n  File "/home/runner/DreamShare/.pythonlibs/lib/python3.11/site-packages/sqlalchemy/sql/ddl.py", line 956, in visit_table\n    )._invoke_with(self.connection)\n      ^^^^^^^^^^^^^^^^^^^^^^^^^^^^^\n  File "/home/runner/DreamShare/.pythonlibs/lib/python3.11/site-packages/sqlalchemy/sql/ddl.py", line 314, in _invoke_with\n    return bind.execute(self)\n           ^^^^^^^^^^^^^^^^^^\n  File "/home/runner/DreamShare/.pythonlibs/lib/python3.11/site-packages/sqlalchemy/engine/base.py", line 1418, in execute\n    return meth(\n           ^^^^^\n  File "/home/runner/DreamShare/.pythonlibs/lib/python3.11/site-packages/sqlalchemy/sql/ddl.py", line 180, in _execute_on_connection\n    return connection._execute_ddl(\n           ^^^^^^^^^^^^^^^^^^^^^^^^\n  File "/home/runner/DreamShare/.pythonlibs/lib/python3.11/site-packages/sqlalchemy/engine/base.py", line 1529, in _execute_ddl\n    ret = self._execute_context(\n          ^^^^^^^^^^^^^^^^^^^^^^\n  File "/home/runner/DreamShare/.pythonlibs/lib/python3.11/site-packages/sqlalchemy/engine/base.py", line 1846, in _execute_context\n    return self._exec_single_context(\n           ^^^^^^^^^^^^^^^^^^^^^^^^^^\n  File "/home/runner/DreamShare/.pythonlibs/lib/python3.11/site-packages/sqlalchemy/engine/base.py", line 1986, in _exec_single_context\n    self._handle_dbapi_exception(\n  File "/home/runner/DreamShare/.pythonlibs/lib/python3.11/site-packages/sqlalchemy/engine/base.py", line 2355, in _handle_dbapi_exception\n    raise sqlalchemy_exception.with_traceback(exc_info[2]) from e\n  File "/home/runner/DreamShare/.pythonlibs/lib/python3.11/site-packages/sqlalchemy/engine/base.py", line 1967, in _exec_single_context\n    self.dialect.do_execute(\n  File "/home/runner/DreamShare/.pythonlibs/lib/python3.11/site-packages/sqlalchemy/engine/default.py", line 941, in do_execute\n    cursor.execute(statement, parameters)\nsqlalchemy.exc.ProgrammingError: (psycopg2.errors.DuplicateTable) relation "user" already exists\n\n[SQL: \nCREATE TABLE "user" (\n\tid SERIAL NOT NULL, \n\tusername VARCHAR(64) NOT NULL, \n\temail VARCHAR(120) NOT NULL, \n\tpassword_hash VARCHAR(256), \n\tsubscription_type VARCHAR(20), \n\tsubscription_end_date TIMESTAMP WITHOUT TIME ZONE, \n\tmonthly_ai_analysis_count INTEGER, \n\tlast_analysis_reset TIMESTAMP WITHOUT TIME ZONE, \n\tPRIMARY KEY (id), \n\tUNIQUE (username), \n\tUNIQUE (email)\n)\n\n]\n(Background on this error at: https://sqlalche.me/e/20/f405)\n', 'context': {}}

2024-11-13 17:46:06,552 - None - None - None None
Level: ERROR
Module: logging_config
Message: Application Error: {'timestamp': '2024-11-13T17:46:06.550861', 'error_type': 'ProgrammingError', 'error_message': '(psycopg2.errors.DuplicateTable) relation "user" already exists\n\n[SQL: \nCREATE TABLE "user" (\n\tid SERIAL NOT NULL, \n\tusername VARCHAR(64) NOT NULL, \n\temail VARCHAR(120) NOT NULL, \n\tpassword_hash VARCHAR(256), \n\tsubscription_type VARCHAR(20), \n\tsubscription_end_date TIMESTAMP WITHOUT TIME ZONE, \n\tmonthly_ai_analysis_count INTEGER, \n\tlast_analysis_reset TIMESTAMP WITHOUT TIME ZONE, \n\tPRIMARY KEY (id), \n\tUNIQUE (username), \n\tUNIQUE (email)\n)\n\n]\n(Background on this error at: https://sqlalche.me/e/20/f405)', 'traceback': 'Traceback (most recent call last):\n  File "/home/runner/DreamShare/.pythonlibs/lib/python3.11/site-packages/sqlalchemy/engine/base.py", line 1967, in _exec_single_context\n    self.dialect.do_execute(\n  File "/home/runner/DreamShare/.pythonlibs/lib/python3.11/site-packages/sqlalchemy/engine/default.py", line 941, in do_execute\n    cursor.execute(statement, parameters)\npsycopg2.errors.DuplicateTable: relation "user" already exists\n\n\nThe above exception was the direct cause of the following exception:\n\nTraceback (most recent call last):\n  File "/home/runner/DreamShare/app.py", line 78, in create_app\n    db.create_all()\n  File "/home/runner/DreamShare/.pythonlibs/lib/python3.11/site-packages/flask_sqlalchemy/extension.py", line 900, in create_all\n    self._call_for_binds(bind_key, "create_all")\n  File "/home/runner/DreamShare/.pythonlibs/lib/python3.11/site-packages/flask_sqlalchemy/extension.py", line 881, in _call_for_binds\n    getattr(metadata, op_name)(bind=engine)\n  File "/home/runner/DreamShare/.pythonlibs/lib/python3.11/site-packages/sqlalchemy/sql/schema.py", line 5868, in create_all\n    bind._run_ddl_visitor(\n  File "/home/runner/DreamShare/.pythonlibs/lib/python3.11/site-packages/sqlalchemy/engine/base.py", line 3253, in _run_ddl_visitor\n    conn._run_ddl_visitor(visitorcallable, element, **kwargs)\n  File "/home/runner/DreamShare/.pythonlibs/lib/python3.11/site-packages/sqlalchemy/engine/base.py", line 2459, in _run_ddl_visitor\n    visitorcallable(self.dialect, self, **kwargs).traverse_single(element)\n  File "/home/runner/DreamShare/.pythonlibs/lib/python3.11/site-packages/sqlalchemy/sql/visitors.py", line 664, in traverse_single\n    return meth(obj, **kw)\n           ^^^^^^^^^^^^^^^\n  File "/home/runner/DreamShare/.pythonlibs/lib/python3.11/site-packages/sqlalchemy/sql/ddl.py", line 918, in visit_metadata\n    self.traverse_single(\n  File "/home/runner/DreamShare/.pythonlibs/lib/python3.11/site-packages/sqlalchemy/sql/visitors.py", line 664, in traverse_single\n    return meth(obj, **kw)\n           ^^^^^^^^^^^^^^^\n  File "/home/runner/DreamShare/.pythonlibs/lib/python3.11/site-packages/sqlalchemy/sql/ddl.py", line 956, in visit_table\n    )._invoke_with(self.connection)\n      ^^^^^^^^^^^^^^^^^^^^^^^^^^^^^\n  File "/home/runner/DreamShare/.pythonlibs/lib/python3.11/site-packages/sqlalchemy/sql/ddl.py", line 314, in _invoke_with\n    return bind.execute(self)\n           ^^^^^^^^^^^^^^^^^^\n  File "/home/runner/DreamShare/.pythonlibs/lib/python3.11/site-packages/sqlalchemy/engine/base.py", line 1418, in execute\n    return meth(\n           ^^^^^\n  File "/home/runner/DreamShare/.pythonlibs/lib/python3.11/site-packages/sqlalchemy/sql/ddl.py", line 180, in _execute_on_connection\n    return connection._execute_ddl(\n           ^^^^^^^^^^^^^^^^^^^^^^^^\n  File "/home/runner/DreamShare/.pythonlibs/lib/python3.11/site-packages/sqlalchemy/engine/base.py", line 1529, in _execute_ddl\n    ret = self._execute_context(\n          ^^^^^^^^^^^^^^^^^^^^^^\n  File "/home/runner/DreamShare/.pythonlibs/lib/python3.11/site-packages/sqlalchemy/engine/base.py", line 1846, in _execute_context\n    return self._exec_single_context(\n           ^^^^^^^^^^^^^^^^^^^^^^^^^^\n  File "/home/runner/DreamShare/.pythonlibs/lib/python3.11/site-packages/sqlalchemy/engine/base.py", line 1986, in _exec_single_context\n    self._handle_dbapi_exception(\n  File "/home/runner/DreamShare/.pythonlibs/lib/python3.11/site-packages/sqlalchemy/engine/base.py", line 2355, in _handle_dbapi_exception\n    raise sqlalchemy_exception.with_traceback(exc_info[2]) from e\n  File "/home/runner/DreamShare/.pythonlibs/lib/python3.11/site-packages/sqlalchemy/engine/base.py", line 1967, in _exec_single_context\n    self.dialect.do_execute(\n  File "/home/runner/DreamShare/.pythonlibs/lib/python3.11/site-packages/sqlalchemy/engine/default.py", line 941, in do_execute\n    cursor.execute(statement, parameters)\nsqlalchemy.exc.ProgrammingError: (psycopg2.errors.DuplicateTable) relation "user" already exists\n\n[SQL: \nCREATE TABLE "user" (\n\tid SERIAL NOT NULL, \n\tusername VARCHAR(64) NOT NULL, \n\temail VARCHAR(120) NOT NULL, \n\tpassword_hash VARCHAR(256), \n\tsubscription_type VARCHAR(20), \n\tsubscription_end_date TIMESTAMP WITHOUT TIME ZONE, \n\tmonthly_ai_analysis_count INTEGER, \n\tlast_analysis_reset TIMESTAMP WITHOUT TIME ZONE, \n\tPRIMARY KEY (id), \n\tUNIQUE (username), \n\tUNIQUE (email)\n)\n\n]\n(Background on this error at: https://sqlalche.me/e/20/f405)\n', 'context': {}}

2024-11-13 17:46:06,552 - None - None - None None
Level: ERROR
Module: logging_config
Message: Application Error: {'timestamp': '2024-11-13T17:46:06.550861', 'error_type': 'ProgrammingError', 'error_message': '(psycopg2.errors.DuplicateTable) relation "user" already exists\n\n[SQL: \nCREATE TABLE "user" (\n\tid SERIAL NOT NULL, \n\tusername VARCHAR(64) NOT NULL, \n\temail VARCHAR(120) NOT NULL, \n\tpassword_hash VARCHAR(256), \n\tsubscription_type VARCHAR(20), \n\tsubscription_end_date TIMESTAMP WITHOUT TIME ZONE, \n\tmonthly_ai_analysis_count INTEGER, \n\tlast_analysis_reset TIMESTAMP WITHOUT TIME ZONE, \n\tPRIMARY KEY (id), \n\tUNIQUE (username), \n\tUNIQUE (email)\n)\n\n]\n(Background on this error at: https://sqlalche.me/e/20/f405)', 'traceback': 'Traceback (most recent call last):\n  File "/home/runner/DreamShare/.pythonlibs/lib/python3.11/site-packages/sqlalchemy/engine/base.py", line 1967, in _exec_single_context\n    self.dialect.do_execute(\n  File "/home/runner/DreamShare/.pythonlibs/lib/python3.11/site-packages/sqlalchemy/engine/default.py", line 941, in do_execute\n    cursor.execute(statement, parameters)\npsycopg2.errors.DuplicateTable: relation "user" already exists\n\n\nThe above exception was the direct cause of the following exception:\n\nTraceback (most recent call last):\n  File "/home/runner/DreamShare/app.py", line 78, in create_app\n    db.create_all()\n  File "/home/runner/DreamShare/.pythonlibs/lib/python3.11/site-packages/flask_sqlalchemy/extension.py", line 900, in create_all\n    self._call_for_binds(bind_key, "create_all")\n  File "/home/runner/DreamShare/.pythonlibs/lib/python3.11/site-packages/flask_sqlalchemy/extension.py", line 881, in _call_for_binds\n    getattr(metadata, op_name)(bind=engine)\n  File "/home/runner/DreamShare/.pythonlibs/lib/python3.11/site-packages/sqlalchemy/sql/schema.py", line 5868, in create_all\n    bind._run_ddl_visitor(\n  File "/home/runner/DreamShare/.pythonlibs/lib/python3.11/site-packages/sqlalchemy/engine/base.py", line 3253, in _run_ddl_visitor\n    conn._run_ddl_visitor(visitorcallable, element, **kwargs)\n  File "/home/runner/DreamShare/.pythonlibs/lib/python3.11/site-packages/sqlalchemy/engine/base.py", line 2459, in _run_ddl_visitor\n    visitorcallable(self.dialect, self, **kwargs).traverse_single(element)\n  File "/home/runner/DreamShare/.pythonlibs/lib/python3.11/site-packages/sqlalchemy/sql/visitors.py", line 664, in traverse_single\n    return meth(obj, **kw)\n           ^^^^^^^^^^^^^^^\n  File "/home/runner/DreamShare/.pythonlibs/lib/python3.11/site-packages/sqlalchemy/sql/ddl.py", line 918, in visit_metadata\n    self.traverse_single(\n  File "/home/runner/DreamShare/.pythonlibs/lib/python3.11/site-packages/sqlalchemy/sql/visitors.py", line 664, in traverse_single\n    return meth(obj, **kw)\n           ^^^^^^^^^^^^^^^\n  File "/home/runner/DreamShare/.pythonlibs/lib/python3.11/site-packages/sqlalchemy/sql/ddl.py", line 956, in visit_table\n    )._invoke_with(self.connection)\n      ^^^^^^^^^^^^^^^^^^^^^^^^^^^^^\n  File "/home/runner/DreamShare/.pythonlibs/lib/python3.11/site-packages/sqlalchemy/sql/ddl.py", line 314, in _invoke_with\n    return bind.execute(self)\n           ^^^^^^^^^^^^^^^^^^\n  File "/home/runner/DreamShare/.pythonlibs/lib/python3.11/site-packages/sqlalchemy/engine/base.py", line 1418, in execute\n    return meth(\n           ^^^^^\n  File "/home/runner/DreamShare/.pythonlibs/lib/python3.11/site-packages/sqlalchemy/sql/ddl.py", line 180, in _execute_on_connection\n    return connection._execute_ddl(\n           ^^^^^^^^^^^^^^^^^^^^^^^^\n  File "/home/runner/DreamShare/.pythonlibs/lib/python3.11/site-packages/sqlalchemy/engine/base.py", line 1529, in _execute_ddl\n    ret = self._execute_context(\n          ^^^^^^^^^^^^^^^^^^^^^^\n  File "/home/runner/DreamShare/.pythonlibs/lib/python3.11/site-packages/sqlalchemy/engine/base.py", line 1846, in _execute_context\n    return self._exec_single_context(\n           ^^^^^^^^^^^^^^^^^^^^^^^^^^\n  File "/home/runner/DreamShare/.pythonlibs/lib/python3.11/site-packages/sqlalchemy/engine/base.py", line 1986, in _exec_single_context\n    self._handle_dbapi_exception(\n  File "/home/runner/DreamShare/.pythonlibs/lib/python3.11/site-packages/sqlalchemy/engine/base.py", line 2355, in _handle_dbapi_exception\n    raise sqlalchemy_exception.with_traceback(exc_info[2]) from e\n  File "/home/runner/DreamShare/.pythonlibs/lib/python3.11/site-packages/sqlalchemy/engine/base.py", line 1967, in _exec_single_context\n    self.dialect.do_execute(\n  File "/home/runner/DreamShare/.pythonlibs/lib/python3.11/site-packages/sqlalchemy/engine/default.py", line 941, in do_execute\n    cursor.execute(statement, parameters)\nsqlalchemy.exc.ProgrammingError: (psycopg2.errors.DuplicateTable) relation "user" already exists\n\n[SQL: \nCREATE TABLE "user" (\n\tid SERIAL NOT NULL, \n\tusername VARCHAR(64) NOT NULL, \n\temail VARCHAR(120) NOT NULL, \n\tpassword_hash VARCHAR(256), \n\tsubscription_type VARCHAR(20), \n\tsubscription_end_date TIMESTAMP WITHOUT TIME ZONE, \n\tmonthly_ai_analysis_count INTEGER, \n\tlast_analysis_reset TIMESTAMP WITHOUT TIME ZONE, \n\tPRIMARY KEY (id), \n\tUNIQUE (username), \n\tUNIQUE (email)\n)\n\n]\n(Background on this error at: https://sqlalche.me/e/20/f405)\n', 'context': {}}

2024-11-13 17:46:06,552 - None - None - None None
Level: ERROR
Module: logging_config
Message: Application Error: {'timestamp': '2024-11-13T17:46:06.550861', 'error_type': 'ProgrammingError', 'error_message': '(psycopg2.errors.DuplicateTable) relation "user" already exists\n\n[SQL: \nCREATE TABLE "user" (\n\tid SERIAL NOT NULL, \n\tusername VARCHAR(64) NOT NULL, \n\temail VARCHAR(120) NOT NULL, \n\tpassword_hash VARCHAR(256), \n\tsubscription_type VARCHAR(20), \n\tsubscription_end_date TIMESTAMP WITHOUT TIME ZONE, \n\tmonthly_ai_analysis_count INTEGER, \n\tlast_analysis_reset TIMESTAMP WITHOUT TIME ZONE, \n\tPRIMARY KEY (id), \n\tUNIQUE (username), \n\tUNIQUE (email)\n)\n\n]\n(Background on this error at: https://sqlalche.me/e/20/f405)', 'traceback': 'Traceback (most recent call last):\n  File "/home/runner/DreamShare/.pythonlibs/lib/python3.11/site-packages/sqlalchemy/engine/base.py", line 1967, in _exec_single_context\n    self.dialect.do_execute(\n  File "/home/runner/DreamShare/.pythonlibs/lib/python3.11/site-packages/sqlalchemy/engine/default.py", line 941, in do_execute\n    cursor.execute(statement, parameters)\npsycopg2.errors.DuplicateTable: relation "user" already exists\n\n\nThe above exception was the direct cause of the following exception:\n\nTraceback (most recent call last):\n  File "/home/runner/DreamShare/app.py", line 78, in create_app\n    db.create_all()\n  File "/home/runner/DreamShare/.pythonlibs/lib/python3.11/site-packages/flask_sqlalchemy/extension.py", line 900, in create_all\n    self._call_for_binds(bind_key, "create_all")\n  File "/home/runner/DreamShare/.pythonlibs/lib/python3.11/site-packages/flask_sqlalchemy/extension.py", line 881, in _call_for_binds\n    getattr(metadata, op_name)(bind=engine)\n  File "/home/runner/DreamShare/.pythonlibs/lib/python3.11/site-packages/sqlalchemy/sql/schema.py", line 5868, in create_all\n    bind._run_ddl_visitor(\n  File "/home/runner/DreamShare/.pythonlibs/lib/python3.11/site-packages/sqlalchemy/engine/base.py", line 3253, in _run_ddl_visitor\n    conn._run_ddl_visitor(visitorcallable, element, **kwargs)\n  File "/home/runner/DreamShare/.pythonlibs/lib/python3.11/site-packages/sqlalchemy/engine/base.py", line 2459, in _run_ddl_visitor\n    visitorcallable(self.dialect, self, **kwargs).traverse_single(element)\n  File "/home/runner/DreamShare/.pythonlibs/lib/python3.11/site-packages/sqlalchemy/sql/visitors.py", line 664, in traverse_single\n    return meth(obj, **kw)\n           ^^^^^^^^^^^^^^^\n  File "/home/runner/DreamShare/.pythonlibs/lib/python3.11/site-packages/sqlalchemy/sql/ddl.py", line 918, in visit_metadata\n    self.traverse_single(\n  File "/home/runner/DreamShare/.pythonlibs/lib/python3.11/site-packages/sqlalchemy/sql/visitors.py", line 664, in traverse_single\n    return meth(obj, **kw)\n           ^^^^^^^^^^^^^^^\n  File "/home/runner/DreamShare/.pythonlibs/lib/python3.11/site-packages/sqlalchemy/sql/ddl.py", line 956, in visit_table\n    )._invoke_with(self.connection)\n      ^^^^^^^^^^^^^^^^^^^^^^^^^^^^^\n  File "/home/runner/DreamShare/.pythonlibs/lib/python3.11/site-packages/sqlalchemy/sql/ddl.py", line 314, in _invoke_with\n    return bind.execute(self)\n           ^^^^^^^^^^^^^^^^^^\n  File "/home/runner/DreamShare/.pythonlibs/lib/python3.11/site-packages/sqlalchemy/engine/base.py", line 1418, in execute\n    return meth(\n           ^^^^^\n  File "/home/runner/DreamShare/.pythonlibs/lib/python3.11/site-packages/sqlalchemy/sql/ddl.py", line 180, in _execute_on_connection\n    return connection._execute_ddl(\n           ^^^^^^^^^^^^^^^^^^^^^^^^\n  File "/home/runner/DreamShare/.pythonlibs/lib/python3.11/site-packages/sqlalchemy/engine/base.py", line 1529, in _execute_ddl\n    ret = self._execute_context(\n          ^^^^^^^^^^^^^^^^^^^^^^\n  File "/home/runner/DreamShare/.pythonlibs/lib/python3.11/site-packages/sqlalchemy/engine/base.py", line 1846, in _execute_context\n    return self._exec_single_context(\n           ^^^^^^^^^^^^^^^^^^^^^^^^^^\n  File "/home/runner/DreamShare/.pythonlibs/lib/python3.11/site-packages/sqlalchemy/engine/base.py", line 1986, in _exec_single_context\n    self._handle_dbapi_exception(\n  File "/home/runner/DreamShare/.pythonlibs/lib/python3.11/site-packages/sqlalchemy/engine/base.py", line 2355, in _handle_dbapi_exception\n    raise sqlalchemy_exception.with_traceback(exc_info[2]) from e\n  File "/home/runner/DreamShare/.pythonlibs/lib/python3.11/site-packages/sqlalchemy/engine/base.py", line 1967, in _exec_single_context\n    self.dialect.do_execute(\n  File "/home/runner/DreamShare/.pythonlibs/lib/python3.11/site-packages/sqlalchemy/engine/default.py", line 941, in do_execute\n    cursor.execute(statement, parameters)\nsqlalchemy.exc.ProgrammingError: (psycopg2.errors.DuplicateTable) relation "user" already exists\n\n[SQL: \nCREATE TABLE "user" (\n\tid SERIAL NOT NULL, \n\tusername VARCHAR(64) NOT NULL, \n\temail VARCHAR(120) NOT NULL, \n\tpassword_hash VARCHAR(256), \n\tsubscription_type VARCHAR(20), \n\tsubscription_end_date TIMESTAMP WITHOUT TIME ZONE, \n\tmonthly_ai_analysis_count INTEGER, \n\tlast_analysis_reset TIMESTAMP WITHOUT TIME ZONE, \n\tPRIMARY KEY (id), \n\tUNIQUE (username), \n\tUNIQUE (email)\n)\n\n]\n(Background on this error at: https://sqlalche.me/e/20/f405)\n', 'context': {}}

2024-11-13 17:46:07,980 - None - None - None None
Level: ERROR
Module: logging_config
Message: Application Error: {'timestamp': '2024-11-13T17:46:07.978831', 'error_type': 'IntegrityError', 'error_message': '(psycopg2.errors.UniqueViolation) duplicate key value violates unique constraint "pg_class_relname_nsp_index"\nDETAIL:  Key (relname, relnamespace)=(user_id_seq, 360560) already exists.\n\n[SQL: \nCREATE TABLE "user" (\n\tid SERIAL NOT NULL, \n\tusername VARCHAR(64) NOT NULL, \n\temail VARCHAR(120) NOT NULL, \n\tpassword_hash VARCHAR(256), \n\tsubscription_type VARCHAR(20), \n\tsubscription_end_date TIMESTAMP WITHOUT TIME ZONE, \n\tmonthly_ai_analysis_count INTEGER, \n\tlast_analysis_reset TIMESTAMP WITHOUT TIME ZONE, \n\tPRIMARY KEY (id), \n\tUNIQUE (username), \n\tUNIQUE (email)\n)\n\n]\n(Background on this error at: https://sqlalche.me/e/20/gkpj)', 'traceback': 'Traceback (most recent call last):\n  File "/home/runner/DreamShare/.pythonlibs/lib/python3.11/site-packages/sqlalchemy/engine/base.py", line 1967, in _exec_single_context\n    self.dialect.do_execute(\n  File "/home/runner/DreamShare/.pythonlibs/lib/python3.11/site-packages/sqlalchemy/engine/default.py", line 941, in do_execute\n    cursor.execute(statement, parameters)\npsycopg2.errors.UniqueViolation: duplicate key value violates unique constraint "pg_class_relname_nsp_index"\nDETAIL:  Key (relname, relnamespace)=(user_id_seq, 360560) already exists.\n\n\nThe above exception was the direct cause of the following exception:\n\nTraceback (most recent call last):\n  File "/home/runner/DreamShare/app.py", line 78, in create_app\n    db.create_all()\n  File "/home/runner/DreamShare/.pythonlibs/lib/python3.11/site-packages/flask_sqlalchemy/extension.py", line 900, in create_all\n    self._call_for_binds(bind_key, "create_all")\n  File "/home/runner/DreamShare/.pythonlibs/lib/python3.11/site-packages/flask_sqlalchemy/extension.py", line 881, in _call_for_binds\n    getattr(metadata, op_name)(bind=engine)\n  File "/home/runner/DreamShare/.pythonlibs/lib/python3.11/site-packages/sqlalchemy/sql/schema.py", line 5868, in create_all\n    bind._run_ddl_visitor(\n  File "/home/runner/DreamShare/.pythonlibs/lib/python3.11/site-packages/sqlalchemy/engine/base.py", line 3253, in _run_ddl_visitor\n    conn._run_ddl_visitor(visitorcallable, element, **kwargs)\n  File "/home/runner/DreamShare/.pythonlibs/lib/python3.11/site-packages/sqlalchemy/engine/base.py", line 2459, in _run_ddl_visitor\n    visitorcallable(self.dialect, self, **kwargs).traverse_single(element)\n  File "/home/runner/DreamShare/.pythonlibs/lib/python3.11/site-packages/sqlalchemy/sql/visitors.py", line 664, in traverse_single\n    return meth(obj, **kw)\n           ^^^^^^^^^^^^^^^\n  File "/home/runner/DreamShare/.pythonlibs/lib/python3.11/site-packages/sqlalchemy/sql/ddl.py", line 918, in visit_metadata\n    self.traverse_single(\n  File "/home/runner/DreamShare/.pythonlibs/lib/python3.11/site-packages/sqlalchemy/sql/visitors.py", line 664, in traverse_single\n    return meth(obj, **kw)\n           ^^^^^^^^^^^^^^^\n  File "/home/runner/DreamShare/.pythonlibs/lib/python3.11/site-packages/sqlalchemy/sql/ddl.py", line 956, in visit_table\n    )._invoke_with(self.connection)\n      ^^^^^^^^^^^^^^^^^^^^^^^^^^^^^\n  File "/home/runner/DreamShare/.pythonlibs/lib/python3.11/site-packages/sqlalchemy/sql/ddl.py", line 314, in _invoke_with\n    return bind.execute(self)\n           ^^^^^^^^^^^^^^^^^^\n  File "/home/runner/DreamShare/.pythonlibs/lib/python3.11/site-packages/sqlalchemy/engine/base.py", line 1418, in execute\n    return meth(\n           ^^^^^\n  File "/home/runner/DreamShare/.pythonlibs/lib/python3.11/site-packages/sqlalchemy/sql/ddl.py", line 180, in _execute_on_connection\n    return connection._execute_ddl(\n           ^^^^^^^^^^^^^^^^^^^^^^^^\n  File "/home/runner/DreamShare/.pythonlibs/lib/python3.11/site-packages/sqlalchemy/engine/base.py", line 1529, in _execute_ddl\n    ret = self._execute_context(\n          ^^^^^^^^^^^^^^^^^^^^^^\n  File "/home/runner/DreamShare/.pythonlibs/lib/python3.11/site-packages/sqlalchemy/engine/base.py", line 1846, in _execute_context\n    return self._exec_single_context(\n           ^^^^^^^^^^^^^^^^^^^^^^^^^^\n  File "/home/runner/DreamShare/.pythonlibs/lib/python3.11/site-packages/sqlalchemy/engine/base.py", line 1986, in _exec_single_context\n    self._handle_dbapi_exception(\n  File "/home/runner/DreamShare/.pythonlibs/lib/python3.11/site-packages/sqlalchemy/engine/base.py", line 2355, in _handle_dbapi_exception\n    raise sqlalchemy_exception.with_traceback(exc_info[2]) from e\n  File "/home/runner/DreamShare/.pythonlibs/lib/python3.11/site-packages/sqlalchemy/engine/base.py", line 1967, in _exec_single_context\n    self.dialect.do_execute(\n  File "/home/runner/DreamShare/.pythonlibs/lib/python3.11/site-packages/sqlalchemy/engine/default.py", line 941, in do_execute\n    cursor.execute(statement, parameters)\nsqlalchemy.exc.IntegrityError: (psycopg2.errors.UniqueViolation) duplicate key value violates unique constraint "pg_class_relname_nsp_index"\nDETAIL:  Key (relname, relnamespace)=(user_id_seq, 360560) already exists.\n\n[SQL: \nCREATE TABLE "user" (\n\tid SERIAL NOT NULL, \n\tusername VARCHAR(64) NOT NULL, \n\temail VARCHAR(120) NOT NULL, \n\tpassword_hash VARCHAR(256), \n\tsubscription_type VARCHAR(20), \n\tsubscription_end_date TIMESTAMP WITHOUT TIME ZONE, \n\tmonthly_ai_analysis_count INTEGER, \n\tlast_analysis_reset TIMESTAMP WITHOUT TIME ZONE, \n\tPRIMARY KEY (id), \n\tUNIQUE (username), \n\tUNIQUE (email)\n)\n\n]\n(Background on this error at: https://sqlalche.me/e/20/gkpj)\n', 'context': {}}

2024-11-13 17:46:07,980 - None - None - None None
Level: ERROR
Module: logging_config
Message: Application Error: {'timestamp': '2024-11-13T17:46:07.978831', 'error_type': 'IntegrityError', 'error_message': '(psycopg2.errors.UniqueViolation) duplicate key value violates unique constraint "pg_class_relname_nsp_index"\nDETAIL:  Key (relname, relnamespace)=(user_id_seq, 360560) already exists.\n\n[SQL: \nCREATE TABLE "user" (\n\tid SERIAL NOT NULL, \n\tusername VARCHAR(64) NOT NULL, \n\temail VARCHAR(120) NOT NULL, \n\tpassword_hash VARCHAR(256), \n\tsubscription_type VARCHAR(20), \n\tsubscription_end_date TIMESTAMP WITHOUT TIME ZONE, \n\tmonthly_ai_analysis_count INTEGER, \n\tlast_analysis_reset TIMESTAMP WITHOUT TIME ZONE, \n\tPRIMARY KEY (id), \n\tUNIQUE (username), \n\tUNIQUE (email)\n)\n\n]\n(Background on this error at: https://sqlalche.me/e/20/gkpj)', 'traceback': 'Traceback (most recent call last):\n  File "/home/runner/DreamShare/.pythonlibs/lib/python3.11/site-packages/sqlalchemy/engine/base.py", line 1967, in _exec_single_context\n    self.dialect.do_execute(\n  File "/home/runner/DreamShare/.pythonlibs/lib/python3.11/site-packages/sqlalchemy/engine/default.py", line 941, in do_execute\n    cursor.execute(statement, parameters)\npsycopg2.errors.UniqueViolation: duplicate key value violates unique constraint "pg_class_relname_nsp_index"\nDETAIL:  Key (relname, relnamespace)=(user_id_seq, 360560) already exists.\n\n\nThe above exception was the direct cause of the following exception:\n\nTraceback (most recent call last):\n  File "/home/runner/DreamShare/app.py", line 78, in create_app\n    db.create_all()\n  File "/home/runner/DreamShare/.pythonlibs/lib/python3.11/site-packages/flask_sqlalchemy/extension.py", line 900, in create_all\n    self._call_for_binds(bind_key, "create_all")\n  File "/home/runner/DreamShare/.pythonlibs/lib/python3.11/site-packages/flask_sqlalchemy/extension.py", line 881, in _call_for_binds\n    getattr(metadata, op_name)(bind=engine)\n  File "/home/runner/DreamShare/.pythonlibs/lib/python3.11/site-packages/sqlalchemy/sql/schema.py", line 5868, in create_all\n    bind._run_ddl_visitor(\n  File "/home/runner/DreamShare/.pythonlibs/lib/python3.11/site-packages/sqlalchemy/engine/base.py", line 3253, in _run_ddl_visitor\n    conn._run_ddl_visitor(visitorcallable, element, **kwargs)\n  File "/home/runner/DreamShare/.pythonlibs/lib/python3.11/site-packages/sqlalchemy/engine/base.py", line 2459, in _run_ddl_visitor\n    visitorcallable(self.dialect, self, **kwargs).traverse_single(element)\n  File "/home/runner/DreamShare/.pythonlibs/lib/python3.11/site-packages/sqlalchemy/sql/visitors.py", line 664, in traverse_single\n    return meth(obj, **kw)\n           ^^^^^^^^^^^^^^^\n  File "/home/runner/DreamShare/.pythonlibs/lib/python3.11/site-packages/sqlalchemy/sql/ddl.py", line 918, in visit_metadata\n    self.traverse_single(\n  File "/home/runner/DreamShare/.pythonlibs/lib/python3.11/site-packages/sqlalchemy/sql/visitors.py", line 664, in traverse_single\n    return meth(obj, **kw)\n           ^^^^^^^^^^^^^^^\n  File "/home/runner/DreamShare/.pythonlibs/lib/python3.11/site-packages/sqlalchemy/sql/ddl.py", line 956, in visit_table\n    )._invoke_with(self.connection)\n      ^^^^^^^^^^^^^^^^^^^^^^^^^^^^^\n  File "/home/runner/DreamShare/.pythonlibs/lib/python3.11/site-packages/sqlalchemy/sql/ddl.py", line 314, in _invoke_with\n    return bind.execute(self)\n           ^^^^^^^^^^^^^^^^^^\n  File "/home/runner/DreamShare/.pythonlibs/lib/python3.11/site-packages/sqlalchemy/engine/base.py", line 1418, in execute\n    return meth(\n           ^^^^^\n  File "/home/runner/DreamShare/.pythonlibs/lib/python3.11/site-packages/sqlalchemy/sql/ddl.py", line 180, in _execute_on_connection\n    return connection._execute_ddl(\n           ^^^^^^^^^^^^^^^^^^^^^^^^\n  File "/home/runner/DreamShare/.pythonlibs/lib/python3.11/site-packages/sqlalchemy/engine/base.py", line 1529, in _execute_ddl\n    ret = self._execute_context(\n          ^^^^^^^^^^^^^^^^^^^^^^\n  File "/home/runner/DreamShare/.pythonlibs/lib/python3.11/site-packages/sqlalchemy/engine/base.py", line 1846, in _execute_context\n    return self._exec_single_context(\n           ^^^^^^^^^^^^^^^^^^^^^^^^^^\n  File "/home/runner/DreamShare/.pythonlibs/lib/python3.11/site-packages/sqlalchemy/engine/base.py", line 1986, in _exec_single_context\n    self._handle_dbapi_exception(\n  File "/home/runner/DreamShare/.pythonlibs/lib/python3.11/site-packages/sqlalchemy/engine/base.py", line 2355, in _handle_dbapi_exception\n    raise sqlalchemy_exception.with_traceback(exc_info[2]) from e\n  File "/home/runner/DreamShare/.pythonlibs/lib/python3.11/site-packages/sqlalchemy/engine/base.py", line 1967, in _exec_single_context\n    self.dialect.do_execute(\n  File "/home/runner/DreamShare/.pythonlibs/lib/python3.11/site-packages/sqlalchemy/engine/default.py", line 941, in do_execute\n    cursor.execute(statement, parameters)\nsqlalchemy.exc.IntegrityError: (psycopg2.errors.UniqueViolation) duplicate key value violates unique constraint "pg_class_relname_nsp_index"\nDETAIL:  Key (relname, relnamespace)=(user_id_seq, 360560) already exists.\n\n[SQL: \nCREATE TABLE "user" (\n\tid SERIAL NOT NULL, \n\tusername VARCHAR(64) NOT NULL, \n\temail VARCHAR(120) NOT NULL, \n\tpassword_hash VARCHAR(256), \n\tsubscription_type VARCHAR(20), \n\tsubscription_end_date TIMESTAMP WITHOUT TIME ZONE, \n\tmonthly_ai_analysis_count INTEGER, \n\tlast_analysis_reset TIMESTAMP WITHOUT TIME ZONE, \n\tPRIMARY KEY (id), \n\tUNIQUE (username), \n\tUNIQUE (email)\n)\n\n]\n(Background on this error at: https://sqlalche.me/e/20/gkpj)\n', 'context': {}}

2024-11-13 17:46:07,980 - None - None - None None
Level: ERROR
Module: logging_config
Message: Application Error: {'timestamp': '2024-11-13T17:46:07.978831', 'error_type': 'IntegrityError', 'error_message': '(psycopg2.errors.UniqueViolation) duplicate key value violates unique constraint "pg_class_relname_nsp_index"\nDETAIL:  Key (relname, relnamespace)=(user_id_seq, 360560) already exists.\n\n[SQL: \nCREATE TABLE "user" (\n\tid SERIAL NOT NULL, \n\tusername VARCHAR(64) NOT NULL, \n\temail VARCHAR(120) NOT NULL, \n\tpassword_hash VARCHAR(256), \n\tsubscription_type VARCHAR(20), \n\tsubscription_end_date TIMESTAMP WITHOUT TIME ZONE, \n\tmonthly_ai_analysis_count INTEGER, \n\tlast_analysis_reset TIMESTAMP WITHOUT TIME ZONE, \n\tPRIMARY KEY (id), \n\tUNIQUE (username), \n\tUNIQUE (email)\n)\n\n]\n(Background on this error at: https://sqlalche.me/e/20/gkpj)', 'traceback': 'Traceback (most recent call last):\n  File "/home/runner/DreamShare/.pythonlibs/lib/python3.11/site-packages/sqlalchemy/engine/base.py", line 1967, in _exec_single_context\n    self.dialect.do_execute(\n  File "/home/runner/DreamShare/.pythonlibs/lib/python3.11/site-packages/sqlalchemy/engine/default.py", line 941, in do_execute\n    cursor.execute(statement, parameters)\npsycopg2.errors.UniqueViolation: duplicate key value violates unique constraint "pg_class_relname_nsp_index"\nDETAIL:  Key (relname, relnamespace)=(user_id_seq, 360560) already exists.\n\n\nThe above exception was the direct cause of the following exception:\n\nTraceback (most recent call last):\n  File "/home/runner/DreamShare/app.py", line 78, in create_app\n    db.create_all()\n  File "/home/runner/DreamShare/.pythonlibs/lib/python3.11/site-packages/flask_sqlalchemy/extension.py", line 900, in create_all\n    self._call_for_binds(bind_key, "create_all")\n  File "/home/runner/DreamShare/.pythonlibs/lib/python3.11/site-packages/flask_sqlalchemy/extension.py", line 881, in _call_for_binds\n    getattr(metadata, op_name)(bind=engine)\n  File "/home/runner/DreamShare/.pythonlibs/lib/python3.11/site-packages/sqlalchemy/sql/schema.py", line 5868, in create_all\n    bind._run_ddl_visitor(\n  File "/home/runner/DreamShare/.pythonlibs/lib/python3.11/site-packages/sqlalchemy/engine/base.py", line 3253, in _run_ddl_visitor\n    conn._run_ddl_visitor(visitorcallable, element, **kwargs)\n  File "/home/runner/DreamShare/.pythonlibs/lib/python3.11/site-packages/sqlalchemy/engine/base.py", line 2459, in _run_ddl_visitor\n    visitorcallable(self.dialect, self, **kwargs).traverse_single(element)\n  File "/home/runner/DreamShare/.pythonlibs/lib/python3.11/site-packages/sqlalchemy/sql/visitors.py", line 664, in traverse_single\n    return meth(obj, **kw)\n           ^^^^^^^^^^^^^^^\n  File "/home/runner/DreamShare/.pythonlibs/lib/python3.11/site-packages/sqlalchemy/sql/ddl.py", line 918, in visit_metadata\n    self.traverse_single(\n  File "/home/runner/DreamShare/.pythonlibs/lib/python3.11/site-packages/sqlalchemy/sql/visitors.py", line 664, in traverse_single\n    return meth(obj, **kw)\n           ^^^^^^^^^^^^^^^\n  File "/home/runner/DreamShare/.pythonlibs/lib/python3.11/site-packages/sqlalchemy/sql/ddl.py", line 956, in visit_table\n    )._invoke_with(self.connection)\n      ^^^^^^^^^^^^^^^^^^^^^^^^^^^^^\n  File "/home/runner/DreamShare/.pythonlibs/lib/python3.11/site-packages/sqlalchemy/sql/ddl.py", line 314, in _invoke_with\n    return bind.execute(self)\n           ^^^^^^^^^^^^^^^^^^\n  File "/home/runner/DreamShare/.pythonlibs/lib/python3.11/site-packages/sqlalchemy/engine/base.py", line 1418, in execute\n    return meth(\n           ^^^^^\n  File "/home/runner/DreamShare/.pythonlibs/lib/python3.11/site-packages/sqlalchemy/sql/ddl.py", line 180, in _execute_on_connection\n    return connection._execute_ddl(\n           ^^^^^^^^^^^^^^^^^^^^^^^^\n  File "/home/runner/DreamShare/.pythonlibs/lib/python3.11/site-packages/sqlalchemy/engine/base.py", line 1529, in _execute_ddl\n    ret = self._execute_context(\n          ^^^^^^^^^^^^^^^^^^^^^^\n  File "/home/runner/DreamShare/.pythonlibs/lib/python3.11/site-packages/sqlalchemy/engine/base.py", line 1846, in _execute_context\n    return self._exec_single_context(\n           ^^^^^^^^^^^^^^^^^^^^^^^^^^\n  File "/home/runner/DreamShare/.pythonlibs/lib/python3.11/site-packages/sqlalchemy/engine/base.py", line 1986, in _exec_single_context\n    self._handle_dbapi_exception(\n  File "/home/runner/DreamShare/.pythonlibs/lib/python3.11/site-packages/sqlalchemy/engine/base.py", line 2355, in _handle_dbapi_exception\n    raise sqlalchemy_exception.with_traceback(exc_info[2]) from e\n  File "/home/runner/DreamShare/.pythonlibs/lib/python3.11/site-packages/sqlalchemy/engine/base.py", line 1967, in _exec_single_context\n    self.dialect.do_execute(\n  File "/home/runner/DreamShare/.pythonlibs/lib/python3.11/site-packages/sqlalchemy/engine/default.py", line 941, in do_execute\n    cursor.execute(statement, parameters)\nsqlalchemy.exc.IntegrityError: (psycopg2.errors.UniqueViolation) duplicate key value violates unique constraint "pg_class_relname_nsp_index"\nDETAIL:  Key (relname, relnamespace)=(user_id_seq, 360560) already exists.\n\n[SQL: \nCREATE TABLE "user" (\n\tid SERIAL NOT NULL, \n\tusername VARCHAR(64) NOT NULL, \n\temail VARCHAR(120) NOT NULL, \n\tpassword_hash VARCHAR(256), \n\tsubscription_type VARCHAR(20), \n\tsubscription_end_date TIMESTAMP WITHOUT TIME ZONE, \n\tmonthly_ai_analysis_count INTEGER, \n\tlast_analysis_reset TIMESTAMP WITHOUT TIME ZONE, \n\tPRIMARY KEY (id), \n\tUNIQUE (username), \n\tUNIQUE (email)\n)\n\n]\n(Background on this error at: https://sqlalche.me/e/20/gkpj)\n', 'context': {}}

2024-11-13 17:46:07,980 - None - None - None None
Level: ERROR
Module: logging_config
Message: Application Error: {'timestamp': '2024-11-13T17:46:07.978831', 'error_type': 'IntegrityError', 'error_message': '(psycopg2.errors.UniqueViolation) duplicate key value violates unique constraint "pg_class_relname_nsp_index"\nDETAIL:  Key (relname, relnamespace)=(user_id_seq, 360560) already exists.\n\n[SQL: \nCREATE TABLE "user" (\n\tid SERIAL NOT NULL, \n\tusername VARCHAR(64) NOT NULL, \n\temail VARCHAR(120) NOT NULL, \n\tpassword_hash VARCHAR(256), \n\tsubscription_type VARCHAR(20), \n\tsubscription_end_date TIMESTAMP WITHOUT TIME ZONE, \n\tmonthly_ai_analysis_count INTEGER, \n\tlast_analysis_reset TIMESTAMP WITHOUT TIME ZONE, \n\tPRIMARY KEY (id), \n\tUNIQUE (username), \n\tUNIQUE (email)\n)\n\n]\n(Background on this error at: https://sqlalche.me/e/20/gkpj)', 'traceback': 'Traceback (most recent call last):\n  File "/home/runner/DreamShare/.pythonlibs/lib/python3.11/site-packages/sqlalchemy/engine/base.py", line 1967, in _exec_single_context\n    self.dialect.do_execute(\n  File "/home/runner/DreamShare/.pythonlibs/lib/python3.11/site-packages/sqlalchemy/engine/default.py", line 941, in do_execute\n    cursor.execute(statement, parameters)\npsycopg2.errors.UniqueViolation: duplicate key value violates unique constraint "pg_class_relname_nsp_index"\nDETAIL:  Key (relname, relnamespace)=(user_id_seq, 360560) already exists.\n\n\nThe above exception was the direct cause of the following exception:\n\nTraceback (most recent call last):\n  File "/home/runner/DreamShare/app.py", line 78, in create_app\n    db.create_all()\n  File "/home/runner/DreamShare/.pythonlibs/lib/python3.11/site-packages/flask_sqlalchemy/extension.py", line 900, in create_all\n    self._call_for_binds(bind_key, "create_all")\n  File "/home/runner/DreamShare/.pythonlibs/lib/python3.11/site-packages/flask_sqlalchemy/extension.py", line 881, in _call_for_binds\n    getattr(metadata, op_name)(bind=engine)\n  File "/home/runner/DreamShare/.pythonlibs/lib/python3.11/site-packages/sqlalchemy/sql/schema.py", line 5868, in create_all\n    bind._run_ddl_visitor(\n  File "/home/runner/DreamShare/.pythonlibs/lib/python3.11/site-packages/sqlalchemy/engine/base.py", line 3253, in _run_ddl_visitor\n    conn._run_ddl_visitor(visitorcallable, element, **kwargs)\n  File "/home/runner/DreamShare/.pythonlibs/lib/python3.11/site-packages/sqlalchemy/engine/base.py", line 2459, in _run_ddl_visitor\n    visitorcallable(self.dialect, self, **kwargs).traverse_single(element)\n  File "/home/runner/DreamShare/.pythonlibs/lib/python3.11/site-packages/sqlalchemy/sql/visitors.py", line 664, in traverse_single\n    return meth(obj, **kw)\n           ^^^^^^^^^^^^^^^\n  File "/home/runner/DreamShare/.pythonlibs/lib/python3.11/site-packages/sqlalchemy/sql/ddl.py", line 918, in visit_metadata\n    self.traverse_single(\n  File "/home/runner/DreamShare/.pythonlibs/lib/python3.11/site-packages/sqlalchemy/sql/visitors.py", line 664, in traverse_single\n    return meth(obj, **kw)\n           ^^^^^^^^^^^^^^^\n  File "/home/runner/DreamShare/.pythonlibs/lib/python3.11/site-packages/sqlalchemy/sql/ddl.py", line 956, in visit_table\n    )._invoke_with(self.connection)\n      ^^^^^^^^^^^^^^^^^^^^^^^^^^^^^\n  File "/home/runner/DreamShare/.pythonlibs/lib/python3.11/site-packages/sqlalchemy/sql/ddl.py", line 314, in _invoke_with\n    return bind.execute(self)\n           ^^^^^^^^^^^^^^^^^^\n  File "/home/runner/DreamShare/.pythonlibs/lib/python3.11/site-packages/sqlalchemy/engine/base.py", line 1418, in execute\n    return meth(\n           ^^^^^\n  File "/home/runner/DreamShare/.pythonlibs/lib/python3.11/site-packages/sqlalchemy/sql/ddl.py", line 180, in _execute_on_connection\n    return connection._execute_ddl(\n           ^^^^^^^^^^^^^^^^^^^^^^^^\n  File "/home/runner/DreamShare/.pythonlibs/lib/python3.11/site-packages/sqlalchemy/engine/base.py", line 1529, in _execute_ddl\n    ret = self._execute_context(\n          ^^^^^^^^^^^^^^^^^^^^^^\n  File "/home/runner/DreamShare/.pythonlibs/lib/python3.11/site-packages/sqlalchemy/engine/base.py", line 1846, in _execute_context\n    return self._exec_single_context(\n           ^^^^^^^^^^^^^^^^^^^^^^^^^^\n  File "/home/runner/DreamShare/.pythonlibs/lib/python3.11/site-packages/sqlalchemy/engine/base.py", line 1986, in _exec_single_context\n    self._handle_dbapi_exception(\n  File "/home/runner/DreamShare/.pythonlibs/lib/python3.11/site-packages/sqlalchemy/engine/base.py", line 2355, in _handle_dbapi_exception\n    raise sqlalchemy_exception.with_traceback(exc_info[2]) from e\n  File "/home/runner/DreamShare/.pythonlibs/lib/python3.11/site-packages/sqlalchemy/engine/base.py", line 1967, in _exec_single_context\n    self.dialect.do_execute(\n  File "/home/runner/DreamShare/.pythonlibs/lib/python3.11/site-packages/sqlalchemy/engine/default.py", line 941, in do_execute\n    cursor.execute(statement, parameters)\nsqlalchemy.exc.IntegrityError: (psycopg2.errors.UniqueViolation) duplicate key value violates unique constraint "pg_class_relname_nsp_index"\nDETAIL:  Key (relname, relnamespace)=(user_id_seq, 360560) already exists.\n\n[SQL: \nCREATE TABLE "user" (\n\tid SERIAL NOT NULL, \n\tusername VARCHAR(64) NOT NULL, \n\temail VARCHAR(120) NOT NULL, \n\tpassword_hash VARCHAR(256), \n\tsubscription_type VARCHAR(20), \n\tsubscription_end_date TIMESTAMP WITHOUT TIME ZONE, \n\tmonthly_ai_analysis_count INTEGER, \n\tlast_analysis_reset TIMESTAMP WITHOUT TIME ZONE, \n\tPRIMARY KEY (id), \n\tUNIQUE (username), \n\tUNIQUE (email)\n)\n\n]\n(Background on this error at: https://sqlalche.me/e/20/gkpj)\n', 'context': {}}

2024-11-13 17:46:07,980 - None - None - None None
Level: ERROR
Module: logging_config
Message: Application Error: {'timestamp': '2024-11-13T17:46:07.978831', 'error_type': 'IntegrityError', 'error_message': '(psycopg2.errors.UniqueViolation) duplicate key value violates unique constraint "pg_class_relname_nsp_index"\nDETAIL:  Key (relname, relnamespace)=(user_id_seq, 360560) already exists.\n\n[SQL: \nCREATE TABLE "user" (\n\tid SERIAL NOT NULL, \n\tusername VARCHAR(64) NOT NULL, \n\temail VARCHAR(120) NOT NULL, \n\tpassword_hash VARCHAR(256), \n\tsubscription_type VARCHAR(20), \n\tsubscription_end_date TIMESTAMP WITHOUT TIME ZONE, \n\tmonthly_ai_analysis_count INTEGER, \n\tlast_analysis_reset TIMESTAMP WITHOUT TIME ZONE, \n\tPRIMARY KEY (id), \n\tUNIQUE (username), \n\tUNIQUE (email)\n)\n\n]\n(Background on this error at: https://sqlalche.me/e/20/gkpj)', 'traceback': 'Traceback (most recent call last):\n  File "/home/runner/DreamShare/.pythonlibs/lib/python3.11/site-packages/sqlalchemy/engine/base.py", line 1967, in _exec_single_context\n    self.dialect.do_execute(\n  File "/home/runner/DreamShare/.pythonlibs/lib/python3.11/site-packages/sqlalchemy/engine/default.py", line 941, in do_execute\n    cursor.execute(statement, parameters)\npsycopg2.errors.UniqueViolation: duplicate key value violates unique constraint "pg_class_relname_nsp_index"\nDETAIL:  Key (relname, relnamespace)=(user_id_seq, 360560) already exists.\n\n\nThe above exception was the direct cause of the following exception:\n\nTraceback (most recent call last):\n  File "/home/runner/DreamShare/app.py", line 78, in create_app\n    db.create_all()\n  File "/home/runner/DreamShare/.pythonlibs/lib/python3.11/site-packages/flask_sqlalchemy/extension.py", line 900, in create_all\n    self._call_for_binds(bind_key, "create_all")\n  File "/home/runner/DreamShare/.pythonlibs/lib/python3.11/site-packages/flask_sqlalchemy/extension.py", line 881, in _call_for_binds\n    getattr(metadata, op_name)(bind=engine)\n  File "/home/runner/DreamShare/.pythonlibs/lib/python3.11/site-packages/sqlalchemy/sql/schema.py", line 5868, in create_all\n    bind._run_ddl_visitor(\n  File "/home/runner/DreamShare/.pythonlibs/lib/python3.11/site-packages/sqlalchemy/engine/base.py", line 3253, in _run_ddl_visitor\n    conn._run_ddl_visitor(visitorcallable, element, **kwargs)\n  File "/home/runner/DreamShare/.pythonlibs/lib/python3.11/site-packages/sqlalchemy/engine/base.py", line 2459, in _run_ddl_visitor\n    visitorcallable(self.dialect, self, **kwargs).traverse_single(element)\n  File "/home/runner/DreamShare/.pythonlibs/lib/python3.11/site-packages/sqlalchemy/sql/visitors.py", line 664, in traverse_single\n    return meth(obj, **kw)\n           ^^^^^^^^^^^^^^^\n  File "/home/runner/DreamShare/.pythonlibs/lib/python3.11/site-packages/sqlalchemy/sql/ddl.py", line 918, in visit_metadata\n    self.traverse_single(\n  File "/home/runner/DreamShare/.pythonlibs/lib/python3.11/site-packages/sqlalchemy/sql/visitors.py", line 664, in traverse_single\n    return meth(obj, **kw)\n           ^^^^^^^^^^^^^^^\n  File "/home/runner/DreamShare/.pythonlibs/lib/python3.11/site-packages/sqlalchemy/sql/ddl.py", line 956, in visit_table\n    )._invoke_with(self.connection)\n      ^^^^^^^^^^^^^^^^^^^^^^^^^^^^^\n  File "/home/runner/DreamShare/.pythonlibs/lib/python3.11/site-packages/sqlalchemy/sql/ddl.py", line 314, in _invoke_with\n    return bind.execute(self)\n           ^^^^^^^^^^^^^^^^^^\n  File "/home/runner/DreamShare/.pythonlibs/lib/python3.11/site-packages/sqlalchemy/engine/base.py", line 1418, in execute\n    return meth(\n           ^^^^^\n  File "/home/runner/DreamShare/.pythonlibs/lib/python3.11/site-packages/sqlalchemy/sql/ddl.py", line 180, in _execute_on_connection\n    return connection._execute_ddl(\n           ^^^^^^^^^^^^^^^^^^^^^^^^\n  File "/home/runner/DreamShare/.pythonlibs/lib/python3.11/site-packages/sqlalchemy/engine/base.py", line 1529, in _execute_ddl\n    ret = self._execute_context(\n          ^^^^^^^^^^^^^^^^^^^^^^\n  File "/home/runner/DreamShare/.pythonlibs/lib/python3.11/site-packages/sqlalchemy/engine/base.py", line 1846, in _execute_context\n    return self._exec_single_context(\n           ^^^^^^^^^^^^^^^^^^^^^^^^^^\n  File "/home/runner/DreamShare/.pythonlibs/lib/python3.11/site-packages/sqlalchemy/engine/base.py", line 1986, in _exec_single_context\n    self._handle_dbapi_exception(\n  File "/home/runner/DreamShare/.pythonlibs/lib/python3.11/site-packages/sqlalchemy/engine/base.py", line 2355, in _handle_dbapi_exception\n    raise sqlalchemy_exception.with_traceback(exc_info[2]) from e\n  File "/home/runner/DreamShare/.pythonlibs/lib/python3.11/site-packages/sqlalchemy/engine/base.py", line 1967, in _exec_single_context\n    self.dialect.do_execute(\n  File "/home/runner/DreamShare/.pythonlibs/lib/python3.11/site-packages/sqlalchemy/engine/default.py", line 941, in do_execute\n    cursor.execute(statement, parameters)\nsqlalchemy.exc.IntegrityError: (psycopg2.errors.UniqueViolation) duplicate key value violates unique constraint "pg_class_relname_nsp_index"\nDETAIL:  Key (relname, relnamespace)=(user_id_seq, 360560) already exists.\n\n[SQL: \nCREATE TABLE "user" (\n\tid SERIAL NOT NULL, \n\tusername VARCHAR(64) NOT NULL, \n\temail VARCHAR(120) NOT NULL, \n\tpassword_hash VARCHAR(256), \n\tsubscription_type VARCHAR(20), \n\tsubscription_end_date TIMESTAMP WITHOUT TIME ZONE, \n\tmonthly_ai_analysis_count INTEGER, \n\tlast_analysis_reset TIMESTAMP WITHOUT TIME ZONE, \n\tPRIMARY KEY (id), \n\tUNIQUE (username), \n\tUNIQUE (email)\n)\n\n]\n(Background on this error at: https://sqlalche.me/e/20/gkpj)\n', 'context': {}}

2024-11-13 17:46:07,980 - None - None - None None
Level: ERROR
Module: logging_config
Message: Application Error: {'timestamp': '2024-11-13T17:46:07.978831', 'error_type': 'IntegrityError', 'error_message': '(psycopg2.errors.UniqueViolation) duplicate key value violates unique constraint "pg_class_relname_nsp_index"\nDETAIL:  Key (relname, relnamespace)=(user_id_seq, 360560) already exists.\n\n[SQL: \nCREATE TABLE "user" (\n\tid SERIAL NOT NULL, \n\tusername VARCHAR(64) NOT NULL, \n\temail VARCHAR(120) NOT NULL, \n\tpassword_hash VARCHAR(256), \n\tsubscription_type VARCHAR(20), \n\tsubscription_end_date TIMESTAMP WITHOUT TIME ZONE, \n\tmonthly_ai_analysis_count INTEGER, \n\tlast_analysis_reset TIMESTAMP WITHOUT TIME ZONE, \n\tPRIMARY KEY (id), \n\tUNIQUE (username), \n\tUNIQUE (email)\n)\n\n]\n(Background on this error at: https://sqlalche.me/e/20/gkpj)', 'traceback': 'Traceback (most recent call last):\n  File "/home/runner/DreamShare/.pythonlibs/lib/python3.11/site-packages/sqlalchemy/engine/base.py", line 1967, in _exec_single_context\n    self.dialect.do_execute(\n  File "/home/runner/DreamShare/.pythonlibs/lib/python3.11/site-packages/sqlalchemy/engine/default.py", line 941, in do_execute\n    cursor.execute(statement, parameters)\npsycopg2.errors.UniqueViolation: duplicate key value violates unique constraint "pg_class_relname_nsp_index"\nDETAIL:  Key (relname, relnamespace)=(user_id_seq, 360560) already exists.\n\n\nThe above exception was the direct cause of the following exception:\n\nTraceback (most recent call last):\n  File "/home/runner/DreamShare/app.py", line 78, in create_app\n    db.create_all()\n  File "/home/runner/DreamShare/.pythonlibs/lib/python3.11/site-packages/flask_sqlalchemy/extension.py", line 900, in create_all\n    self._call_for_binds(bind_key, "create_all")\n  File "/home/runner/DreamShare/.pythonlibs/lib/python3.11/site-packages/flask_sqlalchemy/extension.py", line 881, in _call_for_binds\n    getattr(metadata, op_name)(bind=engine)\n  File "/home/runner/DreamShare/.pythonlibs/lib/python3.11/site-packages/sqlalchemy/sql/schema.py", line 5868, in create_all\n    bind._run_ddl_visitor(\n  File "/home/runner/DreamShare/.pythonlibs/lib/python3.11/site-packages/sqlalchemy/engine/base.py", line 3253, in _run_ddl_visitor\n    conn._run_ddl_visitor(visitorcallable, element, **kwargs)\n  File "/home/runner/DreamShare/.pythonlibs/lib/python3.11/site-packages/sqlalchemy/engine/base.py", line 2459, in _run_ddl_visitor\n    visitorcallable(self.dialect, self, **kwargs).traverse_single(element)\n  File "/home/runner/DreamShare/.pythonlibs/lib/python3.11/site-packages/sqlalchemy/sql/visitors.py", line 664, in traverse_single\n    return meth(obj, **kw)\n           ^^^^^^^^^^^^^^^\n  File "/home/runner/DreamShare/.pythonlibs/lib/python3.11/site-packages/sqlalchemy/sql/ddl.py", line 918, in visit_metadata\n    self.traverse_single(\n  File "/home/runner/DreamShare/.pythonlibs/lib/python3.11/site-packages/sqlalchemy/sql/visitors.py", line 664, in traverse_single\n    return meth(obj, **kw)\n           ^^^^^^^^^^^^^^^\n  File "/home/runner/DreamShare/.pythonlibs/lib/python3.11/site-packages/sqlalchemy/sql/ddl.py", line 956, in visit_table\n    )._invoke_with(self.connection)\n      ^^^^^^^^^^^^^^^^^^^^^^^^^^^^^\n  File "/home/runner/DreamShare/.pythonlibs/lib/python3.11/site-packages/sqlalchemy/sql/ddl.py", line 314, in _invoke_with\n    return bind.execute(self)\n           ^^^^^^^^^^^^^^^^^^\n  File "/home/runner/DreamShare/.pythonlibs/lib/python3.11/site-packages/sqlalchemy/engine/base.py", line 1418, in execute\n    return meth(\n           ^^^^^\n  File "/home/runner/DreamShare/.pythonlibs/lib/python3.11/site-packages/sqlalchemy/sql/ddl.py", line 180, in _execute_on_connection\n    return connection._execute_ddl(\n           ^^^^^^^^^^^^^^^^^^^^^^^^\n  File "/home/runner/DreamShare/.pythonlibs/lib/python3.11/site-packages/sqlalchemy/engine/base.py", line 1529, in _execute_ddl\n    ret = self._execute_context(\n          ^^^^^^^^^^^^^^^^^^^^^^\n  File "/home/runner/DreamShare/.pythonlibs/lib/python3.11/site-packages/sqlalchemy/engine/base.py", line 1846, in _execute_context\n    return self._exec_single_context(\n           ^^^^^^^^^^^^^^^^^^^^^^^^^^\n  File "/home/runner/DreamShare/.pythonlibs/lib/python3.11/site-packages/sqlalchemy/engine/base.py", line 1986, in _exec_single_context\n    self._handle_dbapi_exception(\n  File "/home/runner/DreamShare/.pythonlibs/lib/python3.11/site-packages/sqlalchemy/engine/base.py", line 2355, in _handle_dbapi_exception\n    raise sqlalchemy_exception.with_traceback(exc_info[2]) from e\n  File "/home/runner/DreamShare/.pythonlibs/lib/python3.11/site-packages/sqlalchemy/engine/base.py", line 1967, in _exec_single_context\n    self.dialect.do_execute(\n  File "/home/runner/DreamShare/.pythonlibs/lib/python3.11/site-packages/sqlalchemy/engine/default.py", line 941, in do_execute\n    cursor.execute(statement, parameters)\nsqlalchemy.exc.IntegrityError: (psycopg2.errors.UniqueViolation) duplicate key value violates unique constraint "pg_class_relname_nsp_index"\nDETAIL:  Key (relname, relnamespace)=(user_id_seq, 360560) already exists.\n\n[SQL: \nCREATE TABLE "user" (\n\tid SERIAL NOT NULL, \n\tusername VARCHAR(64) NOT NULL, \n\temail VARCHAR(120) NOT NULL, \n\tpassword_hash VARCHAR(256), \n\tsubscription_type VARCHAR(20), \n\tsubscription_end_date TIMESTAMP WITHOUT TIME ZONE, \n\tmonthly_ai_analysis_count INTEGER, \n\tlast_analysis_reset TIMESTAMP WITHOUT TIME ZONE, \n\tPRIMARY KEY (id), \n\tUNIQUE (username), \n\tUNIQUE (email)\n)\n\n]\n(Background on this error at: https://sqlalche.me/e/20/gkpj)\n', 'context': {}}

2024-11-13 17:46:08,573 - - - 127.0.0.1 - POST http://localhost/login
Level: ERROR
Module: activity_tracker
Message: Error tracking activity: __init__() got an unexpected keyword argument 'created_at'

2024-11-13 17:46:08,573 - - - 127.0.0.1 - POST http://localhost/login
Level: ERROR
Module: activity_tracker
Message: Error tracking activity: __init__() got an unexpected keyword argument 'created_at'

2024-11-13 17:46:08,573 - - - 127.0.0.1 - POST http://localhost/login
Level: ERROR
Module: activity_tracker
Message: Error tracking activity: __init__() got an unexpected keyword argument 'created_at'

2024-11-13 17:46:08,573 - - - 127.0.0.1 - POST http://localhost/login
Level: ERROR
Module: activity_tracker
Message: Error tracking activity: __init__() got an unexpected keyword argument 'created_at'

2024-11-13 17:46:08,573 - - - 127.0.0.1 - POST http://localhost/login
Level: ERROR
Module: activity_tracker
Message: Error tracking activity: __init__() got an unexpected keyword argument 'created_at'

2024-11-13 17:46:08,573 - - - 127.0.0.1 - POST http://localhost/login
Level: ERROR
Module: activity_tracker
Message: Error tracking activity: __init__() got an unexpected keyword argument 'created_at'

2024-11-13 17:46:08,573 - - - 127.0.0.1 - POST http://localhost/login
Level: ERROR
Module: activity_tracker
Message: Error tracking activity: __init__() got an unexpected keyword argument 'created_at'

2024-11-13 17:46:08,675 - - - 127.0.0.1 - GET http://localhost/
Level: ERROR
Module: activity_tracker
Message: Error tracking activity: __init__() got an unexpected keyword argument 'created_at'

2024-11-13 17:46:08,675 - - - 127.0.0.1 - GET http://localhost/
Level: ERROR
Module: activity_tracker
Message: Error tracking activity: __init__() got an unexpected keyword argument 'created_at'

2024-11-13 17:46:08,675 - - - 127.0.0.1 - GET http://localhost/
Level: ERROR
Module: activity_tracker
Message: Error tracking activity: __init__() got an unexpected keyword argument 'created_at'

2024-11-13 17:46:08,675 - - - 127.0.0.1 - GET http://localhost/
Level: ERROR
Module: activity_tracker
Message: Error tracking activity: __init__() got an unexpected keyword argument 'created_at'

2024-11-13 17:46:08,675 - - - 127.0.0.1 - GET http://localhost/
Level: ERROR
Module: activity_tracker
Message: Error tracking activity: __init__() got an unexpected keyword argument 'created_at'

2024-11-13 17:46:08,675 - - - 127.0.0.1 - GET http://localhost/
Level: ERROR
Module: activity_tracker
Message: Error tracking activity: __init__() got an unexpected keyword argument 'created_at'

2024-11-13 17:46:08,675 - - - 127.0.0.1 - GET http://localhost/
Level: ERROR
Module: activity_tracker
Message: Error tracking activity: __init__() got an unexpected keyword argument 'created_at'

2024-11-13 17:46:08,848 - - - 127.0.0.1 - GET http://localhost/
Level: ERROR
Module: activity_tracker
Message: Error tracking activity: __init__() got an unexpected keyword argument 'created_at'

2024-11-13 17:46:08,848 - - - 127.0.0.1 - GET http://localhost/
Level: ERROR
Module: activity_tracker
Message: Error tracking activity: __init__() got an unexpected keyword argument 'created_at'

2024-11-13 17:46:08,848 - - - 127.0.0.1 - GET http://localhost/
Level: ERROR
Module: activity_tracker
Message: Error tracking activity: __init__() got an unexpected keyword argument 'created_at'

2024-11-13 17:46:08,848 - - - 127.0.0.1 - GET http://localhost/
Level: ERROR
Module: activity_tracker
Message: Error tracking activity: __init__() got an unexpected keyword argument 'created_at'

2024-11-13 17:46:08,848 - - - 127.0.0.1 - GET http://localhost/
Level: ERROR
Module: activity_tracker
Message: Error tracking activity: __init__() got an unexpected keyword argument 'created_at'

2024-11-13 17:46:08,848 - - - 127.0.0.1 - GET http://localhost/
Level: ERROR
Module: activity_tracker
Message: Error tracking activity: __init__() got an unexpected keyword argument 'created_at'

2024-11-13 17:46:08,848 - - - 127.0.0.1 - GET http://localhost/
Level: ERROR
Module: activity_tracker
Message: Error tracking activity: __init__() got an unexpected keyword argument 'created_at'

2024-11-13 17:46:11,040 - - - 127.0.0.1 - POST http://localhost/register
Level: ERROR
Module: activity_tracker
Message: Error tracking activity: __init__() got an unexpected keyword argument 'created_at'

2024-11-13 17:46:11,040 - - - 127.0.0.1 - POST http://localhost/register
Level: ERROR
Module: activity_tracker
Message: Error tracking activity: __init__() got an unexpected keyword argument 'created_at'

2024-11-13 17:46:11,040 - - - 127.0.0.1 - POST http://localhost/register
Level: ERROR
Module: activity_tracker
Message: Error tracking activity: __init__() got an unexpected keyword argument 'created_at'

2024-11-13 17:46:11,040 - - - 127.0.0.1 - POST http://localhost/register
Level: ERROR
Module: activity_tracker
Message: Error tracking activity: __init__() got an unexpected keyword argument 'created_at'

2024-11-13 17:46:11,040 - - - 127.0.0.1 - POST http://localhost/register
Level: ERROR
Module: activity_tracker
Message: Error tracking activity: __init__() got an unexpected keyword argument 'created_at'

2024-11-13 17:46:11,040 - - - 127.0.0.1 - POST http://localhost/register
Level: ERROR
Module: activity_tracker
Message: Error tracking activity: __init__() got an unexpected keyword argument 'created_at'

2024-11-13 17:46:11,040 - - - 127.0.0.1 - POST http://localhost/register
Level: ERROR
Module: activity_tracker
Message: Error tracking activity: __init__() got an unexpected keyword argument 'created_at'

2024-11-13 17:46:11,040 - - - 127.0.0.1 - POST http://localhost/register
Level: ERROR
Module: activity_tracker
Message: Error tracking activity: __init__() got an unexpected keyword argument 'created_at'

2024-11-13 17:46:11,145 - - - 127.0.0.1 - GET http://localhost/
Level: ERROR
Module: activity_tracker
Message: Error tracking activity: __init__() got an unexpected keyword argument 'created_at'

2024-11-13 17:46:11,145 - - - 127.0.0.1 - GET http://localhost/
Level: ERROR
Module: activity_tracker
Message: Error tracking activity: __init__() got an unexpected keyword argument 'created_at'

2024-11-13 17:46:11,145 - - - 127.0.0.1 - GET http://localhost/
Level: ERROR
Module: activity_tracker
Message: Error tracking activity: __init__() got an unexpected keyword argument 'created_at'

2024-11-13 17:46:11,145 - - - 127.0.0.1 - GET http://localhost/
Level: ERROR
Module: activity_tracker
Message: Error tracking activity: __init__() got an unexpected keyword argument 'created_at'

2024-11-13 17:46:11,145 - - - 127.0.0.1 - GET http://localhost/
Level: ERROR
Module: activity_tracker
Message: Error tracking activity: __init__() got an unexpected keyword argument 'created_at'

2024-11-13 17:46:11,145 - - - 127.0.0.1 - GET http://localhost/
Level: ERROR
Module: activity_tracker
Message: Error tracking activity: __init__() got an unexpected keyword argument 'created_at'

2024-11-13 17:46:11,145 - - - 127.0.0.1 - GET http://localhost/
Level: ERROR
Module: activity_tracker
Message: Error tracking activity: __init__() got an unexpected keyword argument 'created_at'

2024-11-13 17:46:11,145 - - - 127.0.0.1 - GET http://localhost/
Level: ERROR
Module: activity_tracker
Message: Error tracking activity: __init__() got an unexpected keyword argument 'created_at'

2024-11-13 17:46:11,330 - - - 127.0.0.1 - GET http://localhost/
Level: ERROR
Module: activity_tracker
Message: Error tracking activity: __init__() got an unexpected keyword argument 'created_at'

2024-11-13 17:46:11,330 - - - 127.0.0.1 - GET http://localhost/
Level: ERROR
Module: activity_tracker
Message: Error tracking activity: __init__() got an unexpected keyword argument 'created_at'

2024-11-13 17:46:11,330 - - - 127.0.0.1 - GET http://localhost/
Level: ERROR
Module: activity_tracker
Message: Error tracking activity: __init__() got an unexpected keyword argument 'created_at'

2024-11-13 17:46:11,330 - - - 127.0.0.1 - GET http://localhost/
Level: ERROR
Module: activity_tracker
Message: Error tracking activity: __init__() got an unexpected keyword argument 'created_at'

2024-11-13 17:46:11,330 - - - 127.0.0.1 - GET http://localhost/
Level: ERROR
Module: activity_tracker
Message: Error tracking activity: __init__() got an unexpected keyword argument 'created_at'

2024-11-13 17:46:11,330 - - - 127.0.0.1 - GET http://localhost/
Level: ERROR
Module: activity_tracker
Message: Error tracking activity: __init__() got an unexpected keyword argument 'created_at'

2024-11-13 17:46:11,330 - - - 127.0.0.1 - GET http://localhost/
Level: ERROR
Module: activity_tracker
Message: Error tracking activity: __init__() got an unexpected keyword argument 'created_at'

2024-11-13 17:46:11,330 - - - 127.0.0.1 - GET http://localhost/
Level: ERROR
Module: activity_tracker
Message: Error tracking activity: __init__() got an unexpected keyword argument 'created_at'

2024-11-13 17:46:13,172 - - - 127.0.0.1 - POST http://localhost/login
Level: ERROR
Module: activity_tracker
Message: Error tracking activity: __init__() got an unexpected keyword argument 'created_at'

2024-11-13 17:46:13,172 - - - 127.0.0.1 - POST http://localhost/login
Level: ERROR
Module: activity_tracker
Message: Error tracking activity: __init__() got an unexpected keyword argument 'created_at'

2024-11-13 17:46:13,172 - - - 127.0.0.1 - POST http://localhost/login
Level: ERROR
Module: activity_tracker
Message: Error tracking activity: __init__() got an unexpected keyword argument 'created_at'

2024-11-13 17:46:13,172 - - - 127.0.0.1 - POST http://localhost/login
Level: ERROR
Module: activity_tracker
Message: Error tracking activity: __init__() got an unexpected keyword argument 'created_at'

2024-11-13 17:46:13,172 - - - 127.0.0.1 - POST http://localhost/login
Level: ERROR
Module: activity_tracker
Message: Error tracking activity: __init__() got an unexpected keyword argument 'created_at'

2024-11-13 17:46:13,172 - - - 127.0.0.1 - POST http://localhost/login
Level: ERROR
Module: activity_tracker
Message: Error tracking activity: __init__() got an unexpected keyword argument 'created_at'

2024-11-13 17:46:13,172 - - - 127.0.0.1 - POST http://localhost/login
Level: ERROR
Module: activity_tracker
Message: Error tracking activity: __init__() got an unexpected keyword argument 'created_at'

2024-11-13 17:46:13,172 - - - 127.0.0.1 - POST http://localhost/login
Level: ERROR
Module: activity_tracker
Message: Error tracking activity: __init__() got an unexpected keyword argument 'created_at'

2024-11-13 17:46:13,172 - - - 127.0.0.1 - POST http://localhost/login
Level: ERROR
Module: activity_tracker
Message: Error tracking activity: __init__() got an unexpected keyword argument 'created_at'

2024-11-13 17:46:13,281 - - - 127.0.0.1 - POST http://localhost/dream/new
Level: ERROR
Module: routes
Message: Error creating dream: __init__() got an unexpected keyword argument 'is_public'

2024-11-13 17:46:13,281 - - - 127.0.0.1 - POST http://localhost/dream/new
Level: ERROR
Module: routes
Message: Error creating dream: __init__() got an unexpected keyword argument 'is_public'

2024-11-13 17:46:13,281 - - - 127.0.0.1 - POST http://localhost/dream/new
Level: ERROR
Module: routes
Message: Error creating dream: __init__() got an unexpected keyword argument 'is_public'

2024-11-13 17:46:13,281 - - - 127.0.0.1 - POST http://localhost/dream/new
Level: ERROR
Module: routes
Message: Error creating dream: __init__() got an unexpected keyword argument 'is_public'

2024-11-13 17:46:13,281 - - - 127.0.0.1 - POST http://localhost/dream/new
Level: ERROR
Module: routes
Message: Error creating dream: __init__() got an unexpected keyword argument 'is_public'

2024-11-13 17:46:13,281 - - - 127.0.0.1 - POST http://localhost/dream/new
Level: ERROR
Module: routes
Message: Error creating dream: __init__() got an unexpected keyword argument 'is_public'

2024-11-13 17:46:13,281 - - - 127.0.0.1 - POST http://localhost/dream/new
Level: ERROR
Module: routes
Message: Error creating dream: __init__() got an unexpected keyword argument 'is_public'

2024-11-13 17:46:13,281 - - - 127.0.0.1 - POST http://localhost/dream/new
Level: ERROR
Module: routes
Message: Error creating dream: __init__() got an unexpected keyword argument 'is_public'

2024-11-13 17:46:13,281 - - - 127.0.0.1 - POST http://localhost/dream/new
Level: ERROR
Module: routes
Message: Error creating dream: __init__() got an unexpected keyword argument 'is_public'

2024-11-13 17:46:19,206 - - - None - GET http://localhost/
Level: ERROR
Module: logging_config
Message: Application Error: {'timestamp': '2024-11-13T17:46:19.206243', 'error_type': 'ValueError', 'error_message': 'Test error', 'traceback': 'NoneType: None\n', 'context': {'test': 'context'}, 'url': 'http://localhost/', 'method': 'GET', 'headers': {'Host': 'localhost'}, 'remote_addr': None}

2024-11-13 17:46:19,206 - - - None - GET http://localhost/
Level: ERROR
Module: logging_config
Message: Application Error: {'timestamp': '2024-11-13T17:46:19.206243', 'error_type': 'ValueError', 'error_message': 'Test error', 'traceback': 'NoneType: None\n', 'context': {'test': 'context'}, 'url': 'http://localhost/', 'method': 'GET', 'headers': {'Host': 'localhost'}, 'remote_addr': None}

2024-11-13 17:46:19,206 - - - None - GET http://localhost/
Level: ERROR
Module: logging_config
Message: Application Error: {'timestamp': '2024-11-13T17:46:19.206243', 'error_type': 'ValueError', 'error_message': 'Test error', 'traceback': 'NoneType: None\n', 'context': {'test': 'context'}, 'url': 'http://localhost/', 'method': 'GET', 'headers': {'Host': 'localhost'}, 'remote_addr': None}

2024-11-13 17:46:19,206 - - - None - GET http://localhost/
Level: ERROR
Module: logging_config
Message: Application Error: {'timestamp': '2024-11-13T17:46:19.206243', 'error_type': 'ValueError', 'error_message': 'Test error', 'traceback': 'NoneType: None\n', 'context': {'test': 'context'}, 'url': 'http://localhost/', 'method': 'GET', 'headers': {'Host': 'localhost'}, 'remote_addr': None}

2024-11-13 17:46:19,206 - - - None - GET http://localhost/
Level: ERROR
Module: logging_config
Message: Application Error: {'timestamp': '2024-11-13T17:46:19.206243', 'error_type': 'ValueError', 'error_message': 'Test error', 'traceback': 'NoneType: None\n', 'context': {'test': 'context'}, 'url': 'http://localhost/', 'method': 'GET', 'headers': {'Host': 'localhost'}, 'remote_addr': None}

2024-11-13 17:46:19,206 - - - None - GET http://localhost/
Level: ERROR
Module: logging_config
Message: Application Error: {'timestamp': '2024-11-13T17:46:19.206243', 'error_type': 'ValueError', 'error_message': 'Test error', 'traceback': 'NoneType: None\n', 'context': {'test': 'context'}, 'url': 'http://localhost/', 'method': 'GET', 'headers': {'Host': 'localhost'}, 'remote_addr': None}

2024-11-13 17:46:19,206 - - - None - GET http://localhost/
Level: ERROR
Module: logging_config
Message: Application Error: {'timestamp': '2024-11-13T17:46:19.206243', 'error_type': 'ValueError', 'error_message': 'Test error', 'traceback': 'NoneType: None\n', 'context': {'test': 'context'}, 'url': 'http://localhost/', 'method': 'GET', 'headers': {'Host': 'localhost'}, 'remote_addr': None}

2024-11-13 17:46:19,206 - - - None - GET http://localhost/
Level: ERROR
Module: logging_config
Message: Application Error: {'timestamp': '2024-11-13T17:46:19.206243', 'error_type': 'ValueError', 'error_message': 'Test error', 'traceback': 'NoneType: None\n', 'context': {'test': 'context'}, 'url': 'http://localhost/', 'method': 'GET', 'headers': {'Host': 'localhost'}, 'remote_addr': None}

2024-11-13 17:46:19,206 - - - None - GET http://localhost/
Level: ERROR
Module: logging_config
Message: Application Error: {'timestamp': '2024-11-13T17:46:19.206243', 'error_type': 'ValueError', 'error_message': 'Test error', 'traceback': 'NoneType: None\n', 'context': {'test': 'context'}, 'url': 'http://localhost/', 'method': 'GET', 'headers': {'Host': 'localhost'}, 'remote_addr': None}

2024-11-13 17:46:19,206 - - - None - GET http://localhost/
Level: ERROR
Module: logging_config
Message: Application Error: {'timestamp': '2024-11-13T17:46:19.206243', 'error_type': 'ValueError', 'error_message': 'Test error', 'traceback': 'NoneType: None\n', 'context': {'test': 'context'}, 'url': 'http://localhost/', 'method': 'GET', 'headers': {'Host': 'localhost'}, 'remote_addr': None}

2024-11-13 17:46:19,206 - - - None - GET http://localhost/
Level: ERROR
Module: logging_config
Message: Application Error: {'timestamp': '2024-11-13T17:46:19.206243', 'error_type': 'ValueError', 'error_message': 'Test error', 'traceback': 'NoneType: None\n', 'context': {'test': 'context'}, 'url': 'http://localhost/', 'method': 'GET', 'headers': {'Host': 'localhost'}, 'remote_addr': None}

2024-11-13 17:46:19,206 - - - None - GET http://localhost/
Level: ERROR
Module: logging_config
Message: Application Error: {'timestamp': '2024-11-13T17:46:19.206243', 'error_type': 'ValueError', 'error_message': 'Test error', 'traceback': 'NoneType: None\n', 'context': {'test': 'context'}, 'url': 'http://localhost/', 'method': 'GET', 'headers': {'Host': 'localhost'}, 'remote_addr': None}

2024-11-13 17:46:20,611 - - - None - GET http://localhost/
Level: ERROR
Module: logging_config
Message: Application Error: {'timestamp': '2024-11-13T17:46:20.610721', 'error_type': 'ValueError', 'error_message': 'Test error', 'traceback': 'NoneType: None\n', 'context': {'test': 'context'}, 'url': 'http://localhost/', 'method': 'GET', 'headers': {'Host': 'localhost'}, 'remote_addr': None}

2024-11-13 17:46:20,611 - - - None - GET http://localhost/
Level: ERROR
Module: logging_config
Message: Application Error: {'timestamp': '2024-11-13T17:46:20.610721', 'error_type': 'ValueError', 'error_message': 'Test error', 'traceback': 'NoneType: None\n', 'context': {'test': 'context'}, 'url': 'http://localhost/', 'method': 'GET', 'headers': {'Host': 'localhost'}, 'remote_addr': None}

2024-11-13 17:46:20,611 - - - None - GET http://localhost/
Level: ERROR
Module: logging_config
Message: Application Error: {'timestamp': '2024-11-13T17:46:20.610721', 'error_type': 'ValueError', 'error_message': 'Test error', 'traceback': 'NoneType: None\n', 'context': {'test': 'context'}, 'url': 'http://localhost/', 'method': 'GET', 'headers': {'Host': 'localhost'}, 'remote_addr': None}

2024-11-13 17:46:20,611 - - - None - GET http://localhost/
Level: ERROR
Module: logging_config
Message: Application Error: {'timestamp': '2024-11-13T17:46:20.610721', 'error_type': 'ValueError', 'error_message': 'Test error', 'traceback': 'NoneType: None\n', 'context': {'test': 'context'}, 'url': 'http://localhost/', 'method': 'GET', 'headers': {'Host': 'localhost'}, 'remote_addr': None}

2024-11-13 17:46:20,611 - - - None - GET http://localhost/
Level: ERROR
Module: logging_config
Message: Application Error: {'timestamp': '2024-11-13T17:46:20.610721', 'error_type': 'ValueError', 'error_message': 'Test error', 'traceback': 'NoneType: None\n', 'context': {'test': 'context'}, 'url': 'http://localhost/', 'method': 'GET', 'headers': {'Host': 'localhost'}, 'remote_addr': None}

2024-11-13 17:46:20,611 - - - None - GET http://localhost/
Level: ERROR
Module: logging_config
Message: Application Error: {'timestamp': '2024-11-13T17:46:20.610721', 'error_type': 'ValueError', 'error_message': 'Test error', 'traceback': 'NoneType: None\n', 'context': {'test': 'context'}, 'url': 'http://localhost/', 'method': 'GET', 'headers': {'Host': 'localhost'}, 'remote_addr': None}

2024-11-13 17:46:20,611 - - - None - GET http://localhost/
Level: ERROR
Module: logging_config
Message: Application Error: {'timestamp': '2024-11-13T17:46:20.610721', 'error_type': 'ValueError', 'error_message': 'Test error', 'traceback': 'NoneType: None\n', 'context': {'test': 'context'}, 'url': 'http://localhost/', 'method': 'GET', 'headers': {'Host': 'localhost'}, 'remote_addr': None}

2024-11-13 17:46:20,611 - - - None - GET http://localhost/
Level: ERROR
Module: logging_config
Message: Application Error: {'timestamp': '2024-11-13T17:46:20.610721', 'error_type': 'ValueError', 'error_message': 'Test error', 'traceback': 'NoneType: None\n', 'context': {'test': 'context'}, 'url': 'http://localhost/', 'method': 'GET', 'headers': {'Host': 'localhost'}, 'remote_addr': None}

2024-11-13 17:46:20,611 - - - None - GET http://localhost/
Level: ERROR
Module: logging_config
Message: Application Error: {'timestamp': '2024-11-13T17:46:20.610721', 'error_type': 'ValueError', 'error_message': 'Test error', 'traceback': 'NoneType: None\n', 'context': {'test': 'context'}, 'url': 'http://localhost/', 'method': 'GET', 'headers': {'Host': 'localhost'}, 'remote_addr': None}

2024-11-13 17:46:20,611 - - - None - GET http://localhost/
Level: ERROR
Module: logging_config
Message: Application Error: {'timestamp': '2024-11-13T17:46:20.610721', 'error_type': 'ValueError', 'error_message': 'Test error', 'traceback': 'NoneType: None\n', 'context': {'test': 'context'}, 'url': 'http://localhost/', 'method': 'GET', 'headers': {'Host': 'localhost'}, 'remote_addr': None}

2024-11-13 17:46:20,611 - - - None - GET http://localhost/
Level: ERROR
Module: logging_config
Message: Application Error: {'timestamp': '2024-11-13T17:46:20.610721', 'error_type': 'ValueError', 'error_message': 'Test error', 'traceback': 'NoneType: None\n', 'context': {'test': 'context'}, 'url': 'http://localhost/', 'method': 'GET', 'headers': {'Host': 'localhost'}, 'remote_addr': None}

2024-11-13 17:46:20,611 - - - None - GET http://localhost/
Level: ERROR
Module: logging_config
Message: Application Error: {'timestamp': '2024-11-13T17:46:20.610721', 'error_type': 'ValueError', 'error_message': 'Test error', 'traceback': 'NoneType: None\n', 'context': {'test': 'context'}, 'url': 'http://localhost/', 'method': 'GET', 'headers': {'Host': 'localhost'}, 'remote_addr': None}

2024-11-13 17:47:25,473 - - - 127.0.0.1 - POST http://localhost/register
Level: ERROR
Module: activity_tracker
Message: Error tracking activity: __init__() got an unexpected keyword argument 'created_at'

2024-11-13 17:47:25,473 - - - 127.0.0.1 - POST http://localhost/register
Level: ERROR
Module: activity_tracker
Message: Error tracking activity: __init__() got an unexpected keyword argument 'created_at'

2024-11-13 17:47:25,575 - - - 127.0.0.1 - GET http://localhost/
Level: ERROR
Module: activity_tracker
Message: Error tracking activity: __init__() got an unexpected keyword argument 'created_at'

2024-11-13 17:47:25,575 - - - 127.0.0.1 - GET http://localhost/
Level: ERROR
Module: activity_tracker
Message: Error tracking activity: __init__() got an unexpected keyword argument 'created_at'

2024-11-13 17:47:25,730 - - - 127.0.0.1 - GET http://localhost/
Level: ERROR
Module: activity_tracker
Message: Error tracking activity: __init__() got an unexpected keyword argument 'created_at'

2024-11-13 17:47:25,730 - - - 127.0.0.1 - GET http://localhost/
Level: ERROR
Module: activity_tracker
Message: Error tracking activity: __init__() got an unexpected keyword argument 'created_at'

2024-11-13 17:47:29,393 - - - None - GET http://localhost/
Level: ERROR
Module: logging_config
Message: Application Error: {'timestamp': '2024-11-13T17:47:29.393516', 'error_type': 'ValueError', 'error_message': 'Test error', 'traceback': 'NoneType: None\n', 'context': {'test': 'context'}, 'url': 'http://localhost/', 'method': 'GET', 'headers': {'Host': 'localhost'}, 'remote_addr': None}

2024-11-13 17:47:29,393 - - - None - GET http://localhost/
Level: ERROR
Module: logging_config
Message: Application Error: {'timestamp': '2024-11-13T17:47:29.393516', 'error_type': 'ValueError', 'error_message': 'Test error', 'traceback': 'NoneType: None\n', 'context': {'test': 'context'}, 'url': 'http://localhost/', 'method': 'GET', 'headers': {'Host': 'localhost'}, 'remote_addr': None}

2024-11-13 17:47:30,665 - None - None - None None
Level: ERROR
Module: logging_config
Message: Application Error: {'timestamp': '2024-11-13T17:47:30.640551', 'error_type': 'IntegrityError', 'error_message': '(psycopg2.errors.UniqueViolation) duplicate key value violates unique constraint "pg_class_relname_nsp_index"\nDETAIL:  Key (relname, relnamespace)=(user_id_seq, 360560) already exists.\n\n[SQL: \nCREATE TABLE "user" (\n\tid SERIAL NOT NULL, \n\tusername VARCHAR(64) NOT NULL, \n\temail VARCHAR(120) NOT NULL, \n\tpassword_hash VARCHAR(256), \n\tsubscription_type VARCHAR(20), \n\tsubscription_end_date TIMESTAMP WITHOUT TIME ZONE, \n\tmonthly_ai_analysis_count INTEGER, \n\tlast_analysis_reset TIMESTAMP WITHOUT TIME ZONE, \n\tPRIMARY KEY (id), \n\tUNIQUE (username), \n\tUNIQUE (email)\n)\n\n]\n(Background on this error at: https://sqlalche.me/e/20/gkpj)', 'traceback': 'Traceback (most recent call last):\n  File "/home/runner/DreamShare/.pythonlibs/lib/python3.11/site-packages/sqlalchemy/engine/base.py", line 1967, in _exec_single_context\n    self.dialect.do_execute(\n  File "/home/runner/DreamShare/.pythonlibs/lib/python3.11/site-packages/sqlalchemy/engine/default.py", line 941, in do_execute\n    cursor.execute(statement, parameters)\npsycopg2.errors.UniqueViolation: duplicate key value violates unique constraint "pg_class_relname_nsp_index"\nDETAIL:  Key (relname, relnamespace)=(user_id_seq, 360560) already exists.\n\n\nThe above exception was the direct cause of the following exception:\n\nTraceback (most recent call last):\n  File "/home/runner/DreamShare/app.py", line 78, in create_app\n    db.create_all()\n  File "/home/runner/DreamShare/.pythonlibs/lib/python3.11/site-packages/flask_sqlalchemy/extension.py", line 900, in create_all\n    self._call_for_binds(bind_key, "create_all")\n  File "/home/runner/DreamShare/.pythonlibs/lib/python3.11/site-packages/flask_sqlalchemy/extension.py", line 881, in _call_for_binds\n    getattr(metadata, op_name)(bind=engine)\n  File "/home/runner/DreamShare/.pythonlibs/lib/python3.11/site-packages/sqlalchemy/sql/schema.py", line 5868, in create_all\n    bind._run_ddl_visitor(\n  File "/home/runner/DreamShare/.pythonlibs/lib/python3.11/site-packages/sqlalchemy/engine/base.py", line 3253, in _run_ddl_visitor\n    conn._run_ddl_visitor(visitorcallable, element, **kwargs)\n  File "/home/runner/DreamShare/.pythonlibs/lib/python3.11/site-packages/sqlalchemy/engine/base.py", line 2459, in _run_ddl_visitor\n    visitorcallable(self.dialect, self, **kwargs).traverse_single(element)\n  File "/home/runner/DreamShare/.pythonlibs/lib/python3.11/site-packages/sqlalchemy/sql/visitors.py", line 664, in traverse_single\n    return meth(obj, **kw)\n           ^^^^^^^^^^^^^^^\n  File "/home/runner/DreamShare/.pythonlibs/lib/python3.11/site-packages/sqlalchemy/sql/ddl.py", line 918, in visit_metadata\n    self.traverse_single(\n  File "/home/runner/DreamShare/.pythonlibs/lib/python3.11/site-packages/sqlalchemy/sql/visitors.py", line 664, in traverse_single\n    return meth(obj, **kw)\n           ^^^^^^^^^^^^^^^\n  File "/home/runner/DreamShare/.pythonlibs/lib/python3.11/site-packages/sqlalchemy/sql/ddl.py", line 956, in visit_table\n    )._invoke_with(self.connection)\n      ^^^^^^^^^^^^^^^^^^^^^^^^^^^^^\n  File "/home/runner/DreamShare/.pythonlibs/lib/python3.11/site-packages/sqlalchemy/sql/ddl.py", line 314, in _invoke_with\n    return bind.execute(self)\n           ^^^^^^^^^^^^^^^^^^\n  File "/home/runner/DreamShare/.pythonlibs/lib/python3.11/site-packages/sqlalchemy/engine/base.py", line 1418, in execute\n    return meth(\n           ^^^^^\n  File "/home/runner/DreamShare/.pythonlibs/lib/python3.11/site-packages/sqlalchemy/sql/ddl.py", line 180, in _execute_on_connection\n    return connection._execute_ddl(\n           ^^^^^^^^^^^^^^^^^^^^^^^^\n  File "/home/runner/DreamShare/.pythonlibs/lib/python3.11/site-packages/sqlalchemy/engine/base.py", line 1529, in _execute_ddl\n    ret = self._execute_context(\n          ^^^^^^^^^^^^^^^^^^^^^^\n  File "/home/runner/DreamShare/.pythonlibs/lib/python3.11/site-packages/sqlalchemy/engine/base.py", line 1846, in _execute_context\n    return self._exec_single_context(\n           ^^^^^^^^^^^^^^^^^^^^^^^^^^\n  File "/home/runner/DreamShare/.pythonlibs/lib/python3.11/site-packages/sqlalchemy/engine/base.py", line 1986, in _exec_single_context\n    self._handle_dbapi_exception(\n  File "/home/runner/DreamShare/.pythonlibs/lib/python3.11/site-packages/sqlalchemy/engine/base.py", line 2355, in _handle_dbapi_exception\n    raise sqlalchemy_exception.with_traceback(exc_info[2]) from e\n  File "/home/runner/DreamShare/.pythonlibs/lib/python3.11/site-packages/sqlalchemy/engine/base.py", line 1967, in _exec_single_context\n    self.dialect.do_execute(\n  File "/home/runner/DreamShare/.pythonlibs/lib/python3.11/site-packages/sqlalchemy/engine/default.py", line 941, in do_execute\n    cursor.execute(statement, parameters)\nsqlalchemy.exc.IntegrityError: (psycopg2.errors.UniqueViolation) duplicate key value violates unique constraint "pg_class_relname_nsp_index"\nDETAIL:  Key (relname, relnamespace)=(user_id_seq, 360560) already exists.\n\n[SQL: \nCREATE TABLE "user" (\n\tid SERIAL NOT NULL, \n\tusername VARCHAR(64) NOT NULL, \n\temail VARCHAR(120) NOT NULL, \n\tpassword_hash VARCHAR(256), \n\tsubscription_type VARCHAR(20), \n\tsubscription_end_date TIMESTAMP WITHOUT TIME ZONE, \n\tmonthly_ai_analysis_count INTEGER, \n\tlast_analysis_reset TIMESTAMP WITHOUT TIME ZONE, \n\tPRIMARY KEY (id), \n\tUNIQUE (username), \n\tUNIQUE (email)\n)\n\n]\n(Background on this error at: https://sqlalche.me/e/20/gkpj)\n', 'context': {}}

2024-11-13 17:47:30,664 - None - None - None None
Level: ERROR
Module: logging_config
Message: Application Error: {'timestamp': '2024-11-13T17:47:30.639052', 'error_type': 'IntegrityError', 'error_message': '(psycopg2.errors.UniqueViolation) duplicate key value violates unique constraint "pg_class_relname_nsp_index"\nDETAIL:  Key (relname, relnamespace)=(user_id_seq, 360560) already exists.\n\n[SQL: \nCREATE TABLE "user" (\n\tid SERIAL NOT NULL, \n\tusername VARCHAR(64) NOT NULL, \n\temail VARCHAR(120) NOT NULL, \n\tpassword_hash VARCHAR(256), \n\tsubscription_type VARCHAR(20), \n\tsubscription_end_date TIMESTAMP WITHOUT TIME ZONE, \n\tmonthly_ai_analysis_count INTEGER, \n\tlast_analysis_reset TIMESTAMP WITHOUT TIME ZONE, \n\tPRIMARY KEY (id), \n\tUNIQUE (username), \n\tUNIQUE (email)\n)\n\n]\n(Background on this error at: https://sqlalche.me/e/20/gkpj)', 'traceback': 'Traceback (most recent call last):\n  File "/home/runner/DreamShare/.pythonlibs/lib/python3.11/site-packages/sqlalchemy/engine/base.py", line 1967, in _exec_single_context\n    self.dialect.do_execute(\n  File "/home/runner/DreamShare/.pythonlibs/lib/python3.11/site-packages/sqlalchemy/engine/default.py", line 941, in do_execute\n    cursor.execute(statement, parameters)\npsycopg2.errors.UniqueViolation: duplicate key value violates unique constraint "pg_class_relname_nsp_index"\nDETAIL:  Key (relname, relnamespace)=(user_id_seq, 360560) already exists.\n\n\nThe above exception was the direct cause of the following exception:\n\nTraceback (most recent call last):\n  File "/home/runner/DreamShare/app.py", line 78, in create_app\n    db.create_all()\n  File "/home/runner/DreamShare/.pythonlibs/lib/python3.11/site-packages/flask_sqlalchemy/extension.py", line 900, in create_all\n    self._call_for_binds(bind_key, "create_all")\n  File "/home/runner/DreamShare/.pythonlibs/lib/python3.11/site-packages/flask_sqlalchemy/extension.py", line 881, in _call_for_binds\n    getattr(metadata, op_name)(bind=engine)\n  File "/home/runner/DreamShare/.pythonlibs/lib/python3.11/site-packages/sqlalchemy/sql/schema.py", line 5868, in create_all\n    bind._run_ddl_visitor(\n  File "/home/runner/DreamShare/.pythonlibs/lib/python3.11/site-packages/sqlalchemy/engine/base.py", line 3253, in _run_ddl_visitor\n    conn._run_ddl_visitor(visitorcallable, element, **kwargs)\n  File "/home/runner/DreamShare/.pythonlibs/lib/python3.11/site-packages/sqlalchemy/engine/base.py", line 2459, in _run_ddl_visitor\n    visitorcallable(self.dialect, self, **kwargs).traverse_single(element)\n  File "/home/runner/DreamShare/.pythonlibs/lib/python3.11/site-packages/sqlalchemy/sql/visitors.py", line 664, in traverse_single\n    return meth(obj, **kw)\n           ^^^^^^^^^^^^^^^\n  File "/home/runner/DreamShare/.pythonlibs/lib/python3.11/site-packages/sqlalchemy/sql/ddl.py", line 918, in visit_metadata\n    self.traverse_single(\n  File "/home/runner/DreamShare/.pythonlibs/lib/python3.11/site-packages/sqlalchemy/sql/visitors.py", line 664, in traverse_single\n    return meth(obj, **kw)\n           ^^^^^^^^^^^^^^^\n  File "/home/runner/DreamShare/.pythonlibs/lib/python3.11/site-packages/sqlalchemy/sql/ddl.py", line 956, in visit_table\n    )._invoke_with(self.connection)\n      ^^^^^^^^^^^^^^^^^^^^^^^^^^^^^\n  File "/home/runner/DreamShare/.pythonlibs/lib/python3.11/site-packages/sqlalchemy/sql/ddl.py", line 314, in _invoke_with\n    return bind.execute(self)\n           ^^^^^^^^^^^^^^^^^^\n  File "/home/runner/DreamShare/.pythonlibs/lib/python3.11/site-packages/sqlalchemy/engine/base.py", line 1418, in execute\n    return meth(\n           ^^^^^\n  File "/home/runner/DreamShare/.pythonlibs/lib/python3.11/site-packages/sqlalchemy/sql/ddl.py", line 180, in _execute_on_connection\n    return connection._execute_ddl(\n           ^^^^^^^^^^^^^^^^^^^^^^^^\n  File "/home/runner/DreamShare/.pythonlibs/lib/python3.11/site-packages/sqlalchemy/engine/base.py", line 1529, in _execute_ddl\n    ret = self._execute_context(\n          ^^^^^^^^^^^^^^^^^^^^^^\n  File "/home/runner/DreamShare/.pythonlibs/lib/python3.11/site-packages/sqlalchemy/engine/base.py", line 1846, in _execute_context\n    return self._exec_single_context(\n           ^^^^^^^^^^^^^^^^^^^^^^^^^^\n  File "/home/runner/DreamShare/.pythonlibs/lib/python3.11/site-packages/sqlalchemy/engine/base.py", line 1986, in _exec_single_context\n    self._handle_dbapi_exception(\n  File "/home/runner/DreamShare/.pythonlibs/lib/python3.11/site-packages/sqlalchemy/engine/base.py", line 2355, in _handle_dbapi_exception\n    raise sqlalchemy_exception.with_traceback(exc_info[2]) from e\n  File "/home/runner/DreamShare/.pythonlibs/lib/python3.11/site-packages/sqlalchemy/engine/base.py", line 1967, in _exec_single_context\n    self.dialect.do_execute(\n  File "/home/runner/DreamShare/.pythonlibs/lib/python3.11/site-packages/sqlalchemy/engine/default.py", line 941, in do_execute\n    cursor.execute(statement, parameters)\nsqlalchemy.exc.IntegrityError: (psycopg2.errors.UniqueViolation) duplicate key value violates unique constraint "pg_class_relname_nsp_index"\nDETAIL:  Key (relname, relnamespace)=(user_id_seq, 360560) already exists.\n\n[SQL: \nCREATE TABLE "user" (\n\tid SERIAL NOT NULL, \n\tusername VARCHAR(64) NOT NULL, \n\temail VARCHAR(120) NOT NULL, \n\tpassword_hash VARCHAR(256), \n\tsubscription_type VARCHAR(20), \n\tsubscription_end_date TIMESTAMP WITHOUT TIME ZONE, \n\tmonthly_ai_analysis_count INTEGER, \n\tlast_analysis_reset TIMESTAMP WITHOUT TIME ZONE, \n\tPRIMARY KEY (id), \n\tUNIQUE (username), \n\tUNIQUE (email)\n)\n\n]\n(Background on this error at: https://sqlalche.me/e/20/gkpj)\n', 'context': {}}

2024-11-13 17:47:54,033 - - - 127.0.0.1 - POST http://localhost/login
Level: ERROR
Module: activity_tracker
Message: Error tracking activity: __init__() got an unexpected keyword argument 'created_at'

2024-11-13 17:47:54,033 - - - 127.0.0.1 - POST http://localhost/login
Level: ERROR
Module: activity_tracker
Message: Error tracking activity: __init__() got an unexpected keyword argument 'created_at'

2024-11-13 17:47:54,135 - - - 127.0.0.1 - GET http://localhost/
Level: ERROR
Module: activity_tracker
Message: Error tracking activity: __init__() got an unexpected keyword argument 'created_at'

2024-11-13 17:47:54,135 - - - 127.0.0.1 - GET http://localhost/
Level: ERROR
Module: activity_tracker
Message: Error tracking activity: __init__() got an unexpected keyword argument 'created_at'

2024-11-13 17:47:54,289 - - - 127.0.0.1 - GET http://localhost/
Level: ERROR
Module: activity_tracker
Message: Error tracking activity: __init__() got an unexpected keyword argument 'created_at'

2024-11-13 17:47:54,289 - - - 127.0.0.1 - GET http://localhost/
Level: ERROR
Module: activity_tracker
Message: Error tracking activity: __init__() got an unexpected keyword argument 'created_at'

2024-11-13 17:47:55,612 - - - 127.0.0.1 - POST http://localhost/register
Level: ERROR
Module: activity_tracker
Message: Error tracking activity: __init__() got an unexpected keyword argument 'created_at'

2024-11-13 17:47:55,612 - - - 127.0.0.1 - POST http://localhost/register
Level: ERROR
Module: activity_tracker
Message: Error tracking activity: __init__() got an unexpected keyword argument 'created_at'

2024-11-13 17:47:55,701 - - - 127.0.0.1 - GET http://localhost/
Level: ERROR
Module: activity_tracker
Message: Error tracking activity: __init__() got an unexpected keyword argument 'created_at'

2024-11-13 17:47:55,701 - - - 127.0.0.1 - GET http://localhost/
Level: ERROR
Module: activity_tracker
Message: Error tracking activity: __init__() got an unexpected keyword argument 'created_at'

2024-11-13 17:47:55,839 - - - 127.0.0.1 - GET http://localhost/
Level: ERROR
Module: activity_tracker
Message: Error tracking activity: __init__() got an unexpected keyword argument 'created_at'

2024-11-13 17:47:55,839 - - - 127.0.0.1 - GET http://localhost/
Level: ERROR
Module: activity_tracker
Message: Error tracking activity: __init__() got an unexpected keyword argument 'created_at'

2024-11-13 17:47:57,173 - - - 127.0.0.1 - POST http://localhost/login
Level: ERROR
Module: activity_tracker
Message: Error tracking activity: __init__() got an unexpected keyword argument 'created_at'

2024-11-13 17:47:57,173 - - - 127.0.0.1 - POST http://localhost/login
Level: ERROR
Module: activity_tracker
Message: Error tracking activity: __init__() got an unexpected keyword argument 'created_at'

2024-11-13 17:47:57,260 - - - 127.0.0.1 - POST http://localhost/dream/new
Level: ERROR
Module: routes
Message: Error creating dream: __init__() got an unexpected keyword argument 'is_public'

2024-11-13 17:47:57,260 - - - 127.0.0.1 - POST http://localhost/dream/new
Level: ERROR
Module: routes
Message: Error creating dream: __init__() got an unexpected keyword argument 'is_public'

2024-11-13 17:48:00,788 - - - None - GET http://localhost/
Level: ERROR
Module: logging_config
Message: Application Error: {'timestamp': '2024-11-13T17:48:00.788773', 'error_type': 'ValueError', 'error_message': 'Test error', 'traceback': 'NoneType: None\n', 'context': {'test': 'context'}, 'url': 'http://localhost/', 'method': 'GET', 'headers': {'Host': 'localhost'}, 'remote_addr': None}

2024-11-13 17:48:00,788 - - - None - GET http://localhost/
Level: ERROR
Module: logging_config
Message: Application Error: {'timestamp': '2024-11-13T17:48:00.788773', 'error_type': 'ValueError', 'error_message': 'Test error', 'traceback': 'NoneType: None\n', 'context': {'test': 'context'}, 'url': 'http://localhost/', 'method': 'GET', 'headers': {'Host': 'localhost'}, 'remote_addr': None}

2024-11-13 17:49:06,485 - - - 127.0.0.1 - POST http://localhost/login
Level: ERROR
Module: activity_tracker
Message: Error tracking activity: __init__() got an unexpected keyword argument 'created_at'

2024-11-13 17:49:06,485 - - - 127.0.0.1 - POST http://localhost/login
Level: ERROR
Module: activity_tracker
Message: Error tracking activity: __init__() got an unexpected keyword argument 'created_at'

2024-11-13 17:49:06,582 - - - 127.0.0.1 - GET http://localhost/
Level: ERROR
Module: activity_tracker
Message: Error tracking activity: __init__() got an unexpected keyword argument 'created_at'

2024-11-13 17:49:06,582 - - - 127.0.0.1 - GET http://localhost/
Level: ERROR
Module: activity_tracker
Message: Error tracking activity: __init__() got an unexpected keyword argument 'created_at'

2024-11-13 17:49:06,749 - - - 127.0.0.1 - GET http://localhost/
Level: ERROR
Module: activity_tracker
Message: Error tracking activity: __init__() got an unexpected keyword argument 'created_at'

2024-11-13 17:49:06,749 - - - 127.0.0.1 - GET http://localhost/
Level: ERROR
Module: activity_tracker
Message: Error tracking activity: __init__() got an unexpected keyword argument 'created_at'

2024-11-13 17:49:08,236 - - - 127.0.0.1 - POST http://localhost/register
Level: ERROR
Module: activity_tracker
Message: Error tracking activity: __init__() got an unexpected keyword argument 'created_at'

2024-11-13 17:49:08,236 - - - 127.0.0.1 - POST http://localhost/register
Level: ERROR
Module: activity_tracker
Message: Error tracking activity: __init__() got an unexpected keyword argument 'created_at'

2024-11-13 17:49:08,341 - - - 127.0.0.1 - GET http://localhost/
Level: ERROR
Module: activity_tracker
Message: Error tracking activity: __init__() got an unexpected keyword argument 'created_at'

2024-11-13 17:49:08,341 - - - 127.0.0.1 - GET http://localhost/
Level: ERROR
Module: activity_tracker
Message: Error tracking activity: __init__() got an unexpected keyword argument 'created_at'

2024-11-13 17:49:08,489 - - - 127.0.0.1 - GET http://localhost/
Level: ERROR
Module: activity_tracker
Message: Error tracking activity: __init__() got an unexpected keyword argument 'created_at'

2024-11-13 17:49:08,489 - - - 127.0.0.1 - GET http://localhost/
Level: ERROR
Module: activity_tracker
Message: Error tracking activity: __init__() got an unexpected keyword argument 'created_at'

2024-11-13 17:49:10,099 - - - 127.0.0.1 - POST http://localhost/login
Level: ERROR
Module: activity_tracker
Message: Error tracking activity: __init__() got an unexpected keyword argument 'created_at'

2024-11-13 17:49:10,099 - - - 127.0.0.1 - POST http://localhost/login
Level: ERROR
Module: activity_tracker
Message: Error tracking activity: __init__() got an unexpected keyword argument 'created_at'

2024-11-13 17:49:10,204 - - - 127.0.0.1 - POST http://localhost/dream/new
Level: ERROR
Module: routes
Message: Error creating dream: __init__() got an unexpected keyword argument 'is_public'

2024-11-13 17:49:10,204 - - - 127.0.0.1 - POST http://localhost/dream/new
Level: ERROR
Module: routes
Message: Error creating dream: __init__() got an unexpected keyword argument 'is_public'

2024-11-13 17:49:12,214 - - - 127.0.0.1 - POST http://localhost/login
Level: ERROR
Module: activity_tracker
Message: Error tracking activity: __init__() got an unexpected keyword argument 'created_at'

2024-11-13 17:49:12,214 - - - 127.0.0.1 - POST http://localhost/login
Level: ERROR
Module: activity_tracker
Message: Error tracking activity: __init__() got an unexpected keyword argument 'created_at'

2024-11-13 17:49:14,563 - - - 127.0.0.1 - POST http://localhost/login
Level: ERROR
Module: activity_tracker
Message: Error tracking activity: __init__() got an unexpected keyword argument 'created_at'

2024-11-13 17:49:14,563 - - - 127.0.0.1 - POST http://localhost/login
Level: ERROR
Module: activity_tracker
Message: Error tracking activity: __init__() got an unexpected keyword argument 'created_at'

2024-11-13 17:49:14,681 - - - 127.0.0.1 - GET http://localhost/dream/patterns
Level: ERROR
Module: activity_tracker
Message: Error tracking activity: __init__() got an unexpected keyword argument 'created_at'

2024-11-13 17:49:14,681 - - - 127.0.0.1 - GET http://localhost/dream/patterns
Level: ERROR
Module: activity_tracker
Message: Error tracking activity: __init__() got an unexpected keyword argument 'created_at'

2024-11-13 17:49:16,333 - - - 127.0.0.1 - POST http://localhost/login
Level: ERROR
Module: activity_tracker
Message: Error tracking activity: __init__() got an unexpected keyword argument 'created_at'

2024-11-13 17:49:16,333 - - - 127.0.0.1 - POST http://localhost/login
Level: ERROR
Module: activity_tracker
Message: Error tracking activity: __init__() got an unexpected keyword argument 'created_at'

2024-11-13 17:49:18,139 - - - 127.0.0.1 - POST http://localhost/login
Level: ERROR
Module: activity_tracker
Message: Error tracking activity: __init__() got an unexpected keyword argument 'created_at'

2024-11-13 17:49:18,139 - - - 127.0.0.1 - POST http://localhost/login
Level: ERROR
Module: activity_tracker
Message: Error tracking activity: __init__() got an unexpected keyword argument 'created_at'

2024-11-13 17:49:20,964 - - - 127.0.0.1 - POST http://localhost/login
Level: ERROR
Module: activity_tracker
Message: Error tracking activity: __init__() got an unexpected keyword argument 'created_at'

2024-11-13 17:49:20,964 - - - 127.0.0.1 - POST http://localhost/login
Level: ERROR
Module: activity_tracker
Message: Error tracking activity: __init__() got an unexpected keyword argument 'created_at'

2024-11-13 17:49:21,062 - - - 127.0.0.1 - GET http://localhost/logout
Level: ERROR
Module: activity_tracker
Message: Error tracking activity: __init__() got an unexpected keyword argument 'created_at'

2024-11-13 17:49:21,062 - - - 127.0.0.1 - GET http://localhost/logout
Level: ERROR
Module: activity_tracker
Message: Error tracking activity: __init__() got an unexpected keyword argument 'created_at'

2024-11-13 17:49:25,765 - - - None - GET http://localhost/
Level: ERROR
Module: logging_config
Message: Application Error: {'timestamp': '2024-11-13T17:49:25.764832', 'error_type': 'ValueError', 'error_message': 'Test error', 'traceback': 'NoneType: None\n', 'context': {'test': 'context'}, 'url': 'http://localhost/', 'method': 'GET', 'headers': {'Host': 'localhost'}, 'remote_addr': None}

2024-11-13 17:49:25,765 - - - None - GET http://localhost/
Level: ERROR
Module: logging_config
Message: Application Error: {'timestamp': '2024-11-13T17:49:25.764832', 'error_type': 'ValueError', 'error_message': 'Test error', 'traceback': 'NoneType: None\n', 'context': {'test': 'context'}, 'url': 'http://localhost/', 'method': 'GET', 'headers': {'Host': 'localhost'}, 'remote_addr': None}

2024-11-13 17:49:25,772 - - - None - GET http://localhost/
Level: ERROR
Module: logging_config
Message: Application Error: {'timestamp': '2024-11-13T17:49:25.772291', 'error_type': 'Exception', 'error_message': 'Complex error', 'traceback': 'NoneType: None\n', 'context': {'user_id': 1, 'action': 'test_action', 'timestamp': '2024-11-13T17:49:25.772272'}, 'url': 'http://localhost/', 'method': 'GET', 'headers': {'Host': 'localhost'}, 'remote_addr': None}

2024-11-13 17:49:25,772 - - - None - GET http://localhost/
Level: ERROR
Module: logging_config
Message: Application Error: {'timestamp': '2024-11-13T17:49:25.772291', 'error_type': 'Exception', 'error_message': 'Complex error', 'traceback': 'NoneType: None\n', 'context': {'user_id': 1, 'action': 'test_action', 'timestamp': '2024-11-13T17:49:25.772272'}, 'url': 'http://localhost/', 'method': 'GET', 'headers': {'Host': 'localhost'}, 'remote_addr': None}

